2023-12-28 16:14:00.613 | ERROR    | utils.loggings:exception:40 - (pymysql.err.DataError) (1264, "Out of range value for column 'user_id' at row 1")
[SQL: INSERT INTO user_info (user_id, user_name, profile_picture, signature, gender, phone, date_of_birth, address) VALUES (%(user_id)s, %(user_name)s, %(profile_picture)s, %(signature)s, %(gender)s, %(phone)s, %(date_of_birth)s, %(address)s)]
[parameters: {'user_id': '2023122816141436', 'user_name': '223', 'profile_picture': None, 'signature': None, 'gender': None, 'phone': None, 'date_of_birth': None, 'address': None}]
(Background on this error at: https://sqlalche.me/e/20/9h9h)
Traceback (most recent call last):

  File "D:\Anaconda\envs\api.project.com\lib\site-packages\sqlalchemy\engine\base.py", line 1969, in _exec_single_context
    self.dialect.do_execute(
    │    │       └ <function DefaultDialect.do_execute at 0x0000028F6FEE48B0>
    │    └ <sqlalchemy.dialects.mysql.pymysql.MySQLDialect_pymysql object at 0x0000028F70312040>
    └ <sqlalchemy.engine.base.Connection object at 0x0000028F708B9700>

  File "D:\Anaconda\envs\api.project.com\lib\site-packages\sqlalchemy\engine\default.py", line 922, in do_execute
    cursor.execute(statement, parameters)
    │      │       │          └ {'user_id': '2023122816141436', 'user_name': '223', 'profile_picture': None, 'signature': None, 'gender': None, 'phone': None...
    │      │       └ 'INSERT INTO user_info (user_id, user_name, profile_picture, signature, gender, phone, date_of_birth, address) VALUES (%(user...
    │      └ <function Cursor.execute at 0x0000028F704F3700>
    └ <pymysql.cursors.Cursor object at 0x0000028F708ED820>

  File "D:\Anaconda\envs\api.project.com\lib\site-packages\pymysql\cursors.py", line 158, in execute
    result = self._query(query)
             │    │      └ "INSERT INTO user_info (user_id, user_name, profile_picture, signature, gender, phone, date_of_birth, address) VALUES ('20231...
             │    └ <function Cursor._query at 0x0000028F704F3B80>
             └ <pymysql.cursors.Cursor object at 0x0000028F708ED820>

  File "D:\Anaconda\envs\api.project.com\lib\site-packages\pymysql\cursors.py", line 325, in _query
    conn.query(q)
    │    │     └ "INSERT INTO user_info (user_id, user_name, profile_picture, signature, gender, phone, date_of_birth, address) VALUES ('20231...
    │    └ <function Connection.query at 0x0000028F704FEC10>
    └ <pymysql.connections.Connection object at 0x0000028F708B9E20>

  File "D:\Anaconda\envs\api.project.com\lib\site-packages\pymysql\connections.py", line 549, in query
    self._affected_rows = self._read_query_result(unbuffered=unbuffered)
    │    │                │    │                             └ False
    │    │                │    └ <function Connection._read_query_result at 0x0000028F704FF280>
    │    │                └ <pymysql.connections.Connection object at 0x0000028F708B9E20>
    │    └ 1
    └ <pymysql.connections.Connection object at 0x0000028F708B9E20>

  File "D:\Anaconda\envs\api.project.com\lib\site-packages\pymysql\connections.py", line 779, in _read_query_result
    result.read()
    │      └ <function MySQLResult.read at 0x0000028F704FFA60>
    └ <pymysql.connections.MySQLResult object at 0x0000028F708ED430>

  File "D:\Anaconda\envs\api.project.com\lib\site-packages\pymysql\connections.py", line 1157, in read
    first_packet = self.connection._read_packet()
                   │    └ None
                   └ <pymysql.connections.MySQLResult object at 0x0000028F708ED430>

  File "D:\Anaconda\envs\api.project.com\lib\site-packages\pymysql\connections.py", line 729, in _read_packet
    packet.raise_for_error()
    │      └ <function MysqlPacket.raise_for_error at 0x0000028F704FC820>
    └ <pymysql.protocol.MysqlPacket object at 0x0000028F708ED040>

  File "D:\Anaconda\envs\api.project.com\lib\site-packages\pymysql\protocol.py", line 221, in raise_for_error
    err.raise_mysql_exception(self._data)
    │   │                     │    └ <member '_data' of 'MysqlPacket' objects>
    │   │                     └ <pymysql.protocol.MysqlPacket object at 0x0000028F708ED040>
    │   └ <function raise_mysql_exception at 0x0000028F703A8CA0>
    └ <module 'pymysql.err' from 'D:\\Anaconda\\envs\\api.project.com\\lib\\site-packages\\pymysql\\err.py'>

  File "D:\Anaconda\envs\api.project.com\lib\site-packages\pymysql\err.py", line 143, in raise_mysql_exception
    raise errorclass(errno, errval)
          │          │      └ "Out of range value for column 'user_id' at row 1"
          │          └ 1264
          └ <class 'pymysql.err.DataError'>

pymysql.err.DataError: (1264, "Out of range value for column 'user_id' at row 1")


The above exception was the direct cause of the following exception:


Traceback (most recent call last):

  File "D:\Anaconda\envs\api.project.com\lib\threading.py", line 890, in _bootstrap
    self._bootstrap_inner()
    │    └ <function Thread._bootstrap_inner at 0x0000028F6C694430>
    └ <Thread(Thread-1, started daemon 22124)>

  File "D:\Anaconda\envs\api.project.com\lib\threading.py", line 932, in _bootstrap_inner
    self.run()
    │    └ <function Thread.run at 0x0000028F6C694160>
    └ <Thread(Thread-1, started daemon 22124)>

  File "D:\Anaconda\envs\api.project.com\lib\threading.py", line 870, in run
    self._target(*self._args, **self._kwargs)
    │    │        │    │        │    └ {}
    │    │        │    │        └ <Thread(Thread-1, started daemon 22124)>
    │    │        │    └ ()
    │    │        └ <Thread(Thread-1, started daemon 22124)>
    │    └ <bound method BaseWSGIServer.serve_forever of <werkzeug.serving.BaseWSGIServer object at 0x0000028F70854220>>
    └ <Thread(Thread-1, started daemon 22124)>

  File "D:\Anaconda\envs\api.project.com\lib\site-packages\werkzeug\serving.py", line 806, in serve_forever
    super().serve_forever(poll_interval=poll_interval)
                                        └ 0.5

  File "D:\Anaconda\envs\api.project.com\lib\socketserver.py", line 237, in serve_forever
    self._handle_request_noblock()
    │    └ <function BaseServer._handle_request_noblock at 0x0000028F6C696A60>
    └ <werkzeug.serving.BaseWSGIServer object at 0x0000028F70854220>

  File "D:\Anaconda\envs\api.project.com\lib\socketserver.py", line 316, in _handle_request_noblock
    self.process_request(request, client_address)
    │    │               │        └ ('127.0.0.1', 4840)
    │    │               └ <socket.socket fd=864, family=AddressFamily.AF_INET, type=SocketKind.SOCK_STREAM, proto=0, laddr=('127.0.0.1', 5000), raddr=(...
    │    └ <function BaseServer.process_request at 0x0000028F6C696C10>
    └ <werkzeug.serving.BaseWSGIServer object at 0x0000028F70854220>

  File "D:\Anaconda\envs\api.project.com\lib\socketserver.py", line 347, in process_request
    self.finish_request(request, client_address)
    │    │              │        └ ('127.0.0.1', 4840)
    │    │              └ <socket.socket fd=864, family=AddressFamily.AF_INET, type=SocketKind.SOCK_STREAM, proto=0, laddr=('127.0.0.1', 5000), raddr=(...
    │    └ <function BaseServer.finish_request at 0x0000028F6C696D30>
    └ <werkzeug.serving.BaseWSGIServer object at 0x0000028F70854220>

  File "D:\Anaconda\envs\api.project.com\lib\socketserver.py", line 360, in finish_request
    self.RequestHandlerClass(request, client_address, self)
    │    │                   │        │               └ <werkzeug.serving.BaseWSGIServer object at 0x0000028F70854220>
    │    │                   │        └ ('127.0.0.1', 4840)
    │    │                   └ <socket.socket fd=864, family=AddressFamily.AF_INET, type=SocketKind.SOCK_STREAM, proto=0, laddr=('127.0.0.1', 5000), raddr=(...
    │    └ <class 'werkzeug.serving.WSGIRequestHandler'>
    └ <werkzeug.serving.BaseWSGIServer object at 0x0000028F70854220>

  File "D:\Anaconda\envs\api.project.com\lib\socketserver.py", line 720, in __init__
    self.handle()
    │    └ <function WSGIRequestHandler.handle at 0x0000028F6E3F3CA0>
    └ <werkzeug.serving.WSGIRequestHandler object at 0x0000028F7087BCD0>

  File "D:\Anaconda\envs\api.project.com\lib\site-packages\werkzeug\serving.py", line 390, in handle
    super().handle()

  File "D:\Anaconda\envs\api.project.com\lib\http\server.py", line 426, in handle
    self.handle_one_request()
    │    └ <function BaseHTTPRequestHandler.handle_one_request at 0x0000028F6E22B1F0>
    └ <werkzeug.serving.WSGIRequestHandler object at 0x0000028F7087BCD0>

  File "D:\Anaconda\envs\api.project.com\lib\http\server.py", line 414, in handle_one_request
    method()
    └ <bound method WSGIRequestHandler.run_wsgi of <werkzeug.serving.WSGIRequestHandler object at 0x0000028F7087BCD0>>

  File "D:\Anaconda\envs\api.project.com\lib\site-packages\werkzeug\serving.py", line 362, in run_wsgi
    execute(self.server.app)
    │       │    │      └ <werkzeug.debug.DebuggedApplication object at 0x0000028F708114C0>
    │       │    └ <werkzeug.serving.BaseWSGIServer object at 0x0000028F70854220>
    │       └ <werkzeug.serving.WSGIRequestHandler object at 0x0000028F7087BCD0>
    └ <function WSGIRequestHandler.run_wsgi.<locals>.execute at 0x0000028F70899940>

  File "D:\Anaconda\envs\api.project.com\lib\site-packages\werkzeug\serving.py", line 325, in execute
    for data in application_iter:
                └ <generator object DebuggedApplication.debug_application at 0x0000028F7088DBA0>

  File "D:\Anaconda\envs\api.project.com\lib\site-packages\werkzeug\debug\__init__.py", line 330, in debug_application
    app_iter = self.app(environ, start_response)
               │    │   │        └ <function WSGIRequestHandler.run_wsgi.<locals>.start_response at 0x0000028F70899F70>
               │    │   └ {'wsgi.version': (1, 0), 'wsgi.url_scheme': 'http', 'wsgi.input': <_io.BufferedReader name=864>, 'wsgi.errors': <_io.TextIOWr...
               │    └ <Flask 'app'>
               └ <werkzeug.debug.DebuggedApplication object at 0x0000028F708114C0>

  File "D:\Anaconda\envs\api.project.com\lib\site-packages\flask\app.py", line 2213, in __call__
    return self.wsgi_app(environ, start_response)
           │    │        │        └ <function WSGIRequestHandler.run_wsgi.<locals>.start_response at 0x0000028F70899F70>
           │    │        └ {'wsgi.version': (1, 0), 'wsgi.url_scheme': 'http', 'wsgi.input': <_io.BufferedReader name=864>, 'wsgi.errors': <_io.TextIOWr...
           │    └ <function Flask.wsgi_app at 0x0000028F6ED02E50>
           └ <Flask 'app'>

  File "D:\Anaconda\envs\api.project.com\lib\site-packages\flask\app.py", line 2190, in wsgi_app
    response = self.full_dispatch_request()
               │    └ <function Flask.full_dispatch_request at 0x0000028F6ED023A0>
               └ <Flask 'app'>

  File "D:\Anaconda\envs\api.project.com\lib\site-packages\flask\app.py", line 1484, in full_dispatch_request
    rv = self.dispatch_request()
         │    └ <function Flask.dispatch_request at 0x0000028F6ED02310>
         └ <Flask 'app'>

  File "D:\Anaconda\envs\api.project.com\lib\site-packages\flask\app.py", line 1469, in dispatch_request
    return self.ensure_sync(self.view_functions[rule.endpoint])(**view_args)
           │    │           │    │              │    │            └ {}
           │    │           │    │              │    └ 'userInfo.UserInfo'
           │    │           │    │              └ <Rule '/api_1_0/userInfo' (PUT, DELETE, OPTIONS, HEAD, POST, GET) -> userInfo.UserInfo>
           │    │           │    └ {'static': <function Flask.__init__.<locals>.<lambda> at 0x0000028F702EEF70>, 'apiversion.Apiversion': <function View.as_view...
           │    │           └ <Flask 'app'>
           │    └ <function Flask.ensure_sync at 0x0000028F6ED025E0>
           └ <Flask 'app'>

  File "D:\Anaconda\envs\api.project.com\lib\site-packages\flask_restful\__init__.py", line 489, in wrapper
    resp = resource(*args, **kwargs)
           │         │       └ {}
           │         └ ()
           └ <function View.as_view.<locals>.view at 0x0000028F70614550>

  File "D:\Anaconda\envs\api.project.com\lib\site-packages\flask\views.py", line 109, in view
    return current_app.ensure_sync(self.dispatch_request)(**kwargs)
           │                       │    │                   └ {}
           │                       │    └ <function Resource.dispatch_request at 0x0000028F7051DA60>
           │                       └ <api_1_0.userInfoResource.userInfoResource.UserInfoResource object at 0x0000028F708B9190>
           └ <Flask 'app'>

  File "D:\Anaconda\envs\api.project.com\lib\site-packages\flask_restful\__init__.py", line 604, in dispatch_request
    resp = meth(*args, **kwargs)
           │     │       └ {}
           │     └ ()
           └ <bound method UserInfoResource.post of <class 'api_1_0.userInfoResource.userInfoResource.UserInfoResource'>>

  File "D:\Python_RESTfulAPI_Codegen\dist\dist_1703676800155\api.project.com\api_1_0\userInfoResource\userInfoResource.py", line 182, in post
    res = UserInfoController.add(**kwargs)
          │                  │     └ {'user_name': '223'}
          │                  └ <classmethod object at 0x0000028F70611910>
          └ <class 'controller.userInfoController.UserInfoController'>

> File "D:\Python_RESTfulAPI_Codegen\dist\dist_1703676800155\api.project.com\controller\userInfoController.py", line 38, in add
    db.session.commit()
    │  │       └ <function scoped_session.commit at 0x0000028F702650D0>
    │  └ <sqlalchemy.orm.scoping.scoped_session object at 0x0000028F6ED27160>
    └ <SQLAlchemy mysql+pymysql://root:***@8.130.89.73:3306/skill_sharing?charset=utf8>

  File "D:\Anaconda\envs\api.project.com\lib\site-packages\sqlalchemy\orm\scoping.py", line 598, in commit
    return self._proxied.commit()
           │    └ <property object at 0x0000028F7025F630>
           └ <sqlalchemy.orm.scoping.scoped_session object at 0x0000028F6ED27160>

  File "D:\Anaconda\envs\api.project.com\lib\site-packages\sqlalchemy\orm\session.py", line 1969, in commit
    trans.commit(_to_root=True)
    │     └ <function SessionTransaction.commit at 0x0000028F701B4AF0>
    └ <sqlalchemy.orm.session.SessionTransaction object at 0x0000028F708D20C0>

  File "<string>", line 2, in commit

  File "D:\Anaconda\envs\api.project.com\lib\site-packages\sqlalchemy\orm\state_changes.py", line 139, in _go
    ret_value = fn(self, *arg, **kw)
                │  │      │      └ {'_to_root': True}
                │  │      └ ()
                │  └ <sqlalchemy.orm.session.SessionTransaction object at 0x0000028F708D20C0>
                └ <function SessionTransaction.commit at 0x0000028F701B4A60>

  File "D:\Anaconda\envs\api.project.com\lib\site-packages\sqlalchemy\orm\session.py", line 1256, in commit
    self._prepare_impl()
    │    └ <function SessionTransaction._prepare_impl at 0x0000028F701B49D0>
    └ <sqlalchemy.orm.session.SessionTransaction object at 0x0000028F708D20C0>

  File "<string>", line 2, in _prepare_impl

  File "D:\Anaconda\envs\api.project.com\lib\site-packages\sqlalchemy\orm\state_changes.py", line 139, in _go
    ret_value = fn(self, *arg, **kw)
                │  │      │      └ {}
                │  │      └ ()
                │  └ <sqlalchemy.orm.session.SessionTransaction object at 0x0000028F708D20C0>
                └ <function SessionTransaction._prepare_impl at 0x0000028F701B48B0>

  File "D:\Anaconda\envs\api.project.com\lib\site-packages\sqlalchemy\orm\session.py", line 1231, in _prepare_impl
    self.session.flush()
    │    │       └ <function Session.flush at 0x0000028F701BE670>
    │    └ <sqlalchemy.orm.session.Session object at 0x0000028F708B9490>
    └ <sqlalchemy.orm.session.SessionTransaction object at 0x0000028F708D20C0>

  File "D:\Anaconda\envs\api.project.com\lib\site-packages\sqlalchemy\orm\session.py", line 4312, in flush
    self._flush(objects)
    │    │      └ None
    │    └ <function Session._flush at 0x0000028F701BE820>
    └ <sqlalchemy.orm.session.Session object at 0x0000028F708B9490>

  File "D:\Anaconda\envs\api.project.com\lib\site-packages\sqlalchemy\orm\session.py", line 4448, in _flush
    transaction.rollback(_capture_exception=True)
    │           └ <function SessionTransaction.rollback at 0x0000028F701B4D30>
    └ <sqlalchemy.orm.session.SessionTransaction object at 0x0000028F708D5FC0>

  File "D:\Anaconda\envs\api.project.com\lib\site-packages\sqlalchemy\util\langhelpers.py", line 146, in __exit__
    raise exc_value.with_traceback(exc_tb)
          │         │              └ <traceback object at 0x0000028F70876CC0>
          │         └ <method 'with_traceback' of 'BaseException' objects>
          └ DataError('(pymysql.err.DataError) (1264, "Out of range value for column \'user_id\' at row 1")')

  File "D:\Anaconda\envs\api.project.com\lib\site-packages\sqlalchemy\orm\session.py", line 4408, in _flush
    flush_context.execute()
    │             └ <function UOWTransaction.execute at 0x0000028F701A99D0>
    └ <sqlalchemy.orm.unitofwork.UOWTransaction object at 0x0000028F708B9C40>

  File "D:\Anaconda\envs\api.project.com\lib\site-packages\sqlalchemy\orm\unitofwork.py", line 466, in execute
    rec.execute(self)
    │   │       └ <sqlalchemy.orm.unitofwork.UOWTransaction object at 0x0000028F708B9C40>
    │   └ <function SaveUpdateAll.execute at 0x0000028F701AA310>
    └ SaveUpdateAll(Mapper[UserInfo(user_info)])

  File "D:\Anaconda\envs\api.project.com\lib\site-packages\sqlalchemy\orm\unitofwork.py", line 642, in execute
    util.preloaded.orm_persistence.save_obj(
    │    │         │               └ <function save_obj at 0x0000028F7017F9D0>
    │    │         └ <module 'sqlalchemy.orm.persistence' from 'D:\\Anaconda\\envs\\api.project.com\\lib\\site-packages\\sqlalchemy\\orm\\persiste...
    │    └ <module 'sqlalchemy.util.preloaded' from 'D:\\Anaconda\\envs\\api.project.com\\lib\\site-packages\\sqlalchemy\\util\\preloade...
    └ <module 'sqlalchemy.util' from 'D:\\Anaconda\\envs\\api.project.com\\lib\\site-packages\\sqlalchemy\\util\\__init__.py'>

  File "D:\Anaconda\envs\api.project.com\lib\site-packages\sqlalchemy\orm\persistence.py", line 93, in save_obj
    _emit_insert_statements(
    └ <function _emit_insert_statements at 0x0000028F7018A0D0>

  File "D:\Anaconda\envs\api.project.com\lib\site-packages\sqlalchemy\orm\persistence.py", line 1043, in _emit_insert_statements
    result = connection.execute(
             │          └ <function Connection.execute at 0x0000028F6FCD81F0>
             └ <sqlalchemy.engine.base.Connection object at 0x0000028F708B9700>

  File "D:\Anaconda\envs\api.project.com\lib\site-packages\sqlalchemy\engine\base.py", line 1416, in execute
    return meth(
           └ <bound method ClauseElement._execute_on_connection of <sqlalchemy.sql.dml.Insert object at 0x0000028F708ED190>>

  File "D:\Anaconda\envs\api.project.com\lib\site-packages\sqlalchemy\sql\elements.py", line 516, in _execute_on_connection
    return connection._execute_clauseelement(
           │          └ <function Connection._execute_clauseelement at 0x0000028F6FCD84C0>
           └ <sqlalchemy.engine.base.Connection object at 0x0000028F708B9700>

  File "D:\Anaconda\envs\api.project.com\lib\site-packages\sqlalchemy\engine\base.py", line 1639, in _execute_clauseelement
    ret = self._execute_context(
          │    └ <function Connection._execute_context at 0x0000028F6FCD8670>
          └ <sqlalchemy.engine.base.Connection object at 0x0000028F708B9700>

  File "D:\Anaconda\envs\api.project.com\lib\site-packages\sqlalchemy\engine\base.py", line 1848, in _execute_context
    return self._exec_single_context(
           │    └ <function Connection._exec_single_context at 0x0000028F6FCD8700>
           └ <sqlalchemy.engine.base.Connection object at 0x0000028F708B9700>

  File "D:\Anaconda\envs\api.project.com\lib\site-packages\sqlalchemy\engine\base.py", line 1988, in _exec_single_context
    self._handle_dbapi_exception(
    │    └ <function Connection._handle_dbapi_exception at 0x0000028F6FCD8940>
    └ <sqlalchemy.engine.base.Connection object at 0x0000028F708B9700>

  File "D:\Anaconda\envs\api.project.com\lib\site-packages\sqlalchemy\engine\base.py", line 2343, in _handle_dbapi_exception
    raise sqlalchemy_exception.with_traceback(exc_info[2]) from e
          │                    │              │                 └ DataError(1264, "Out of range value for column 'user_id' at row 1")
          │                    │              └ (<class 'pymysql.err.DataError'>, DataError(1264, "Out of range value for column 'user_id' at row 1"), <traceback object at 0...
          │                    └ <method 'with_traceback' of 'BaseException' objects>
          └ DataError('(pymysql.err.DataError) (1264, "Out of range value for column \'user_id\' at row 1")')

  File "D:\Anaconda\envs\api.project.com\lib\site-packages\sqlalchemy\engine\base.py", line 1969, in _exec_single_context
    self.dialect.do_execute(
    │    │       └ <function DefaultDialect.do_execute at 0x0000028F6FEE48B0>
    │    └ <sqlalchemy.dialects.mysql.pymysql.MySQLDialect_pymysql object at 0x0000028F70312040>
    └ <sqlalchemy.engine.base.Connection object at 0x0000028F708B9700>

  File "D:\Anaconda\envs\api.project.com\lib\site-packages\sqlalchemy\engine\default.py", line 922, in do_execute
    cursor.execute(statement, parameters)
    │      │       │          └ {'user_id': '2023122816141436', 'user_name': '223', 'profile_picture': None, 'signature': None, 'gender': None, 'phone': None...
    │      │       └ 'INSERT INTO user_info (user_id, user_name, profile_picture, signature, gender, phone, date_of_birth, address) VALUES (%(user...
    │      └ <function Cursor.execute at 0x0000028F704F3700>
    └ <pymysql.cursors.Cursor object at 0x0000028F708ED820>

  File "D:\Anaconda\envs\api.project.com\lib\site-packages\pymysql\cursors.py", line 158, in execute
    result = self._query(query)
             │    │      └ "INSERT INTO user_info (user_id, user_name, profile_picture, signature, gender, phone, date_of_birth, address) VALUES ('20231...
             │    └ <function Cursor._query at 0x0000028F704F3B80>
             └ <pymysql.cursors.Cursor object at 0x0000028F708ED820>

  File "D:\Anaconda\envs\api.project.com\lib\site-packages\pymysql\cursors.py", line 325, in _query
    conn.query(q)
    │    │     └ "INSERT INTO user_info (user_id, user_name, profile_picture, signature, gender, phone, date_of_birth, address) VALUES ('20231...
    │    └ <function Connection.query at 0x0000028F704FEC10>
    └ <pymysql.connections.Connection object at 0x0000028F708B9E20>

  File "D:\Anaconda\envs\api.project.com\lib\site-packages\pymysql\connections.py", line 549, in query
    self._affected_rows = self._read_query_result(unbuffered=unbuffered)
    │    │                │    │                             └ False
    │    │                │    └ <function Connection._read_query_result at 0x0000028F704FF280>
    │    │                └ <pymysql.connections.Connection object at 0x0000028F708B9E20>
    │    └ 1
    └ <pymysql.connections.Connection object at 0x0000028F708B9E20>

  File "D:\Anaconda\envs\api.project.com\lib\site-packages\pymysql\connections.py", line 779, in _read_query_result
    result.read()
    │      └ <function MySQLResult.read at 0x0000028F704FFA60>
    └ <pymysql.connections.MySQLResult object at 0x0000028F708ED430>

  File "D:\Anaconda\envs\api.project.com\lib\site-packages\pymysql\connections.py", line 1157, in read
    first_packet = self.connection._read_packet()
                   │    └ None
                   └ <pymysql.connections.MySQLResult object at 0x0000028F708ED430>

  File "D:\Anaconda\envs\api.project.com\lib\site-packages\pymysql\connections.py", line 729, in _read_packet
    packet.raise_for_error()
    │      └ <function MysqlPacket.raise_for_error at 0x0000028F704FC820>
    └ <pymysql.protocol.MysqlPacket object at 0x0000028F708ED040>

  File "D:\Anaconda\envs\api.project.com\lib\site-packages\pymysql\protocol.py", line 221, in raise_for_error
    err.raise_mysql_exception(self._data)
    │   │                     │    └ <member '_data' of 'MysqlPacket' objects>
    │   │                     └ <pymysql.protocol.MysqlPacket object at 0x0000028F708ED040>
    │   └ <function raise_mysql_exception at 0x0000028F703A8CA0>
    └ <module 'pymysql.err' from 'D:\\Anaconda\\envs\\api.project.com\\lib\\site-packages\\pymysql\\err.py'>

  File "D:\Anaconda\envs\api.project.com\lib\site-packages\pymysql\err.py", line 143, in raise_mysql_exception
    raise errorclass(errno, errval)
          │          │      └ "Out of range value for column 'user_id' at row 1"
          │          └ 1264
          └ <class 'pymysql.err.DataError'>

sqlalchemy.exc.DataError: (pymysql.err.DataError) (1264, "Out of range value for column 'user_id' at row 1")
[SQL: INSERT INTO user_info (user_id, user_name, profile_picture, signature, gender, phone, date_of_birth, address) VALUES (%(user_id)s, %(user_name)s, %(profile_picture)s, %(signature)s, %(gender)s, %(phone)s, %(date_of_birth)s, %(address)s)]
[parameters: {'user_id': '2023122816141436', 'user_name': '223', 'profile_picture': None, 'signature': None, 'gender': None, 'phone': None, 'date_of_birth': None, 'address': None}]
(Background on this error at: https://sqlalche.me/e/20/9h9h)
2023-12-28 16:14:37.593 | ERROR    | utils.loggings:exception:40 - (pymysql.err.DataError) (1264, "Out of range value for column 'user_id' at row 1")
[SQL: INSERT INTO user_info (user_id, user_name, profile_picture, signature, gender, phone, date_of_birth, address) VALUES (%(user_id)s, %(user_name)s, %(profile_picture)s, %(signature)s, %(gender)s, %(phone)s, %(date_of_birth)s, %(address)s)]
[parameters: {'user_id': '2023122816143780', 'user_name': '223', 'profile_picture': None, 'signature': None, 'gender': None, 'phone': None, 'date_of_birth': None, 'address': None}]
(Background on this error at: https://sqlalche.me/e/20/9h9h)
Traceback (most recent call last):

  File "D:\Anaconda\envs\api.project.com\lib\site-packages\sqlalchemy\engine\base.py", line 1969, in _exec_single_context
    self.dialect.do_execute(
    │    │       └ <function DefaultDialect.do_execute at 0x0000028F6FEE48B0>
    │    └ <sqlalchemy.dialects.mysql.pymysql.MySQLDialect_pymysql object at 0x0000028F70312040>
    └ <sqlalchemy.engine.base.Connection object at 0x0000028F70C55D60>

  File "D:\Anaconda\envs\api.project.com\lib\site-packages\sqlalchemy\engine\default.py", line 922, in do_execute
    cursor.execute(statement, parameters)
    │      │       │          └ {'user_id': '2023122816143780', 'user_name': '223', 'profile_picture': None, 'signature': None, 'gender': None, 'phone': None...
    │      │       └ 'INSERT INTO user_info (user_id, user_name, profile_picture, signature, gender, phone, date_of_birth, address) VALUES (%(user...
    │      └ <function Cursor.execute at 0x0000028F704F3700>
    └ <pymysql.cursors.Cursor object at 0x0000028F70C55E80>

  File "D:\Anaconda\envs\api.project.com\lib\site-packages\pymysql\cursors.py", line 158, in execute
    result = self._query(query)
             │    │      └ "INSERT INTO user_info (user_id, user_name, profile_picture, signature, gender, phone, date_of_birth, address) VALUES ('20231...
             │    └ <function Cursor._query at 0x0000028F704F3B80>
             └ <pymysql.cursors.Cursor object at 0x0000028F70C55E80>

  File "D:\Anaconda\envs\api.project.com\lib\site-packages\pymysql\cursors.py", line 325, in _query
    conn.query(q)
    │    │     └ "INSERT INTO user_info (user_id, user_name, profile_picture, signature, gender, phone, date_of_birth, address) VALUES ('20231...
    │    └ <function Connection.query at 0x0000028F704FEC10>
    └ <pymysql.connections.Connection object at 0x0000028F708B9E20>

  File "D:\Anaconda\envs\api.project.com\lib\site-packages\pymysql\connections.py", line 549, in query
    self._affected_rows = self._read_query_result(unbuffered=unbuffered)
    │    │                │    │                             └ False
    │    │                │    └ <function Connection._read_query_result at 0x0000028F704FF280>
    │    │                └ <pymysql.connections.Connection object at 0x0000028F708B9E20>
    │    └ 1
    └ <pymysql.connections.Connection object at 0x0000028F708B9E20>

  File "D:\Anaconda\envs\api.project.com\lib\site-packages\pymysql\connections.py", line 779, in _read_query_result
    result.read()
    │      └ <function MySQLResult.read at 0x0000028F704FFA60>
    └ <pymysql.connections.MySQLResult object at 0x0000028F70C55E20>

  File "D:\Anaconda\envs\api.project.com\lib\site-packages\pymysql\connections.py", line 1157, in read
    first_packet = self.connection._read_packet()
                   │    └ None
                   └ <pymysql.connections.MySQLResult object at 0x0000028F70C55E20>

  File "D:\Anaconda\envs\api.project.com\lib\site-packages\pymysql\connections.py", line 729, in _read_packet
    packet.raise_for_error()
    │      └ <function MysqlPacket.raise_for_error at 0x0000028F704FC820>
    └ <pymysql.protocol.MysqlPacket object at 0x0000028F70C55EE0>

  File "D:\Anaconda\envs\api.project.com\lib\site-packages\pymysql\protocol.py", line 221, in raise_for_error
    err.raise_mysql_exception(self._data)
    │   │                     │    └ <member '_data' of 'MysqlPacket' objects>
    │   │                     └ <pymysql.protocol.MysqlPacket object at 0x0000028F70C55EE0>
    │   └ <function raise_mysql_exception at 0x0000028F703A8CA0>
    └ <module 'pymysql.err' from 'D:\\Anaconda\\envs\\api.project.com\\lib\\site-packages\\pymysql\\err.py'>

  File "D:\Anaconda\envs\api.project.com\lib\site-packages\pymysql\err.py", line 143, in raise_mysql_exception
    raise errorclass(errno, errval)
          │          │      └ "Out of range value for column 'user_id' at row 1"
          │          └ 1264
          └ <class 'pymysql.err.DataError'>

pymysql.err.DataError: (1264, "Out of range value for column 'user_id' at row 1")


The above exception was the direct cause of the following exception:


Traceback (most recent call last):

  File "D:\Anaconda\envs\api.project.com\lib\threading.py", line 890, in _bootstrap
    self._bootstrap_inner()
    │    └ <function Thread._bootstrap_inner at 0x0000028F6C694430>
    └ <Thread(Thread-1, started daemon 22124)>

  File "D:\Anaconda\envs\api.project.com\lib\threading.py", line 932, in _bootstrap_inner
    self.run()
    │    └ <function Thread.run at 0x0000028F6C694160>
    └ <Thread(Thread-1, started daemon 22124)>

  File "D:\Anaconda\envs\api.project.com\lib\threading.py", line 870, in run
    self._target(*self._args, **self._kwargs)
    │    │        │    │        │    └ {}
    │    │        │    │        └ <Thread(Thread-1, started daemon 22124)>
    │    │        │    └ ()
    │    │        └ <Thread(Thread-1, started daemon 22124)>
    │    └ <bound method BaseWSGIServer.serve_forever of <werkzeug.serving.BaseWSGIServer object at 0x0000028F70854220>>
    └ <Thread(Thread-1, started daemon 22124)>

  File "D:\Anaconda\envs\api.project.com\lib\site-packages\werkzeug\serving.py", line 806, in serve_forever
    super().serve_forever(poll_interval=poll_interval)
                                        └ 0.5

  File "D:\Anaconda\envs\api.project.com\lib\socketserver.py", line 237, in serve_forever
    self._handle_request_noblock()
    │    └ <function BaseServer._handle_request_noblock at 0x0000028F6C696A60>
    └ <werkzeug.serving.BaseWSGIServer object at 0x0000028F70854220>

  File "D:\Anaconda\envs\api.project.com\lib\socketserver.py", line 316, in _handle_request_noblock
    self.process_request(request, client_address)
    │    │               │        └ ('127.0.0.1', 41416)
    │    │               └ <socket.socket fd=980, family=AddressFamily.AF_INET, type=SocketKind.SOCK_STREAM, proto=0, laddr=('127.0.0.1', 5000), raddr=(...
    │    └ <function BaseServer.process_request at 0x0000028F6C696C10>
    └ <werkzeug.serving.BaseWSGIServer object at 0x0000028F70854220>

  File "D:\Anaconda\envs\api.project.com\lib\socketserver.py", line 347, in process_request
    self.finish_request(request, client_address)
    │    │              │        └ ('127.0.0.1', 41416)
    │    │              └ <socket.socket fd=980, family=AddressFamily.AF_INET, type=SocketKind.SOCK_STREAM, proto=0, laddr=('127.0.0.1', 5000), raddr=(...
    │    └ <function BaseServer.finish_request at 0x0000028F6C696D30>
    └ <werkzeug.serving.BaseWSGIServer object at 0x0000028F70854220>

  File "D:\Anaconda\envs\api.project.com\lib\socketserver.py", line 360, in finish_request
    self.RequestHandlerClass(request, client_address, self)
    │    │                   │        │               └ <werkzeug.serving.BaseWSGIServer object at 0x0000028F70854220>
    │    │                   │        └ ('127.0.0.1', 41416)
    │    │                   └ <socket.socket fd=980, family=AddressFamily.AF_INET, type=SocketKind.SOCK_STREAM, proto=0, laddr=('127.0.0.1', 5000), raddr=(...
    │    └ <class 'werkzeug.serving.WSGIRequestHandler'>
    └ <werkzeug.serving.BaseWSGIServer object at 0x0000028F70854220>

  File "D:\Anaconda\envs\api.project.com\lib\socketserver.py", line 720, in __init__
    self.handle()
    │    └ <function WSGIRequestHandler.handle at 0x0000028F6E3F3CA0>
    └ <werkzeug.serving.WSGIRequestHandler object at 0x0000028F7087BA00>

  File "D:\Anaconda\envs\api.project.com\lib\site-packages\werkzeug\serving.py", line 390, in handle
    super().handle()

  File "D:\Anaconda\envs\api.project.com\lib\http\server.py", line 426, in handle
    self.handle_one_request()
    │    └ <function BaseHTTPRequestHandler.handle_one_request at 0x0000028F6E22B1F0>
    └ <werkzeug.serving.WSGIRequestHandler object at 0x0000028F7087BA00>

  File "D:\Anaconda\envs\api.project.com\lib\http\server.py", line 414, in handle_one_request
    method()
    └ <bound method WSGIRequestHandler.run_wsgi of <werkzeug.serving.WSGIRequestHandler object at 0x0000028F7087BA00>>

  File "D:\Anaconda\envs\api.project.com\lib\site-packages\werkzeug\serving.py", line 362, in run_wsgi
    execute(self.server.app)
    │       │    │      └ <werkzeug.debug.DebuggedApplication object at 0x0000028F708114C0>
    │       │    └ <werkzeug.serving.BaseWSGIServer object at 0x0000028F70854220>
    │       └ <werkzeug.serving.WSGIRequestHandler object at 0x0000028F7087BA00>
    └ <function WSGIRequestHandler.run_wsgi.<locals>.execute at 0x0000028F70BE4AF0>

  File "D:\Anaconda\envs\api.project.com\lib\site-packages\werkzeug\serving.py", line 325, in execute
    for data in application_iter:
                └ <generator object DebuggedApplication.debug_application at 0x0000028F7088DBA0>

  File "D:\Anaconda\envs\api.project.com\lib\site-packages\werkzeug\debug\__init__.py", line 330, in debug_application
    app_iter = self.app(environ, start_response)
               │    │   │        └ <function WSGIRequestHandler.run_wsgi.<locals>.start_response at 0x0000028F70BE49D0>
               │    │   └ {'wsgi.version': (1, 0), 'wsgi.url_scheme': 'http', 'wsgi.input': <_io.BufferedReader name=980>, 'wsgi.errors': <_io.TextIOWr...
               │    └ <Flask 'app'>
               └ <werkzeug.debug.DebuggedApplication object at 0x0000028F708114C0>

  File "D:\Anaconda\envs\api.project.com\lib\site-packages\flask\app.py", line 2213, in __call__
    return self.wsgi_app(environ, start_response)
           │    │        │        └ <function WSGIRequestHandler.run_wsgi.<locals>.start_response at 0x0000028F70BE49D0>
           │    │        └ {'wsgi.version': (1, 0), 'wsgi.url_scheme': 'http', 'wsgi.input': <_io.BufferedReader name=980>, 'wsgi.errors': <_io.TextIOWr...
           │    └ <function Flask.wsgi_app at 0x0000028F6ED02E50>
           └ <Flask 'app'>

  File "D:\Anaconda\envs\api.project.com\lib\site-packages\flask\app.py", line 2190, in wsgi_app
    response = self.full_dispatch_request()
               │    └ <function Flask.full_dispatch_request at 0x0000028F6ED023A0>
               └ <Flask 'app'>

  File "D:\Anaconda\envs\api.project.com\lib\site-packages\flask\app.py", line 1484, in full_dispatch_request
    rv = self.dispatch_request()
         │    └ <function Flask.dispatch_request at 0x0000028F6ED02310>
         └ <Flask 'app'>

  File "D:\Anaconda\envs\api.project.com\lib\site-packages\flask\app.py", line 1469, in dispatch_request
    return self.ensure_sync(self.view_functions[rule.endpoint])(**view_args)
           │    │           │    │              │    │            └ {}
           │    │           │    │              │    └ 'userInfo.UserInfo'
           │    │           │    │              └ <Rule '/api_1_0/userInfo' (PUT, DELETE, OPTIONS, HEAD, POST, GET) -> userInfo.UserInfo>
           │    │           │    └ {'static': <function Flask.__init__.<locals>.<lambda> at 0x0000028F702EEF70>, 'apiversion.Apiversion': <function View.as_view...
           │    │           └ <Flask 'app'>
           │    └ <function Flask.ensure_sync at 0x0000028F6ED025E0>
           └ <Flask 'app'>

  File "D:\Anaconda\envs\api.project.com\lib\site-packages\flask_restful\__init__.py", line 489, in wrapper
    resp = resource(*args, **kwargs)
           │         │       └ {}
           │         └ ()
           └ <function View.as_view.<locals>.view at 0x0000028F70614550>

  File "D:\Anaconda\envs\api.project.com\lib\site-packages\flask\views.py", line 109, in view
    return current_app.ensure_sync(self.dispatch_request)(**kwargs)
           │                       │    │                   └ {}
           │                       │    └ <function Resource.dispatch_request at 0x0000028F7051DA60>
           │                       └ <api_1_0.userInfoResource.userInfoResource.UserInfoResource object at 0x0000028F70C555E0>
           └ <Flask 'app'>

  File "D:\Anaconda\envs\api.project.com\lib\site-packages\flask_restful\__init__.py", line 604, in dispatch_request
    resp = meth(*args, **kwargs)
           │     │       └ {}
           │     └ ()
           └ <bound method UserInfoResource.post of <class 'api_1_0.userInfoResource.userInfoResource.UserInfoResource'>>

  File "D:\Python_RESTfulAPI_Codegen\dist\dist_1703676800155\api.project.com\api_1_0\userInfoResource\userInfoResource.py", line 182, in post
    res = UserInfoController.add(**kwargs)
          │                  │     └ {'user_name': '223'}
          │                  └ <classmethod object at 0x0000028F70611910>
          └ <class 'controller.userInfoController.UserInfoController'>

> File "D:\Python_RESTfulAPI_Codegen\dist\dist_1703676800155\api.project.com\controller\userInfoController.py", line 38, in add
    db.session.commit()
    │  │       └ <function scoped_session.commit at 0x0000028F702650D0>
    │  └ <sqlalchemy.orm.scoping.scoped_session object at 0x0000028F6ED27160>
    └ <SQLAlchemy mysql+pymysql://root:***@8.130.89.73:3306/skill_sharing?charset=utf8>

  File "D:\Anaconda\envs\api.project.com\lib\site-packages\sqlalchemy\orm\scoping.py", line 598, in commit
    return self._proxied.commit()
           │    └ <property object at 0x0000028F7025F630>
           └ <sqlalchemy.orm.scoping.scoped_session object at 0x0000028F6ED27160>

  File "D:\Anaconda\envs\api.project.com\lib\site-packages\sqlalchemy\orm\session.py", line 1969, in commit
    trans.commit(_to_root=True)
    │     └ <function SessionTransaction.commit at 0x0000028F701B4AF0>
    └ <sqlalchemy.orm.session.SessionTransaction object at 0x0000028F70C53080>

  File "<string>", line 2, in commit

  File "D:\Anaconda\envs\api.project.com\lib\site-packages\sqlalchemy\orm\state_changes.py", line 139, in _go
    ret_value = fn(self, *arg, **kw)
                │  │      │      └ {'_to_root': True}
                │  │      └ ()
                │  └ <sqlalchemy.orm.session.SessionTransaction object at 0x0000028F70C53080>
                └ <function SessionTransaction.commit at 0x0000028F701B4A60>

  File "D:\Anaconda\envs\api.project.com\lib\site-packages\sqlalchemy\orm\session.py", line 1256, in commit
    self._prepare_impl()
    │    └ <function SessionTransaction._prepare_impl at 0x0000028F701B49D0>
    └ <sqlalchemy.orm.session.SessionTransaction object at 0x0000028F70C53080>

  File "<string>", line 2, in _prepare_impl

  File "D:\Anaconda\envs\api.project.com\lib\site-packages\sqlalchemy\orm\state_changes.py", line 139, in _go
    ret_value = fn(self, *arg, **kw)
                │  │      │      └ {}
                │  │      └ ()
                │  └ <sqlalchemy.orm.session.SessionTransaction object at 0x0000028F70C53080>
                └ <function SessionTransaction._prepare_impl at 0x0000028F701B48B0>

  File "D:\Anaconda\envs\api.project.com\lib\site-packages\sqlalchemy\orm\session.py", line 1231, in _prepare_impl
    self.session.flush()
    │    │       └ <function Session.flush at 0x0000028F701BE670>
    │    └ <sqlalchemy.orm.session.Session object at 0x0000028F70C55430>
    └ <sqlalchemy.orm.session.SessionTransaction object at 0x0000028F70C53080>

  File "D:\Anaconda\envs\api.project.com\lib\site-packages\sqlalchemy\orm\session.py", line 4312, in flush
    self._flush(objects)
    │    │      └ None
    │    └ <function Session._flush at 0x0000028F701BE820>
    └ <sqlalchemy.orm.session.Session object at 0x0000028F70C55430>

  File "D:\Anaconda\envs\api.project.com\lib\site-packages\sqlalchemy\orm\session.py", line 4448, in _flush
    transaction.rollback(_capture_exception=True)
    │           └ <function SessionTransaction.rollback at 0x0000028F701B4D30>
    └ <sqlalchemy.orm.session.SessionTransaction object at 0x0000028F70C65100>

  File "D:\Anaconda\envs\api.project.com\lib\site-packages\sqlalchemy\util\langhelpers.py", line 146, in __exit__
    raise exc_value.with_traceback(exc_tb)
          │         │              └ <traceback object at 0x0000028F70C53780>
          │         └ <method 'with_traceback' of 'BaseException' objects>
          └ DataError('(pymysql.err.DataError) (1264, "Out of range value for column \'user_id\' at row 1")')

  File "D:\Anaconda\envs\api.project.com\lib\site-packages\sqlalchemy\orm\session.py", line 4408, in _flush
    flush_context.execute()
    │             └ <function UOWTransaction.execute at 0x0000028F701A99D0>
    └ <sqlalchemy.orm.unitofwork.UOWTransaction object at 0x0000028F70C55CD0>

  File "D:\Anaconda\envs\api.project.com\lib\site-packages\sqlalchemy\orm\unitofwork.py", line 466, in execute
    rec.execute(self)
    │   │       └ <sqlalchemy.orm.unitofwork.UOWTransaction object at 0x0000028F70C55CD0>
    │   └ <function SaveUpdateAll.execute at 0x0000028F701AA310>
    └ SaveUpdateAll(Mapper[UserInfo(user_info)])

  File "D:\Anaconda\envs\api.project.com\lib\site-packages\sqlalchemy\orm\unitofwork.py", line 642, in execute
    util.preloaded.orm_persistence.save_obj(
    │    │         │               └ <function save_obj at 0x0000028F7017F9D0>
    │    │         └ <module 'sqlalchemy.orm.persistence' from 'D:\\Anaconda\\envs\\api.project.com\\lib\\site-packages\\sqlalchemy\\orm\\persiste...
    │    └ <module 'sqlalchemy.util.preloaded' from 'D:\\Anaconda\\envs\\api.project.com\\lib\\site-packages\\sqlalchemy\\util\\preloade...
    └ <module 'sqlalchemy.util' from 'D:\\Anaconda\\envs\\api.project.com\\lib\\site-packages\\sqlalchemy\\util\\__init__.py'>

  File "D:\Anaconda\envs\api.project.com\lib\site-packages\sqlalchemy\orm\persistence.py", line 93, in save_obj
    _emit_insert_statements(
    └ <function _emit_insert_statements at 0x0000028F7018A0D0>

  File "D:\Anaconda\envs\api.project.com\lib\site-packages\sqlalchemy\orm\persistence.py", line 1043, in _emit_insert_statements
    result = connection.execute(
             │          └ <function Connection.execute at 0x0000028F6FCD81F0>
             └ <sqlalchemy.engine.base.Connection object at 0x0000028F70C55D60>

  File "D:\Anaconda\envs\api.project.com\lib\site-packages\sqlalchemy\engine\base.py", line 1416, in execute
    return meth(
           └ <bound method ClauseElement._execute_on_connection of <sqlalchemy.sql.dml.Insert object at 0x0000028F708ED190>>

  File "D:\Anaconda\envs\api.project.com\lib\site-packages\sqlalchemy\sql\elements.py", line 516, in _execute_on_connection
    return connection._execute_clauseelement(
           │          └ <function Connection._execute_clauseelement at 0x0000028F6FCD84C0>
           └ <sqlalchemy.engine.base.Connection object at 0x0000028F70C55D60>

  File "D:\Anaconda\envs\api.project.com\lib\site-packages\sqlalchemy\engine\base.py", line 1639, in _execute_clauseelement
    ret = self._execute_context(
          │    └ <function Connection._execute_context at 0x0000028F6FCD8670>
          └ <sqlalchemy.engine.base.Connection object at 0x0000028F70C55D60>

  File "D:\Anaconda\envs\api.project.com\lib\site-packages\sqlalchemy\engine\base.py", line 1848, in _execute_context
    return self._exec_single_context(
           │    └ <function Connection._exec_single_context at 0x0000028F6FCD8700>
           └ <sqlalchemy.engine.base.Connection object at 0x0000028F70C55D60>

  File "D:\Anaconda\envs\api.project.com\lib\site-packages\sqlalchemy\engine\base.py", line 1988, in _exec_single_context
    self._handle_dbapi_exception(
    │    └ <function Connection._handle_dbapi_exception at 0x0000028F6FCD8940>
    └ <sqlalchemy.engine.base.Connection object at 0x0000028F70C55D60>

  File "D:\Anaconda\envs\api.project.com\lib\site-packages\sqlalchemy\engine\base.py", line 2343, in _handle_dbapi_exception
    raise sqlalchemy_exception.with_traceback(exc_info[2]) from e
          │                    │              │                 └ DataError(1264, "Out of range value for column 'user_id' at row 1")
          │                    │              └ (<class 'pymysql.err.DataError'>, DataError(1264, "Out of range value for column 'user_id' at row 1"), <traceback object at 0...
          │                    └ <method 'with_traceback' of 'BaseException' objects>
          └ DataError('(pymysql.err.DataError) (1264, "Out of range value for column \'user_id\' at row 1")')

  File "D:\Anaconda\envs\api.project.com\lib\site-packages\sqlalchemy\engine\base.py", line 1969, in _exec_single_context
    self.dialect.do_execute(
    │    │       └ <function DefaultDialect.do_execute at 0x0000028F6FEE48B0>
    │    └ <sqlalchemy.dialects.mysql.pymysql.MySQLDialect_pymysql object at 0x0000028F70312040>
    └ <sqlalchemy.engine.base.Connection object at 0x0000028F70C55D60>

  File "D:\Anaconda\envs\api.project.com\lib\site-packages\sqlalchemy\engine\default.py", line 922, in do_execute
    cursor.execute(statement, parameters)
    │      │       │          └ {'user_id': '2023122816143780', 'user_name': '223', 'profile_picture': None, 'signature': None, 'gender': None, 'phone': None...
    │      │       └ 'INSERT INTO user_info (user_id, user_name, profile_picture, signature, gender, phone, date_of_birth, address) VALUES (%(user...
    │      └ <function Cursor.execute at 0x0000028F704F3700>
    └ <pymysql.cursors.Cursor object at 0x0000028F70C55E80>

  File "D:\Anaconda\envs\api.project.com\lib\site-packages\pymysql\cursors.py", line 158, in execute
    result = self._query(query)
             │    │      └ "INSERT INTO user_info (user_id, user_name, profile_picture, signature, gender, phone, date_of_birth, address) VALUES ('20231...
             │    └ <function Cursor._query at 0x0000028F704F3B80>
             └ <pymysql.cursors.Cursor object at 0x0000028F70C55E80>

  File "D:\Anaconda\envs\api.project.com\lib\site-packages\pymysql\cursors.py", line 325, in _query
    conn.query(q)
    │    │     └ "INSERT INTO user_info (user_id, user_name, profile_picture, signature, gender, phone, date_of_birth, address) VALUES ('20231...
    │    └ <function Connection.query at 0x0000028F704FEC10>
    └ <pymysql.connections.Connection object at 0x0000028F708B9E20>

  File "D:\Anaconda\envs\api.project.com\lib\site-packages\pymysql\connections.py", line 549, in query
    self._affected_rows = self._read_query_result(unbuffered=unbuffered)
    │    │                │    │                             └ False
    │    │                │    └ <function Connection._read_query_result at 0x0000028F704FF280>
    │    │                └ <pymysql.connections.Connection object at 0x0000028F708B9E20>
    │    └ 1
    └ <pymysql.connections.Connection object at 0x0000028F708B9E20>

  File "D:\Anaconda\envs\api.project.com\lib\site-packages\pymysql\connections.py", line 779, in _read_query_result
    result.read()
    │      └ <function MySQLResult.read at 0x0000028F704FFA60>
    └ <pymysql.connections.MySQLResult object at 0x0000028F70C55E20>

  File "D:\Anaconda\envs\api.project.com\lib\site-packages\pymysql\connections.py", line 1157, in read
    first_packet = self.connection._read_packet()
                   │    └ None
                   └ <pymysql.connections.MySQLResult object at 0x0000028F70C55E20>

  File "D:\Anaconda\envs\api.project.com\lib\site-packages\pymysql\connections.py", line 729, in _read_packet
    packet.raise_for_error()
    │      └ <function MysqlPacket.raise_for_error at 0x0000028F704FC820>
    └ <pymysql.protocol.MysqlPacket object at 0x0000028F70C55EE0>

  File "D:\Anaconda\envs\api.project.com\lib\site-packages\pymysql\protocol.py", line 221, in raise_for_error
    err.raise_mysql_exception(self._data)
    │   │                     │    └ <member '_data' of 'MysqlPacket' objects>
    │   │                     └ <pymysql.protocol.MysqlPacket object at 0x0000028F70C55EE0>
    │   └ <function raise_mysql_exception at 0x0000028F703A8CA0>
    └ <module 'pymysql.err' from 'D:\\Anaconda\\envs\\api.project.com\\lib\\site-packages\\pymysql\\err.py'>

  File "D:\Anaconda\envs\api.project.com\lib\site-packages\pymysql\err.py", line 143, in raise_mysql_exception
    raise errorclass(errno, errval)
          │          │      └ "Out of range value for column 'user_id' at row 1"
          │          └ 1264
          └ <class 'pymysql.err.DataError'>

sqlalchemy.exc.DataError: (pymysql.err.DataError) (1264, "Out of range value for column 'user_id' at row 1")
[SQL: INSERT INTO user_info (user_id, user_name, profile_picture, signature, gender, phone, date_of_birth, address) VALUES (%(user_id)s, %(user_name)s, %(profile_picture)s, %(signature)s, %(gender)s, %(phone)s, %(date_of_birth)s, %(address)s)]
[parameters: {'user_id': '2023122816143780', 'user_name': '223', 'profile_picture': None, 'signature': None, 'gender': None, 'phone': None, 'date_of_birth': None, 'address': None}]
(Background on this error at: https://sqlalche.me/e/20/9h9h)
2023-12-28 16:14:49.991 | ERROR    | utils.loggings:exception:40 - (pymysql.err.DataError) (1264, "Out of range value for column 'user_id' at row 1")
[SQL: INSERT INTO user_info (user_id, user_name, profile_picture, signature, gender, phone, date_of_birth, address) VALUES (%(user_id)s, %(user_name)s, %(profile_picture)s, %(signature)s, %(gender)s, %(phone)s, %(date_of_birth)s, %(address)s)]
[parameters: {'user_id': '2023122816143216', 'user_name': '223', 'profile_picture': None, 'signature': None, 'gender': None, 'phone': None, 'date_of_birth': None, 'address': None}]
(Background on this error at: https://sqlalche.me/e/20/9h9h)
Traceback (most recent call last):

  File "D:\Anaconda\envs\api.project.com\lib\site-packages\sqlalchemy\engine\base.py", line 1969, in _exec_single_context
    self.dialect.do_execute(
    │    │       └ <function DefaultDialect.do_execute at 0x0000028F6FEE48B0>
    │    └ <sqlalchemy.dialects.mysql.pymysql.MySQLDialect_pymysql object at 0x0000028F70312040>
    └ <sqlalchemy.engine.base.Connection object at 0x0000028F70C6BC10>

  File "D:\Anaconda\envs\api.project.com\lib\site-packages\sqlalchemy\engine\default.py", line 922, in do_execute
    cursor.execute(statement, parameters)
    │      │       │          └ {'user_id': '2023122816143216', 'user_name': '223', 'profile_picture': None, 'signature': None, 'gender': None, 'phone': None...
    │      │       └ 'INSERT INTO user_info (user_id, user_name, profile_picture, signature, gender, phone, date_of_birth, address) VALUES (%(user...
    │      └ <function Cursor.execute at 0x0000028F704F3700>
    └ <pymysql.cursors.Cursor object at 0x0000028F70C6BD60>

  File "D:\Anaconda\envs\api.project.com\lib\site-packages\pymysql\cursors.py", line 158, in execute
    result = self._query(query)
             │    │      └ "INSERT INTO user_info (user_id, user_name, profile_picture, signature, gender, phone, date_of_birth, address) VALUES ('20231...
             │    └ <function Cursor._query at 0x0000028F704F3B80>
             └ <pymysql.cursors.Cursor object at 0x0000028F70C6BD60>

  File "D:\Anaconda\envs\api.project.com\lib\site-packages\pymysql\cursors.py", line 325, in _query
    conn.query(q)
    │    │     └ "INSERT INTO user_info (user_id, user_name, profile_picture, signature, gender, phone, date_of_birth, address) VALUES ('20231...
    │    └ <function Connection.query at 0x0000028F704FEC10>
    └ <pymysql.connections.Connection object at 0x0000028F708B9E20>

  File "D:\Anaconda\envs\api.project.com\lib\site-packages\pymysql\connections.py", line 549, in query
    self._affected_rows = self._read_query_result(unbuffered=unbuffered)
    │    │                │    │                             └ False
    │    │                │    └ <function Connection._read_query_result at 0x0000028F704FF280>
    │    │                └ <pymysql.connections.Connection object at 0x0000028F708B9E20>
    │    └ 1
    └ <pymysql.connections.Connection object at 0x0000028F708B9E20>

  File "D:\Anaconda\envs\api.project.com\lib\site-packages\pymysql\connections.py", line 779, in _read_query_result
    result.read()
    │      └ <function MySQLResult.read at 0x0000028F704FFA60>
    └ <pymysql.connections.MySQLResult object at 0x0000028F70C6BD00>

  File "D:\Anaconda\envs\api.project.com\lib\site-packages\pymysql\connections.py", line 1157, in read
    first_packet = self.connection._read_packet()
                   │    └ None
                   └ <pymysql.connections.MySQLResult object at 0x0000028F70C6BD00>

  File "D:\Anaconda\envs\api.project.com\lib\site-packages\pymysql\connections.py", line 729, in _read_packet
    packet.raise_for_error()
    │      └ <function MysqlPacket.raise_for_error at 0x0000028F704FC820>
    └ <pymysql.protocol.MysqlPacket object at 0x0000028F70C6BEB0>

  File "D:\Anaconda\envs\api.project.com\lib\site-packages\pymysql\protocol.py", line 221, in raise_for_error
    err.raise_mysql_exception(self._data)
    │   │                     │    └ <member '_data' of 'MysqlPacket' objects>
    │   │                     └ <pymysql.protocol.MysqlPacket object at 0x0000028F70C6BEB0>
    │   └ <function raise_mysql_exception at 0x0000028F703A8CA0>
    └ <module 'pymysql.err' from 'D:\\Anaconda\\envs\\api.project.com\\lib\\site-packages\\pymysql\\err.py'>

  File "D:\Anaconda\envs\api.project.com\lib\site-packages\pymysql\err.py", line 143, in raise_mysql_exception
    raise errorclass(errno, errval)
          │          │      └ "Out of range value for column 'user_id' at row 1"
          │          └ 1264
          └ <class 'pymysql.err.DataError'>

pymysql.err.DataError: (1264, "Out of range value for column 'user_id' at row 1")


The above exception was the direct cause of the following exception:


Traceback (most recent call last):

  File "D:\Anaconda\envs\api.project.com\lib\threading.py", line 890, in _bootstrap
    self._bootstrap_inner()
    │    └ <function Thread._bootstrap_inner at 0x0000028F6C694430>
    └ <Thread(Thread-1, started daemon 22124)>

  File "D:\Anaconda\envs\api.project.com\lib\threading.py", line 932, in _bootstrap_inner
    self.run()
    │    └ <function Thread.run at 0x0000028F6C694160>
    └ <Thread(Thread-1, started daemon 22124)>

  File "D:\Anaconda\envs\api.project.com\lib\threading.py", line 870, in run
    self._target(*self._args, **self._kwargs)
    │    │        │    │        │    └ {}
    │    │        │    │        └ <Thread(Thread-1, started daemon 22124)>
    │    │        │    └ ()
    │    │        └ <Thread(Thread-1, started daemon 22124)>
    │    └ <bound method BaseWSGIServer.serve_forever of <werkzeug.serving.BaseWSGIServer object at 0x0000028F70854220>>
    └ <Thread(Thread-1, started daemon 22124)>

  File "D:\Anaconda\envs\api.project.com\lib\site-packages\werkzeug\serving.py", line 806, in serve_forever
    super().serve_forever(poll_interval=poll_interval)
                                        └ 0.5

  File "D:\Anaconda\envs\api.project.com\lib\socketserver.py", line 237, in serve_forever
    self._handle_request_noblock()
    │    └ <function BaseServer._handle_request_noblock at 0x0000028F6C696A60>
    └ <werkzeug.serving.BaseWSGIServer object at 0x0000028F70854220>

  File "D:\Anaconda\envs\api.project.com\lib\socketserver.py", line 316, in _handle_request_noblock
    self.process_request(request, client_address)
    │    │               │        └ ('127.0.0.1', 23490)
    │    │               └ <socket.socket fd=992, family=AddressFamily.AF_INET, type=SocketKind.SOCK_STREAM, proto=0, laddr=('127.0.0.1', 5000), raddr=(...
    │    └ <function BaseServer.process_request at 0x0000028F6C696C10>
    └ <werkzeug.serving.BaseWSGIServer object at 0x0000028F70854220>

  File "D:\Anaconda\envs\api.project.com\lib\socketserver.py", line 347, in process_request
    self.finish_request(request, client_address)
    │    │              │        └ ('127.0.0.1', 23490)
    │    │              └ <socket.socket fd=992, family=AddressFamily.AF_INET, type=SocketKind.SOCK_STREAM, proto=0, laddr=('127.0.0.1', 5000), raddr=(...
    │    └ <function BaseServer.finish_request at 0x0000028F6C696D30>
    └ <werkzeug.serving.BaseWSGIServer object at 0x0000028F70854220>

  File "D:\Anaconda\envs\api.project.com\lib\socketserver.py", line 360, in finish_request
    self.RequestHandlerClass(request, client_address, self)
    │    │                   │        │               └ <werkzeug.serving.BaseWSGIServer object at 0x0000028F70854220>
    │    │                   │        └ ('127.0.0.1', 23490)
    │    │                   └ <socket.socket fd=992, family=AddressFamily.AF_INET, type=SocketKind.SOCK_STREAM, proto=0, laddr=('127.0.0.1', 5000), raddr=(...
    │    └ <class 'werkzeug.serving.WSGIRequestHandler'>
    └ <werkzeug.serving.BaseWSGIServer object at 0x0000028F70854220>

  File "D:\Anaconda\envs\api.project.com\lib\socketserver.py", line 720, in __init__
    self.handle()
    │    └ <function WSGIRequestHandler.handle at 0x0000028F6E3F3CA0>
    └ <werkzeug.serving.WSGIRequestHandler object at 0x0000028F70C553D0>

  File "D:\Anaconda\envs\api.project.com\lib\site-packages\werkzeug\serving.py", line 390, in handle
    super().handle()

  File "D:\Anaconda\envs\api.project.com\lib\http\server.py", line 426, in handle
    self.handle_one_request()
    │    └ <function BaseHTTPRequestHandler.handle_one_request at 0x0000028F6E22B1F0>
    └ <werkzeug.serving.WSGIRequestHandler object at 0x0000028F70C553D0>

  File "D:\Anaconda\envs\api.project.com\lib\http\server.py", line 414, in handle_one_request
    method()
    └ <bound method WSGIRequestHandler.run_wsgi of <werkzeug.serving.WSGIRequestHandler object at 0x0000028F70C553D0>>

  File "D:\Anaconda\envs\api.project.com\lib\site-packages\werkzeug\serving.py", line 362, in run_wsgi
    execute(self.server.app)
    │       │    │      └ <werkzeug.debug.DebuggedApplication object at 0x0000028F708114C0>
    │       │    └ <werkzeug.serving.BaseWSGIServer object at 0x0000028F70854220>
    │       └ <werkzeug.serving.WSGIRequestHandler object at 0x0000028F70C553D0>
    └ <function WSGIRequestHandler.run_wsgi.<locals>.execute at 0x0000028F70BE4B80>

  File "D:\Anaconda\envs\api.project.com\lib\site-packages\werkzeug\serving.py", line 325, in execute
    for data in application_iter:
                └ <generator object DebuggedApplication.debug_application at 0x0000028F7088DBA0>

  File "D:\Anaconda\envs\api.project.com\lib\site-packages\werkzeug\debug\__init__.py", line 330, in debug_application
    app_iter = self.app(environ, start_response)
               │    │   │        └ <function WSGIRequestHandler.run_wsgi.<locals>.start_response at 0x0000028F70BE48B0>
               │    │   └ {'wsgi.version': (1, 0), 'wsgi.url_scheme': 'http', 'wsgi.input': <_io.BufferedReader name=992>, 'wsgi.errors': <_io.TextIOWr...
               │    └ <Flask 'app'>
               └ <werkzeug.debug.DebuggedApplication object at 0x0000028F708114C0>

  File "D:\Anaconda\envs\api.project.com\lib\site-packages\flask\app.py", line 2213, in __call__
    return self.wsgi_app(environ, start_response)
           │    │        │        └ <function WSGIRequestHandler.run_wsgi.<locals>.start_response at 0x0000028F70BE48B0>
           │    │        └ {'wsgi.version': (1, 0), 'wsgi.url_scheme': 'http', 'wsgi.input': <_io.BufferedReader name=992>, 'wsgi.errors': <_io.TextIOWr...
           │    └ <function Flask.wsgi_app at 0x0000028F6ED02E50>
           └ <Flask 'app'>

  File "D:\Anaconda\envs\api.project.com\lib\site-packages\flask\app.py", line 2190, in wsgi_app
    response = self.full_dispatch_request()
               │    └ <function Flask.full_dispatch_request at 0x0000028F6ED023A0>
               └ <Flask 'app'>

  File "D:\Anaconda\envs\api.project.com\lib\site-packages\flask\app.py", line 1484, in full_dispatch_request
    rv = self.dispatch_request()
         │    └ <function Flask.dispatch_request at 0x0000028F6ED02310>
         └ <Flask 'app'>

  File "D:\Anaconda\envs\api.project.com\lib\site-packages\flask\app.py", line 1469, in dispatch_request
    return self.ensure_sync(self.view_functions[rule.endpoint])(**view_args)
           │    │           │    │              │    │            └ {}
           │    │           │    │              │    └ 'userInfo.UserInfo'
           │    │           │    │              └ <Rule '/api_1_0/userInfo' (PUT, DELETE, OPTIONS, HEAD, POST, GET) -> userInfo.UserInfo>
           │    │           │    └ {'static': <function Flask.__init__.<locals>.<lambda> at 0x0000028F702EEF70>, 'apiversion.Apiversion': <function View.as_view...
           │    │           └ <Flask 'app'>
           │    └ <function Flask.ensure_sync at 0x0000028F6ED025E0>
           └ <Flask 'app'>

  File "D:\Anaconda\envs\api.project.com\lib\site-packages\flask_restful\__init__.py", line 489, in wrapper
    resp = resource(*args, **kwargs)
           │         │       └ {}
           │         └ ()
           └ <function View.as_view.<locals>.view at 0x0000028F70614550>

  File "D:\Anaconda\envs\api.project.com\lib\site-packages\flask\views.py", line 109, in view
    return current_app.ensure_sync(self.dispatch_request)(**kwargs)
           │                       │    │                   └ {}
           │                       │    └ <function Resource.dispatch_request at 0x0000028F7051DA60>
           │                       └ <api_1_0.userInfoResource.userInfoResource.UserInfoResource object at 0x0000028F70C6B490>
           └ <Flask 'app'>

  File "D:\Anaconda\envs\api.project.com\lib\site-packages\flask_restful\__init__.py", line 604, in dispatch_request
    resp = meth(*args, **kwargs)
           │     │       └ {}
           │     └ ()
           └ <bound method UserInfoResource.post of <class 'api_1_0.userInfoResource.userInfoResource.UserInfoResource'>>

  File "D:\Python_RESTfulAPI_Codegen\dist\dist_1703676800155\api.project.com\api_1_0\userInfoResource\userInfoResource.py", line 182, in post
    res = UserInfoController.add(**kwargs)
          │                  │     └ {'user_name': '223'}
          │                  └ <classmethod object at 0x0000028F70611910>
          └ <class 'controller.userInfoController.UserInfoController'>

> File "D:\Python_RESTfulAPI_Codegen\dist\dist_1703676800155\api.project.com\controller\userInfoController.py", line 38, in add
    db.session.commit()
    │  │       └ <function scoped_session.commit at 0x0000028F702650D0>
    │  └ <sqlalchemy.orm.scoping.scoped_session object at 0x0000028F6ED27160>
    └ <SQLAlchemy mysql+pymysql://root:***@8.130.89.73:3306/skill_sharing?charset=utf8>

  File "D:\Anaconda\envs\api.project.com\lib\site-packages\sqlalchemy\orm\scoping.py", line 598, in commit
    return self._proxied.commit()
           │    └ <property object at 0x0000028F7025F630>
           └ <sqlalchemy.orm.scoping.scoped_session object at 0x0000028F6ED27160>

  File "D:\Anaconda\envs\api.project.com\lib\site-packages\sqlalchemy\orm\session.py", line 1969, in commit
    trans.commit(_to_root=True)
    │     └ <function SessionTransaction.commit at 0x0000028F701B4AF0>
    └ <sqlalchemy.orm.session.SessionTransaction object at 0x0000028F70C72140>

  File "<string>", line 2, in commit

  File "D:\Anaconda\envs\api.project.com\lib\site-packages\sqlalchemy\orm\state_changes.py", line 139, in _go
    ret_value = fn(self, *arg, **kw)
                │  │      │      └ {'_to_root': True}
                │  │      └ ()
                │  └ <sqlalchemy.orm.session.SessionTransaction object at 0x0000028F70C72140>
                └ <function SessionTransaction.commit at 0x0000028F701B4A60>

  File "D:\Anaconda\envs\api.project.com\lib\site-packages\sqlalchemy\orm\session.py", line 1256, in commit
    self._prepare_impl()
    │    └ <function SessionTransaction._prepare_impl at 0x0000028F701B49D0>
    └ <sqlalchemy.orm.session.SessionTransaction object at 0x0000028F70C72140>

  File "<string>", line 2, in _prepare_impl

  File "D:\Anaconda\envs\api.project.com\lib\site-packages\sqlalchemy\orm\state_changes.py", line 139, in _go
    ret_value = fn(self, *arg, **kw)
                │  │      │      └ {}
                │  │      └ ()
                │  └ <sqlalchemy.orm.session.SessionTransaction object at 0x0000028F70C72140>
                └ <function SessionTransaction._prepare_impl at 0x0000028F701B48B0>

  File "D:\Anaconda\envs\api.project.com\lib\site-packages\sqlalchemy\orm\session.py", line 1231, in _prepare_impl
    self.session.flush()
    │    │       └ <function Session.flush at 0x0000028F701BE670>
    │    └ <sqlalchemy.orm.session.Session object at 0x0000028F70C6B2E0>
    └ <sqlalchemy.orm.session.SessionTransaction object at 0x0000028F70C72140>

  File "D:\Anaconda\envs\api.project.com\lib\site-packages\sqlalchemy\orm\session.py", line 4312, in flush
    self._flush(objects)
    │    │      └ None
    │    └ <function Session._flush at 0x0000028F701BE820>
    └ <sqlalchemy.orm.session.Session object at 0x0000028F70C6B2E0>

  File "D:\Anaconda\envs\api.project.com\lib\site-packages\sqlalchemy\orm\session.py", line 4448, in _flush
    transaction.rollback(_capture_exception=True)
    │           └ <function SessionTransaction.rollback at 0x0000028F701B4D30>
    └ <sqlalchemy.orm.session.SessionTransaction object at 0x0000028F70C72280>

  File "D:\Anaconda\envs\api.project.com\lib\site-packages\sqlalchemy\util\langhelpers.py", line 146, in __exit__
    raise exc_value.with_traceback(exc_tb)
          │         │              └ <traceback object at 0x0000028F70C6FB00>
          │         └ <method 'with_traceback' of 'BaseException' objects>
          └ DataError('(pymysql.err.DataError) (1264, "Out of range value for column \'user_id\' at row 1")')

  File "D:\Anaconda\envs\api.project.com\lib\site-packages\sqlalchemy\orm\session.py", line 4408, in _flush
    flush_context.execute()
    │             └ <function UOWTransaction.execute at 0x0000028F701A99D0>
    └ <sqlalchemy.orm.unitofwork.UOWTransaction object at 0x0000028F70C6BB80>

  File "D:\Anaconda\envs\api.project.com\lib\site-packages\sqlalchemy\orm\unitofwork.py", line 466, in execute
    rec.execute(self)
    │   │       └ <sqlalchemy.orm.unitofwork.UOWTransaction object at 0x0000028F70C6BB80>
    │   └ <function SaveUpdateAll.execute at 0x0000028F701AA310>
    └ SaveUpdateAll(Mapper[UserInfo(user_info)])

  File "D:\Anaconda\envs\api.project.com\lib\site-packages\sqlalchemy\orm\unitofwork.py", line 642, in execute
    util.preloaded.orm_persistence.save_obj(
    │    │         │               └ <function save_obj at 0x0000028F7017F9D0>
    │    │         └ <module 'sqlalchemy.orm.persistence' from 'D:\\Anaconda\\envs\\api.project.com\\lib\\site-packages\\sqlalchemy\\orm\\persiste...
    │    └ <module 'sqlalchemy.util.preloaded' from 'D:\\Anaconda\\envs\\api.project.com\\lib\\site-packages\\sqlalchemy\\util\\preloade...
    └ <module 'sqlalchemy.util' from 'D:\\Anaconda\\envs\\api.project.com\\lib\\site-packages\\sqlalchemy\\util\\__init__.py'>

  File "D:\Anaconda\envs\api.project.com\lib\site-packages\sqlalchemy\orm\persistence.py", line 93, in save_obj
    _emit_insert_statements(
    └ <function _emit_insert_statements at 0x0000028F7018A0D0>

  File "D:\Anaconda\envs\api.project.com\lib\site-packages\sqlalchemy\orm\persistence.py", line 1043, in _emit_insert_statements
    result = connection.execute(
             │          └ <function Connection.execute at 0x0000028F6FCD81F0>
             └ <sqlalchemy.engine.base.Connection object at 0x0000028F70C6BC10>

  File "D:\Anaconda\envs\api.project.com\lib\site-packages\sqlalchemy\engine\base.py", line 1416, in execute
    return meth(
           └ <bound method ClauseElement._execute_on_connection of <sqlalchemy.sql.dml.Insert object at 0x0000028F708ED190>>

  File "D:\Anaconda\envs\api.project.com\lib\site-packages\sqlalchemy\sql\elements.py", line 516, in _execute_on_connection
    return connection._execute_clauseelement(
           │          └ <function Connection._execute_clauseelement at 0x0000028F6FCD84C0>
           └ <sqlalchemy.engine.base.Connection object at 0x0000028F70C6BC10>

  File "D:\Anaconda\envs\api.project.com\lib\site-packages\sqlalchemy\engine\base.py", line 1639, in _execute_clauseelement
    ret = self._execute_context(
          │    └ <function Connection._execute_context at 0x0000028F6FCD8670>
          └ <sqlalchemy.engine.base.Connection object at 0x0000028F70C6BC10>

  File "D:\Anaconda\envs\api.project.com\lib\site-packages\sqlalchemy\engine\base.py", line 1848, in _execute_context
    return self._exec_single_context(
           │    └ <function Connection._exec_single_context at 0x0000028F6FCD8700>
           └ <sqlalchemy.engine.base.Connection object at 0x0000028F70C6BC10>

  File "D:\Anaconda\envs\api.project.com\lib\site-packages\sqlalchemy\engine\base.py", line 1988, in _exec_single_context
    self._handle_dbapi_exception(
    │    └ <function Connection._handle_dbapi_exception at 0x0000028F6FCD8940>
    └ <sqlalchemy.engine.base.Connection object at 0x0000028F70C6BC10>

  File "D:\Anaconda\envs\api.project.com\lib\site-packages\sqlalchemy\engine\base.py", line 2343, in _handle_dbapi_exception
    raise sqlalchemy_exception.with_traceback(exc_info[2]) from e
          │                    │              │                 └ DataError(1264, "Out of range value for column 'user_id' at row 1")
          │                    │              └ (<class 'pymysql.err.DataError'>, DataError(1264, "Out of range value for column 'user_id' at row 1"), <traceback object at 0...
          │                    └ <method 'with_traceback' of 'BaseException' objects>
          └ DataError('(pymysql.err.DataError) (1264, "Out of range value for column \'user_id\' at row 1")')

  File "D:\Anaconda\envs\api.project.com\lib\site-packages\sqlalchemy\engine\base.py", line 1969, in _exec_single_context
    self.dialect.do_execute(
    │    │       └ <function DefaultDialect.do_execute at 0x0000028F6FEE48B0>
    │    └ <sqlalchemy.dialects.mysql.pymysql.MySQLDialect_pymysql object at 0x0000028F70312040>
    └ <sqlalchemy.engine.base.Connection object at 0x0000028F70C6BC10>

  File "D:\Anaconda\envs\api.project.com\lib\site-packages\sqlalchemy\engine\default.py", line 922, in do_execute
    cursor.execute(statement, parameters)
    │      │       │          └ {'user_id': '2023122816143216', 'user_name': '223', 'profile_picture': None, 'signature': None, 'gender': None, 'phone': None...
    │      │       └ 'INSERT INTO user_info (user_id, user_name, profile_picture, signature, gender, phone, date_of_birth, address) VALUES (%(user...
    │      └ <function Cursor.execute at 0x0000028F704F3700>
    └ <pymysql.cursors.Cursor object at 0x0000028F70C6BD60>

  File "D:\Anaconda\envs\api.project.com\lib\site-packages\pymysql\cursors.py", line 158, in execute
    result = self._query(query)
             │    │      └ "INSERT INTO user_info (user_id, user_name, profile_picture, signature, gender, phone, date_of_birth, address) VALUES ('20231...
             │    └ <function Cursor._query at 0x0000028F704F3B80>
             └ <pymysql.cursors.Cursor object at 0x0000028F70C6BD60>

  File "D:\Anaconda\envs\api.project.com\lib\site-packages\pymysql\cursors.py", line 325, in _query
    conn.query(q)
    │    │     └ "INSERT INTO user_info (user_id, user_name, profile_picture, signature, gender, phone, date_of_birth, address) VALUES ('20231...
    │    └ <function Connection.query at 0x0000028F704FEC10>
    └ <pymysql.connections.Connection object at 0x0000028F708B9E20>

  File "D:\Anaconda\envs\api.project.com\lib\site-packages\pymysql\connections.py", line 549, in query
    self._affected_rows = self._read_query_result(unbuffered=unbuffered)
    │    │                │    │                             └ False
    │    │                │    └ <function Connection._read_query_result at 0x0000028F704FF280>
    │    │                └ <pymysql.connections.Connection object at 0x0000028F708B9E20>
    │    └ 1
    └ <pymysql.connections.Connection object at 0x0000028F708B9E20>

  File "D:\Anaconda\envs\api.project.com\lib\site-packages\pymysql\connections.py", line 779, in _read_query_result
    result.read()
    │      └ <function MySQLResult.read at 0x0000028F704FFA60>
    └ <pymysql.connections.MySQLResult object at 0x0000028F70C6BD00>

  File "D:\Anaconda\envs\api.project.com\lib\site-packages\pymysql\connections.py", line 1157, in read
    first_packet = self.connection._read_packet()
                   │    └ None
                   └ <pymysql.connections.MySQLResult object at 0x0000028F70C6BD00>

  File "D:\Anaconda\envs\api.project.com\lib\site-packages\pymysql\connections.py", line 729, in _read_packet
    packet.raise_for_error()
    │      └ <function MysqlPacket.raise_for_error at 0x0000028F704FC820>
    └ <pymysql.protocol.MysqlPacket object at 0x0000028F70C6BEB0>

  File "D:\Anaconda\envs\api.project.com\lib\site-packages\pymysql\protocol.py", line 221, in raise_for_error
    err.raise_mysql_exception(self._data)
    │   │                     │    └ <member '_data' of 'MysqlPacket' objects>
    │   │                     └ <pymysql.protocol.MysqlPacket object at 0x0000028F70C6BEB0>
    │   └ <function raise_mysql_exception at 0x0000028F703A8CA0>
    └ <module 'pymysql.err' from 'D:\\Anaconda\\envs\\api.project.com\\lib\\site-packages\\pymysql\\err.py'>

  File "D:\Anaconda\envs\api.project.com\lib\site-packages\pymysql\err.py", line 143, in raise_mysql_exception
    raise errorclass(errno, errval)
          │          │      └ "Out of range value for column 'user_id' at row 1"
          │          └ 1264
          └ <class 'pymysql.err.DataError'>

sqlalchemy.exc.DataError: (pymysql.err.DataError) (1264, "Out of range value for column 'user_id' at row 1")
[SQL: INSERT INTO user_info (user_id, user_name, profile_picture, signature, gender, phone, date_of_birth, address) VALUES (%(user_id)s, %(user_name)s, %(profile_picture)s, %(signature)s, %(gender)s, %(phone)s, %(date_of_birth)s, %(address)s)]
[parameters: {'user_id': '2023122816143216', 'user_name': '223', 'profile_picture': None, 'signature': None, 'gender': None, 'phone': None, 'date_of_birth': None, 'address': None}]
(Background on this error at: https://sqlalche.me/e/20/9h9h)
