2023-12-28 16:56:21.442 | ERROR    | utils.loggings:exception:40 - (pymysql.err.OperationalError) (2013, 'Lost connection to MySQL server during query ([WinError 10060] 由于连接方在一段时间后没有正确答复或连接的主机没有反应，连接尝试失败。)')
[SQL: INSERT INTO user_info (user_id, user_name, profile_picture, signature, gender, phone, date_of_birth, address) VALUES (%(user_id)s, %(user_name)s, %(profile_picture)s, %(signature)s, %(gender)s, %(phone)s, %(date_of_birth)s, %(address)s)]
[parameters: {'user_id': '2023122816561879', 'user_name': '张三', 'profile_picture': None, 'signature': None, 'gender': None, 'phone': None, 'date_of_birth': None, 'address': None}]
(Background on this error at: https://sqlalche.me/e/20/e3q8)
Traceback (most recent call last):

  File "D:\Anaconda\envs\api.project.com\lib\site-packages\pymysql\connections.py", line 736, in _read_bytes
    data = self._rfile.read(num_bytes)
           │    │           └ 4
           │    └ None
           └ <pymysql.connections.Connection object at 0x0000027975D67C70>

  File "D:\Anaconda\envs\api.project.com\lib\socket.py", line 669, in readinto
    return self._sock.recv_into(b)
           │    │               └ <memory at 0x0000027975D4DB80>
           │    └ None
           └ <socket.SocketIO object at 0x0000027975D67850>

TimeoutError: [WinError 10060] 由于连接方在一段时间后没有正确答复或连接的主机没有反应，连接尝试失败。


During handling of the above exception, another exception occurred:


Traceback (most recent call last):

  File "D:\Anaconda\envs\api.project.com\lib\site-packages\sqlalchemy\engine\base.py", line 1969, in _exec_single_context
    self.dialect.do_execute(
    │    │       └ <function DefaultDialect.do_execute at 0x00000279753948B0>
    │    └ <sqlalchemy.dialects.mysql.pymysql.MySQLDialect_pymysql object at 0x00000279757C2040>
    └ <sqlalchemy.engine.base.Connection object at 0x0000027975E0AE20>

  File "D:\Anaconda\envs\api.project.com\lib\site-packages\sqlalchemy\engine\default.py", line 922, in do_execute
    cursor.execute(statement, parameters)
    │      │       │          └ {'user_id': '2023122816561879', 'user_name': '张三', 'profile_picture': None, 'signature': None, 'gender': None, 'phone': None,...
    │      │       └ 'INSERT INTO user_info (user_id, user_name, profile_picture, signature, gender, phone, date_of_birth, address) VALUES (%(user...
    │      └ <function Cursor.execute at 0x00000279759A2700>
    └ <pymysql.cursors.Cursor object at 0x0000027975E0AFA0>

  File "D:\Anaconda\envs\api.project.com\lib\site-packages\pymysql\cursors.py", line 158, in execute
    result = self._query(query)
             │    │      └ "INSERT INTO user_info (user_id, user_name, profile_picture, signature, gender, phone, date_of_birth, address) VALUES ('20231...
             │    └ <function Cursor._query at 0x00000279759A2B80>
             └ <pymysql.cursors.Cursor object at 0x0000027975E0AFA0>

  File "D:\Anaconda\envs\api.project.com\lib\site-packages\pymysql\cursors.py", line 325, in _query
    conn.query(q)
    │    │     └ "INSERT INTO user_info (user_id, user_name, profile_picture, signature, gender, phone, date_of_birth, address) VALUES ('20231...
    │    └ <function Connection.query at 0x00000279759AEC10>
    └ <pymysql.connections.Connection object at 0x0000027975D67C70>

  File "D:\Anaconda\envs\api.project.com\lib\site-packages\pymysql\connections.py", line 549, in query
    self._affected_rows = self._read_query_result(unbuffered=unbuffered)
    │    │                │    │                             └ False
    │    │                │    └ <function Connection._read_query_result at 0x00000279759AF280>
    │    │                └ <pymysql.connections.Connection object at 0x0000027975D67C70>
    │    └ 1
    └ <pymysql.connections.Connection object at 0x0000027975D67C70>

  File "D:\Anaconda\envs\api.project.com\lib\site-packages\pymysql\connections.py", line 779, in _read_query_result
    result.read()
    │      └ <function MySQLResult.read at 0x00000279759AFA60>
    └ <pymysql.connections.MySQLResult object at 0x0000027975E0AF40>

  File "D:\Anaconda\envs\api.project.com\lib\site-packages\pymysql\connections.py", line 1157, in read
    first_packet = self.connection._read_packet()
                   │    └ None
                   └ <pymysql.connections.MySQLResult object at 0x0000027975E0AF40>

  File "D:\Anaconda\envs\api.project.com\lib\site-packages\pymysql\connections.py", line 696, in _read_packet
    packet_header = self._read_bytes(4)
                    │    └ <function Connection._read_bytes at 0x00000279759AF160>
                    └ <pymysql.connections.Connection object at 0x0000027975D67C70>

  File "D:\Anaconda\envs\api.project.com\lib\site-packages\pymysql\connections.py", line 742, in _read_bytes
    raise err.OperationalError(
          │   └ <class 'pymysql.err.OperationalError'>
          └ <module 'pymysql.err' from 'D:\\Anaconda\\envs\\api.project.com\\lib\\site-packages\\pymysql\\err.py'>

pymysql.err.OperationalError: (2013, 'Lost connection to MySQL server during query ([WinError 10060] 由于连接方在一段时间后没有正确答复或连接的主机没有反应，连接尝试失败。)')


The above exception was the direct cause of the following exception:


Traceback (most recent call last):

  File "D:\Anaconda\envs\api.project.com\lib\threading.py", line 890, in _bootstrap
    self._bootstrap_inner()
    │    └ <function Thread._bootstrap_inner at 0x0000027971B44430>
    └ <Thread(Thread-1, started daemon 19244)>

  File "D:\Anaconda\envs\api.project.com\lib\threading.py", line 932, in _bootstrap_inner
    self.run()
    │    └ <function Thread.run at 0x0000027971B44160>
    └ <Thread(Thread-1, started daemon 19244)>

  File "D:\Anaconda\envs\api.project.com\lib\threading.py", line 870, in run
    self._target(*self._args, **self._kwargs)
    │    │        │    │        │    └ {}
    │    │        │    │        └ <Thread(Thread-1, started daemon 19244)>
    │    │        │    └ ()
    │    │        └ <Thread(Thread-1, started daemon 19244)>
    │    └ <bound method BaseWSGIServer.serve_forever of <werkzeug.serving.BaseWSGIServer object at 0x0000027975D04220>>
    └ <Thread(Thread-1, started daemon 19244)>

  File "D:\Anaconda\envs\api.project.com\lib\site-packages\werkzeug\serving.py", line 806, in serve_forever
    super().serve_forever(poll_interval=poll_interval)
                                        └ 0.5

  File "D:\Anaconda\envs\api.project.com\lib\socketserver.py", line 237, in serve_forever
    self._handle_request_noblock()
    │    └ <function BaseServer._handle_request_noblock at 0x0000027971B46A60>
    └ <werkzeug.serving.BaseWSGIServer object at 0x0000027975D04220>

  File "D:\Anaconda\envs\api.project.com\lib\socketserver.py", line 316, in _handle_request_noblock
    self.process_request(request, client_address)
    │    │               │        └ ('127.0.0.1', 14657)
    │    │               └ <socket.socket fd=956, family=AddressFamily.AF_INET, type=SocketKind.SOCK_STREAM, proto=0, laddr=('127.0.0.1', 5000), raddr=(...
    │    └ <function BaseServer.process_request at 0x0000027971B46C10>
    └ <werkzeug.serving.BaseWSGIServer object at 0x0000027975D04220>

  File "D:\Anaconda\envs\api.project.com\lib\socketserver.py", line 347, in process_request
    self.finish_request(request, client_address)
    │    │              │        └ ('127.0.0.1', 14657)
    │    │              └ <socket.socket fd=956, family=AddressFamily.AF_INET, type=SocketKind.SOCK_STREAM, proto=0, laddr=('127.0.0.1', 5000), raddr=(...
    │    └ <function BaseServer.finish_request at 0x0000027971B46D30>
    └ <werkzeug.serving.BaseWSGIServer object at 0x0000027975D04220>

  File "D:\Anaconda\envs\api.project.com\lib\socketserver.py", line 360, in finish_request
    self.RequestHandlerClass(request, client_address, self)
    │    │                   │        │               └ <werkzeug.serving.BaseWSGIServer object at 0x0000027975D04220>
    │    │                   │        └ ('127.0.0.1', 14657)
    │    │                   └ <socket.socket fd=956, family=AddressFamily.AF_INET, type=SocketKind.SOCK_STREAM, proto=0, laddr=('127.0.0.1', 5000), raddr=(...
    │    └ <class 'werkzeug.serving.WSGIRequestHandler'>
    └ <werkzeug.serving.BaseWSGIServer object at 0x0000027975D04220>

  File "D:\Anaconda\envs\api.project.com\lib\socketserver.py", line 720, in __init__
    self.handle()
    │    └ <function WSGIRequestHandler.handle at 0x00000279738EECA0>
    └ <werkzeug.serving.WSGIRequestHandler object at 0x0000027975D29A00>

  File "D:\Anaconda\envs\api.project.com\lib\site-packages\werkzeug\serving.py", line 390, in handle
    super().handle()

  File "D:\Anaconda\envs\api.project.com\lib\http\server.py", line 426, in handle
    self.handle_one_request()
    │    └ <function BaseHTTPRequestHandler.handle_one_request at 0x00000279736DB1F0>
    └ <werkzeug.serving.WSGIRequestHandler object at 0x0000027975D29A00>

  File "D:\Anaconda\envs\api.project.com\lib\http\server.py", line 414, in handle_one_request
    method()
    └ <bound method WSGIRequestHandler.run_wsgi of <werkzeug.serving.WSGIRequestHandler object at 0x0000027975D29A00>>

  File "D:\Anaconda\envs\api.project.com\lib\site-packages\werkzeug\serving.py", line 362, in run_wsgi
    execute(self.server.app)
    │       │    │      └ <werkzeug.debug.DebuggedApplication object at 0x0000027975CF64C0>
    │       │    └ <werkzeug.serving.BaseWSGIServer object at 0x0000027975D04220>
    │       └ <werkzeug.serving.WSGIRequestHandler object at 0x0000027975D29A00>
    └ <function WSGIRequestHandler.run_wsgi.<locals>.execute at 0x0000027975D49940>

  File "D:\Anaconda\envs\api.project.com\lib\site-packages\werkzeug\serving.py", line 325, in execute
    for data in application_iter:
                └ <generator object DebuggedApplication.debug_application at 0x0000027975D3CB30>

  File "D:\Anaconda\envs\api.project.com\lib\site-packages\werkzeug\debug\__init__.py", line 330, in debug_application
    app_iter = self.app(environ, start_response)
               │    │   │        └ <function WSGIRequestHandler.run_wsgi.<locals>.start_response at 0x0000027975D494C0>
               │    │   └ {'wsgi.version': (1, 0), 'wsgi.url_scheme': 'http', 'wsgi.input': <_io.BufferedReader name=956>, 'wsgi.errors': <_io.TextIOWr...
               │    └ <Flask 'app'>
               └ <werkzeug.debug.DebuggedApplication object at 0x0000027975CF64C0>

  File "D:\Anaconda\envs\api.project.com\lib\site-packages\flask\app.py", line 2213, in __call__
    return self.wsgi_app(environ, start_response)
           │    │        │        └ <function WSGIRequestHandler.run_wsgi.<locals>.start_response at 0x0000027975D494C0>
           │    │        └ {'wsgi.version': (1, 0), 'wsgi.url_scheme': 'http', 'wsgi.input': <_io.BufferedReader name=956>, 'wsgi.errors': <_io.TextIOWr...
           │    └ <function Flask.wsgi_app at 0x00000279741B2E50>
           └ <Flask 'app'>

  File "D:\Anaconda\envs\api.project.com\lib\site-packages\flask\app.py", line 2190, in wsgi_app
    response = self.full_dispatch_request()
               │    └ <function Flask.full_dispatch_request at 0x00000279741B23A0>
               └ <Flask 'app'>

  File "D:\Anaconda\envs\api.project.com\lib\site-packages\flask\app.py", line 1484, in full_dispatch_request
    rv = self.dispatch_request()
         │    └ <function Flask.dispatch_request at 0x00000279741B2310>
         └ <Flask 'app'>

  File "D:\Anaconda\envs\api.project.com\lib\site-packages\flask\app.py", line 1469, in dispatch_request
    return self.ensure_sync(self.view_functions[rule.endpoint])(**view_args)
           │    │           │    │              │    │            └ {}
           │    │           │    │              │    └ 'userInfo.UserInfo'
           │    │           │    │              └ <Rule '/api_1_0/userInfo' (GET, HEAD, OPTIONS, PUT, POST, DELETE) -> userInfo.UserInfo>
           │    │           │    └ {'static': <function Flask.__init__.<locals>.<lambda> at 0x000002797579EF70>, 'apiversion.Apiversion': <function View.as_view...
           │    │           └ <Flask 'app'>
           │    └ <function Flask.ensure_sync at 0x00000279741B25E0>
           └ <Flask 'app'>

  File "D:\Anaconda\envs\api.project.com\lib\site-packages\flask_restful\__init__.py", line 489, in wrapper
    resp = resource(*args, **kwargs)
           │         │       └ {}
           │         └ ()
           └ <function View.as_view.<locals>.view at 0x0000027975AC44C0>

  File "D:\Anaconda\envs\api.project.com\lib\site-packages\flask\views.py", line 109, in view
    return current_app.ensure_sync(self.dispatch_request)(**kwargs)
           │                       │    │                   └ {}
           │                       │    └ <function Resource.dispatch_request at 0x00000279759CDA60>
           │                       └ <api_1_0.userInfoResource.userInfoResource.UserInfoResource object at 0x0000027975E0A790>
           └ <Flask 'app'>

  File "D:\Anaconda\envs\api.project.com\lib\site-packages\flask_restful\__init__.py", line 604, in dispatch_request
    resp = meth(*args, **kwargs)
           │     │       └ {}
           │     └ ()
           └ <bound method UserInfoResource.post of <class 'api_1_0.userInfoResource.userInfoResource.UserInfoResource'>>

  File "D:\Python_RESTfulAPI_Codegen\dist\dist_1703676800155\api.project.com\api_1_0\userInfoResource\userInfoResource.py", line 182, in post
    res = UserInfoController.add(**kwargs)
          │                  │     └ {'user_name': '张三'}
          │                  └ <classmethod object at 0x0000027975AC1A00>
          └ <class 'controller.userInfoController.UserInfoController'>

> File "D:\Python_RESTfulAPI_Codegen\dist\dist_1703676800155\api.project.com\controller\userInfoController.py", line 38, in add
    db.session.commit()
    │  │       └ <function scoped_session.commit at 0x00000279757150D0>
    │  └ <sqlalchemy.orm.scoping.scoped_session object at 0x00000279741D7160>
    └ <SQLAlchemy mysql+pymysql://root:***@8.130.89.73:3306/skill_sharing?charset=utf8>

  File "D:\Anaconda\envs\api.project.com\lib\site-packages\sqlalchemy\orm\scoping.py", line 598, in commit
    return self._proxied.commit()
           │    └ <property object at 0x00000279757104F0>
           └ <sqlalchemy.orm.scoping.scoped_session object at 0x00000279741D7160>

  File "D:\Anaconda\envs\api.project.com\lib\site-packages\sqlalchemy\orm\session.py", line 1969, in commit
    trans.commit(_to_root=True)
    │     └ <function SessionTransaction.commit at 0x0000027975663AF0>
    └ <sqlalchemy.orm.session.SessionTransaction object at 0x0000027975E22A00>

  File "<string>", line 2, in commit

  File "D:\Anaconda\envs\api.project.com\lib\site-packages\sqlalchemy\orm\state_changes.py", line 139, in _go
    ret_value = fn(self, *arg, **kw)
                │  │      │      └ {'_to_root': True}
                │  │      └ ()
                │  └ <sqlalchemy.orm.session.SessionTransaction object at 0x0000027975E22A00>
                └ <function SessionTransaction.commit at 0x0000027975663A60>

  File "D:\Anaconda\envs\api.project.com\lib\site-packages\sqlalchemy\orm\session.py", line 1256, in commit
    self._prepare_impl()
    │    └ <function SessionTransaction._prepare_impl at 0x00000279756639D0>
    └ <sqlalchemy.orm.session.SessionTransaction object at 0x0000027975E22A00>

  File "<string>", line 2, in _prepare_impl

  File "D:\Anaconda\envs\api.project.com\lib\site-packages\sqlalchemy\orm\state_changes.py", line 139, in _go
    ret_value = fn(self, *arg, **kw)
                │  │      │      └ {}
                │  │      └ ()
                │  └ <sqlalchemy.orm.session.SessionTransaction object at 0x0000027975E22A00>
                └ <function SessionTransaction._prepare_impl at 0x00000279756638B0>

  File "D:\Anaconda\envs\api.project.com\lib\site-packages\sqlalchemy\orm\session.py", line 1231, in _prepare_impl
    self.session.flush()
    │    │       └ <function Session.flush at 0x000002797566E670>
    │    └ <sqlalchemy.orm.session.Session object at 0x0000027975E0A6A0>
    └ <sqlalchemy.orm.session.SessionTransaction object at 0x0000027975E22A00>

  File "D:\Anaconda\envs\api.project.com\lib\site-packages\sqlalchemy\orm\session.py", line 4312, in flush
    self._flush(objects)
    │    │      └ None
    │    └ <function Session._flush at 0x000002797566E820>
    └ <sqlalchemy.orm.session.Session object at 0x0000027975E0A6A0>

  File "D:\Anaconda\envs\api.project.com\lib\site-packages\sqlalchemy\orm\session.py", line 4448, in _flush
    transaction.rollback(_capture_exception=True)
    │           └ <function SessionTransaction.rollback at 0x0000027975663D30>
    └ <sqlalchemy.orm.session.SessionTransaction object at 0x0000027975E22BC0>

  File "D:\Anaconda\envs\api.project.com\lib\site-packages\sqlalchemy\util\langhelpers.py", line 146, in __exit__
    raise exc_value.with_traceback(exc_tb)
          │         │              └ <traceback object at 0x0000027975E36400>
          │         └ <method 'with_traceback' of 'BaseException' objects>
          └ OperationalError("(pymysql.err.OperationalError) (2013, 'Lost connection to MySQL server during query ([WinError 10060] 由于连接方...

  File "D:\Anaconda\envs\api.project.com\lib\site-packages\sqlalchemy\orm\session.py", line 4408, in _flush
    flush_context.execute()
    │             └ <function UOWTransaction.execute at 0x00000279756599D0>
    └ <sqlalchemy.orm.unitofwork.UOWTransaction object at 0x0000027975E0AC40>

  File "D:\Anaconda\envs\api.project.com\lib\site-packages\sqlalchemy\orm\unitofwork.py", line 466, in execute
    rec.execute(self)
    │   │       └ <sqlalchemy.orm.unitofwork.UOWTransaction object at 0x0000027975E0AC40>
    │   └ <function SaveUpdateAll.execute at 0x000002797565A310>
    └ SaveUpdateAll(Mapper[UserInfo(user_info)])

  File "D:\Anaconda\envs\api.project.com\lib\site-packages\sqlalchemy\orm\unitofwork.py", line 642, in execute
    util.preloaded.orm_persistence.save_obj(
    │    │         │               └ <function save_obj at 0x000002797562F9D0>
    │    │         └ <module 'sqlalchemy.orm.persistence' from 'D:\\Anaconda\\envs\\api.project.com\\lib\\site-packages\\sqlalchemy\\orm\\persiste...
    │    └ <module 'sqlalchemy.util.preloaded' from 'D:\\Anaconda\\envs\\api.project.com\\lib\\site-packages\\sqlalchemy\\util\\preloade...
    └ <module 'sqlalchemy.util' from 'D:\\Anaconda\\envs\\api.project.com\\lib\\site-packages\\sqlalchemy\\util\\__init__.py'>

  File "D:\Anaconda\envs\api.project.com\lib\site-packages\sqlalchemy\orm\persistence.py", line 93, in save_obj
    _emit_insert_statements(
    └ <function _emit_insert_statements at 0x000002797563A0D0>

  File "D:\Anaconda\envs\api.project.com\lib\site-packages\sqlalchemy\orm\persistence.py", line 1043, in _emit_insert_statements
    result = connection.execute(
             │          └ <function Connection.execute at 0x00000279751881F0>
             └ <sqlalchemy.engine.base.Connection object at 0x0000027975E0AE20>

  File "D:\Anaconda\envs\api.project.com\lib\site-packages\sqlalchemy\engine\base.py", line 1416, in execute
    return meth(
           └ <bound method ClauseElement._execute_on_connection of <sqlalchemy.sql.dml.Insert object at 0x0000027975D9B220>>

  File "D:\Anaconda\envs\api.project.com\lib\site-packages\sqlalchemy\sql\elements.py", line 516, in _execute_on_connection
    return connection._execute_clauseelement(
           │          └ <function Connection._execute_clauseelement at 0x00000279751884C0>
           └ <sqlalchemy.engine.base.Connection object at 0x0000027975E0AE20>

  File "D:\Anaconda\envs\api.project.com\lib\site-packages\sqlalchemy\engine\base.py", line 1639, in _execute_clauseelement
    ret = self._execute_context(
          │    └ <function Connection._execute_context at 0x0000027975188670>
          └ <sqlalchemy.engine.base.Connection object at 0x0000027975E0AE20>

  File "D:\Anaconda\envs\api.project.com\lib\site-packages\sqlalchemy\engine\base.py", line 1848, in _execute_context
    return self._exec_single_context(
           │    └ <function Connection._exec_single_context at 0x0000027975188700>
           └ <sqlalchemy.engine.base.Connection object at 0x0000027975E0AE20>

  File "D:\Anaconda\envs\api.project.com\lib\site-packages\sqlalchemy\engine\base.py", line 1988, in _exec_single_context
    self._handle_dbapi_exception(
    │    └ <function Connection._handle_dbapi_exception at 0x0000027975188940>
    └ <sqlalchemy.engine.base.Connection object at 0x0000027975E0AE20>

  File "D:\Anaconda\envs\api.project.com\lib\site-packages\sqlalchemy\engine\base.py", line 2343, in _handle_dbapi_exception
    raise sqlalchemy_exception.with_traceback(exc_info[2]) from e
          │                    │              │                 └ OperationalError(2013, 'Lost connection to MySQL server during query ([WinError 10060] 由于连接方在一段时间后没有正确答复或连接的主机没有反应，连接尝试失败。)')
          │                    │              └ (<class 'pymysql.err.OperationalError'>, OperationalError(2013, 'Lost connection to MySQL server during query ([WinError 1006...
          │                    └ <method 'with_traceback' of 'BaseException' objects>
          └ OperationalError("(pymysql.err.OperationalError) (2013, 'Lost connection to MySQL server during query ([WinError 10060] 由于连接方...

  File "D:\Anaconda\envs\api.project.com\lib\site-packages\sqlalchemy\engine\base.py", line 1969, in _exec_single_context
    self.dialect.do_execute(
    │    │       └ <function DefaultDialect.do_execute at 0x00000279753948B0>
    │    └ <sqlalchemy.dialects.mysql.pymysql.MySQLDialect_pymysql object at 0x00000279757C2040>
    └ <sqlalchemy.engine.base.Connection object at 0x0000027975E0AE20>

  File "D:\Anaconda\envs\api.project.com\lib\site-packages\sqlalchemy\engine\default.py", line 922, in do_execute
    cursor.execute(statement, parameters)
    │      │       │          └ {'user_id': '2023122816561879', 'user_name': '张三', 'profile_picture': None, 'signature': None, 'gender': None, 'phone': None,...
    │      │       └ 'INSERT INTO user_info (user_id, user_name, profile_picture, signature, gender, phone, date_of_birth, address) VALUES (%(user...
    │      └ <function Cursor.execute at 0x00000279759A2700>
    └ <pymysql.cursors.Cursor object at 0x0000027975E0AFA0>

  File "D:\Anaconda\envs\api.project.com\lib\site-packages\pymysql\cursors.py", line 158, in execute
    result = self._query(query)
             │    │      └ "INSERT INTO user_info (user_id, user_name, profile_picture, signature, gender, phone, date_of_birth, address) VALUES ('20231...
             │    └ <function Cursor._query at 0x00000279759A2B80>
             └ <pymysql.cursors.Cursor object at 0x0000027975E0AFA0>

  File "D:\Anaconda\envs\api.project.com\lib\site-packages\pymysql\cursors.py", line 325, in _query
    conn.query(q)
    │    │     └ "INSERT INTO user_info (user_id, user_name, profile_picture, signature, gender, phone, date_of_birth, address) VALUES ('20231...
    │    └ <function Connection.query at 0x00000279759AEC10>
    └ <pymysql.connections.Connection object at 0x0000027975D67C70>

  File "D:\Anaconda\envs\api.project.com\lib\site-packages\pymysql\connections.py", line 549, in query
    self._affected_rows = self._read_query_result(unbuffered=unbuffered)
    │    │                │    │                             └ False
    │    │                │    └ <function Connection._read_query_result at 0x00000279759AF280>
    │    │                └ <pymysql.connections.Connection object at 0x0000027975D67C70>
    │    └ 1
    └ <pymysql.connections.Connection object at 0x0000027975D67C70>

  File "D:\Anaconda\envs\api.project.com\lib\site-packages\pymysql\connections.py", line 779, in _read_query_result
    result.read()
    │      └ <function MySQLResult.read at 0x00000279759AFA60>
    └ <pymysql.connections.MySQLResult object at 0x0000027975E0AF40>

  File "D:\Anaconda\envs\api.project.com\lib\site-packages\pymysql\connections.py", line 1157, in read
    first_packet = self.connection._read_packet()
                   │    └ None
                   └ <pymysql.connections.MySQLResult object at 0x0000027975E0AF40>

  File "D:\Anaconda\envs\api.project.com\lib\site-packages\pymysql\connections.py", line 696, in _read_packet
    packet_header = self._read_bytes(4)
                    │    └ <function Connection._read_bytes at 0x00000279759AF160>
                    └ <pymysql.connections.Connection object at 0x0000027975D67C70>

  File "D:\Anaconda\envs\api.project.com\lib\site-packages\pymysql\connections.py", line 742, in _read_bytes
    raise err.OperationalError(
          │   └ <class 'pymysql.err.OperationalError'>
          └ <module 'pymysql.err' from 'D:\\Anaconda\\envs\\api.project.com\\lib\\site-packages\\pymysql\\err.py'>

sqlalchemy.exc.OperationalError: (pymysql.err.OperationalError) (2013, 'Lost connection to MySQL server during query ([WinError 10060] 由于连接方在一段时间后没有正确答复或连接的主机没有反应，连接尝试失败。)')
[SQL: INSERT INTO user_info (user_id, user_name, profile_picture, signature, gender, phone, date_of_birth, address) VALUES (%(user_id)s, %(user_name)s, %(profile_picture)s, %(signature)s, %(gender)s, %(phone)s, %(date_of_birth)s, %(address)s)]
[parameters: {'user_id': '2023122816561879', 'user_name': '张三', 'profile_picture': None, 'signature': None, 'gender': None, 'phone': None, 'date_of_birth': None, 'address': None}]
(Background on this error at: https://sqlalche.me/e/20/e3q8)
2023-12-29 10:11:14.673 | ERROR    | utils.loggings:exception:40 - name 'GenerateID' is not defined
Traceback (most recent call last):

  File "D:\Anaconda\envs\api.project.com\lib\threading.py", line 890, in _bootstrap
    self._bootstrap_inner()
    │    └ <function Thread._bootstrap_inner at 0x00000299C3E35430>
    └ <Thread(Thread-1, started daemon 12456)>

  File "D:\Anaconda\envs\api.project.com\lib\threading.py", line 932, in _bootstrap_inner
    self.run()
    │    └ <function Thread.run at 0x00000299C3E35160>
    └ <Thread(Thread-1, started daemon 12456)>

  File "D:\Anaconda\envs\api.project.com\lib\threading.py", line 870, in run
    self._target(*self._args, **self._kwargs)
    │    │        │    │        │    └ {}
    │    │        │    │        └ <Thread(Thread-1, started daemon 12456)>
    │    │        │    └ ()
    │    │        └ <Thread(Thread-1, started daemon 12456)>
    │    └ <bound method BaseWSGIServer.serve_forever of <werkzeug.serving.BaseWSGIServer object at 0x00000299C7DEF1C0>>
    └ <Thread(Thread-1, started daemon 12456)>

  File "D:\Anaconda\envs\api.project.com\lib\site-packages\werkzeug\serving.py", line 806, in serve_forever
    super().serve_forever(poll_interval=poll_interval)
                                        └ 0.5

  File "D:\Anaconda\envs\api.project.com\lib\socketserver.py", line 237, in serve_forever
    self._handle_request_noblock()
    │    └ <function BaseServer._handle_request_noblock at 0x00000299C3E36A60>
    └ <werkzeug.serving.BaseWSGIServer object at 0x00000299C7DEF1C0>

  File "D:\Anaconda\envs\api.project.com\lib\socketserver.py", line 316, in _handle_request_noblock
    self.process_request(request, client_address)
    │    │               │        └ ('127.0.0.1', 16543)
    │    │               └ <socket.socket fd=848, family=AddressFamily.AF_INET, type=SocketKind.SOCK_STREAM, proto=0, laddr=('127.0.0.1', 5000), raddr=(...
    │    └ <function BaseServer.process_request at 0x00000299C3E36C10>
    └ <werkzeug.serving.BaseWSGIServer object at 0x00000299C7DEF1C0>

  File "D:\Anaconda\envs\api.project.com\lib\socketserver.py", line 347, in process_request
    self.finish_request(request, client_address)
    │    │              │        └ ('127.0.0.1', 16543)
    │    │              └ <socket.socket fd=848, family=AddressFamily.AF_INET, type=SocketKind.SOCK_STREAM, proto=0, laddr=('127.0.0.1', 5000), raddr=(...
    │    └ <function BaseServer.finish_request at 0x00000299C3E36D30>
    └ <werkzeug.serving.BaseWSGIServer object at 0x00000299C7DEF1C0>

  File "D:\Anaconda\envs\api.project.com\lib\socketserver.py", line 360, in finish_request
    self.RequestHandlerClass(request, client_address, self)
    │    │                   │        │               └ <werkzeug.serving.BaseWSGIServer object at 0x00000299C7DEF1C0>
    │    │                   │        └ ('127.0.0.1', 16543)
    │    │                   └ <socket.socket fd=848, family=AddressFamily.AF_INET, type=SocketKind.SOCK_STREAM, proto=0, laddr=('127.0.0.1', 5000), raddr=(...
    │    └ <class 'werkzeug.serving.WSGIRequestHandler'>
    └ <werkzeug.serving.BaseWSGIServer object at 0x00000299C7DEF1C0>

  File "D:\Anaconda\envs\api.project.com\lib\socketserver.py", line 720, in __init__
    self.handle()
    │    └ <function WSGIRequestHandler.handle at 0x00000299C5B93CA0>
    └ <werkzeug.serving.WSGIRequestHandler object at 0x00000299C7E1FC10>

  File "D:\Anaconda\envs\api.project.com\lib\site-packages\werkzeug\serving.py", line 390, in handle
    super().handle()

  File "D:\Anaconda\envs\api.project.com\lib\http\server.py", line 426, in handle
    self.handle_one_request()
    │    └ <function BaseHTTPRequestHandler.handle_one_request at 0x00000299C59CB1F0>
    └ <werkzeug.serving.WSGIRequestHandler object at 0x00000299C7E1FC10>

  File "D:\Anaconda\envs\api.project.com\lib\http\server.py", line 414, in handle_one_request
    method()
    └ <bound method WSGIRequestHandler.run_wsgi of <werkzeug.serving.WSGIRequestHandler object at 0x00000299C7E1FC10>>

  File "D:\Anaconda\envs\api.project.com\lib\site-packages\werkzeug\serving.py", line 362, in run_wsgi
    execute(self.server.app)
    │       │    │      └ <werkzeug.debug.DebuggedApplication object at 0x00000299C7DE1850>
    │       │    └ <werkzeug.serving.BaseWSGIServer object at 0x00000299C7DEF1C0>
    │       └ <werkzeug.serving.WSGIRequestHandler object at 0x00000299C7E1FC10>
    └ <function WSGIRequestHandler.run_wsgi.<locals>.execute at 0x00000299C7E39EE0>

  File "D:\Anaconda\envs\api.project.com\lib\site-packages\werkzeug\serving.py", line 325, in execute
    for data in application_iter:
                └ <generator object DebuggedApplication.debug_application at 0x00000299C7E12D60>

  File "D:\Anaconda\envs\api.project.com\lib\site-packages\werkzeug\debug\__init__.py", line 330, in debug_application
    app_iter = self.app(environ, start_response)
               │    │   │        └ <function WSGIRequestHandler.run_wsgi.<locals>.start_response at 0x00000299C7E39E50>
               │    │   └ {'wsgi.version': (1, 0), 'wsgi.url_scheme': 'http', 'wsgi.input': <_io.BufferedReader name=848>, 'wsgi.errors': <_io.TextIOWr...
               │    └ <Flask 'app'>
               └ <werkzeug.debug.DebuggedApplication object at 0x00000299C7DE1850>

  File "D:\Anaconda\envs\api.project.com\lib\site-packages\flask\app.py", line 2213, in __call__
    return self.wsgi_app(environ, start_response)
           │    │        │        └ <function WSGIRequestHandler.run_wsgi.<locals>.start_response at 0x00000299C7E39E50>
           │    │        └ {'wsgi.version': (1, 0), 'wsgi.url_scheme': 'http', 'wsgi.input': <_io.BufferedReader name=848>, 'wsgi.errors': <_io.TextIOWr...
           │    └ <function Flask.wsgi_app at 0x00000299C64A2E50>
           └ <Flask 'app'>

  File "D:\Anaconda\envs\api.project.com\lib\site-packages\flask\app.py", line 2190, in wsgi_app
    response = self.full_dispatch_request()
               │    └ <function Flask.full_dispatch_request at 0x00000299C64A23A0>
               └ <Flask 'app'>

  File "D:\Anaconda\envs\api.project.com\lib\site-packages\flask\app.py", line 1484, in full_dispatch_request
    rv = self.dispatch_request()
         │    └ <function Flask.dispatch_request at 0x00000299C64A2310>
         └ <Flask 'app'>

  File "D:\Anaconda\envs\api.project.com\lib\site-packages\flask\app.py", line 1469, in dispatch_request
    return self.ensure_sync(self.view_functions[rule.endpoint])(**view_args)
           │    │           │    │              │    │            └ {}
           │    │           │    │              │    └ 'userInfo.UserInfo'
           │    │           │    │              └ <Rule '/api_1_0/userInfo' (OPTIONS, PUT, DELETE, HEAD, GET, POST) -> userInfo.UserInfo>
           │    │           │    └ {'static': <function Flask.__init__.<locals>.<lambda> at 0x00000299C7A8EF70>, 'apiversion.Apiversion': <function View.as_view...
           │    │           └ <Flask 'app'>
           │    └ <function Flask.ensure_sync at 0x00000299C64A25E0>
           └ <Flask 'app'>

  File "D:\Anaconda\envs\api.project.com\lib\site-packages\flask_restful\__init__.py", line 489, in wrapper
    resp = resource(*args, **kwargs)
           │         │       └ {}
           │         └ ()
           └ <function View.as_view.<locals>.view at 0x00000299C7DB44C0>

  File "D:\Anaconda\envs\api.project.com\lib\site-packages\flask\views.py", line 109, in view
    return current_app.ensure_sync(self.dispatch_request)(**kwargs)
           │                       │    │                   └ {}
           │                       │    └ <function Resource.dispatch_request at 0x00000299C7CBDA60>
           │                       └ <api_1_0.userInfoResource.userInfoResource.UserInfoResource object at 0x00000299C7E44340>
           └ <Flask 'app'>

  File "D:\Anaconda\envs\api.project.com\lib\site-packages\flask_restful\__init__.py", line 604, in dispatch_request
    resp = meth(*args, **kwargs)
           │     │       └ {}
           │     └ ()
           └ <bound method UserInfoResource.post of <class 'api_1_0.userInfoResource.userInfoResource.UserInfoResource'>>

  File "D:\Python_RESTfulAPI_Codegen\dist\dist_1703676800155\api.project.com\api_1_0\userInfoResource\userInfoResource.py", line 127, in post
    res = UserInfoController.create_or_update_user_from_wechat(phone_number)
          │                  │                                 └ '18260595626'
          │                  └ <classmethod object at 0x00000299C7DB19D0>
          └ <class 'controller.userInfoController.UserInfoController'>

> File "D:\Python_RESTfulAPI_Codegen\dist\dist_1703676800155\api.project.com\controller\userInfoController.py", line 60, in create_or_update_user_from_wechat
    user_id = GenerateID.create_random_id()

NameError: name 'GenerateID' is not defined
2023-12-29 10:11:50.241 | ERROR    | utils.loggings:exception:40 - (pymysql.err.IntegrityError) (1048, "Column 'user_name' cannot be null")
[SQL: INSERT INTO user_info (user_id, user_name, profile_picture, signature, gender, phone, date_of_birth, address) VALUES (%(user_id)s, %(user_name)s, %(profile_picture)s, %(signature)s, %(gender)s, %(phone)s, %(date_of_birth)s, %(address)s)]
[parameters: {'user_id': '2023122910115891', 'user_name': None, 'profile_picture': None, 'signature': None, 'gender': None, 'phone': '18260595626', 'date_of_birth': None, 'address': None}]
(Background on this error at: https://sqlalche.me/e/20/gkpj)
Traceback (most recent call last):

  File "D:\Anaconda\envs\api.project.com\lib\site-packages\sqlalchemy\engine\base.py", line 1969, in _exec_single_context
    self.dialect.do_execute(
    │    │       └ <function DefaultDialect.do_execute at 0x00000245704448B0>
    │    └ <sqlalchemy.dialects.mysql.pymysql.MySQLDialect_pymysql object at 0x0000024570872040>
    └ <sqlalchemy.engine.base.Connection object at 0x0000024570BD3B20>

  File "D:\Anaconda\envs\api.project.com\lib\site-packages\sqlalchemy\engine\default.py", line 922, in do_execute
    cursor.execute(statement, parameters)
    │      │       │          └ {'user_id': '2023122910115891', 'user_name': None, 'profile_picture': None, 'signature': None, 'gender': None, 'phone': '1826...
    │      │       └ 'INSERT INTO user_info (user_id, user_name, profile_picture, signature, gender, phone, date_of_birth, address) VALUES (%(user...
    │      └ <function Cursor.execute at 0x0000024570A52700>
    └ <pymysql.cursors.Cursor object at 0x0000024570C7BB50>

  File "D:\Anaconda\envs\api.project.com\lib\site-packages\pymysql\cursors.py", line 158, in execute
    result = self._query(query)
             │    │      └ "INSERT INTO user_info (user_id, user_name, profile_picture, signature, gender, phone, date_of_birth, address) VALUES ('20231...
             │    └ <function Cursor._query at 0x0000024570A52B80>
             └ <pymysql.cursors.Cursor object at 0x0000024570C7BB50>

  File "D:\Anaconda\envs\api.project.com\lib\site-packages\pymysql\cursors.py", line 325, in _query
    conn.query(q)
    │    │     └ "INSERT INTO user_info (user_id, user_name, profile_picture, signature, gender, phone, date_of_birth, address) VALUES ('20231...
    │    └ <function Connection.query at 0x0000024570A5EC10>
    └ <pymysql.connections.Connection object at 0x0000024570BBDDF0>

  File "D:\Anaconda\envs\api.project.com\lib\site-packages\pymysql\connections.py", line 549, in query
    self._affected_rows = self._read_query_result(unbuffered=unbuffered)
    │    │                │    │                             └ False
    │    │                │    └ <function Connection._read_query_result at 0x0000024570A5F280>
    │    │                └ <pymysql.connections.Connection object at 0x0000024570BBDDF0>
    │    └ 0
    └ <pymysql.connections.Connection object at 0x0000024570BBDDF0>

  File "D:\Anaconda\envs\api.project.com\lib\site-packages\pymysql\connections.py", line 779, in _read_query_result
    result.read()
    │      └ <function MySQLResult.read at 0x0000024570A5FA60>
    └ <pymysql.connections.MySQLResult object at 0x0000024570C593D0>

  File "D:\Anaconda\envs\api.project.com\lib\site-packages\pymysql\connections.py", line 1157, in read
    first_packet = self.connection._read_packet()
                   │    └ None
                   └ <pymysql.connections.MySQLResult object at 0x0000024570C593D0>

  File "D:\Anaconda\envs\api.project.com\lib\site-packages\pymysql\connections.py", line 729, in _read_packet
    packet.raise_for_error()
    │      └ <function MysqlPacket.raise_for_error at 0x0000024570A5C820>
    └ <pymysql.protocol.MysqlPacket object at 0x0000024570C59FD0>

  File "D:\Anaconda\envs\api.project.com\lib\site-packages\pymysql\protocol.py", line 221, in raise_for_error
    err.raise_mysql_exception(self._data)
    │   │                     │    └ <member '_data' of 'MysqlPacket' objects>
    │   │                     └ <pymysql.protocol.MysqlPacket object at 0x0000024570C59FD0>
    │   └ <function raise_mysql_exception at 0x00000245708BACA0>
    └ <module 'pymysql.err' from 'D:\\Anaconda\\envs\\api.project.com\\lib\\site-packages\\pymysql\\err.py'>

  File "D:\Anaconda\envs\api.project.com\lib\site-packages\pymysql\err.py", line 143, in raise_mysql_exception
    raise errorclass(errno, errval)
          │          │      └ "Column 'user_name' cannot be null"
          │          └ 1048
          └ <class 'pymysql.err.IntegrityError'>

pymysql.err.IntegrityError: (1048, "Column 'user_name' cannot be null")


The above exception was the direct cause of the following exception:


Traceback (most recent call last):

  File "D:\Anaconda\envs\api.project.com\lib\threading.py", line 890, in _bootstrap
    self._bootstrap_inner()
    │    └ <function Thread._bootstrap_inner at 0x000002456CBF5430>
    └ <Thread(Thread-1, started daemon 24708)>

  File "D:\Anaconda\envs\api.project.com\lib\threading.py", line 932, in _bootstrap_inner
    self.run()
    │    └ <function Thread.run at 0x000002456CBF5160>
    └ <Thread(Thread-1, started daemon 24708)>

  File "D:\Anaconda\envs\api.project.com\lib\threading.py", line 870, in run
    self._target(*self._args, **self._kwargs)
    │    │        │    │        │    └ {}
    │    │        │    │        └ <Thread(Thread-1, started daemon 24708)>
    │    │        │    └ ()
    │    │        └ <Thread(Thread-1, started daemon 24708)>
    │    └ <bound method BaseWSGIServer.serve_forever of <werkzeug.serving.BaseWSGIServer object at 0x0000024570BE00A0>>
    └ <Thread(Thread-1, started daemon 24708)>

  File "D:\Anaconda\envs\api.project.com\lib\site-packages\werkzeug\serving.py", line 806, in serve_forever
    super().serve_forever(poll_interval=poll_interval)
                                        └ 0.5

  File "D:\Anaconda\envs\api.project.com\lib\socketserver.py", line 237, in serve_forever
    self._handle_request_noblock()
    │    └ <function BaseServer._handle_request_noblock at 0x000002456CBF6A60>
    └ <werkzeug.serving.BaseWSGIServer object at 0x0000024570BE00A0>

  File "D:\Anaconda\envs\api.project.com\lib\socketserver.py", line 316, in _handle_request_noblock
    self.process_request(request, client_address)
    │    │               │        └ ('127.0.0.1', 26930)
    │    │               └ <socket.socket fd=560, family=AddressFamily.AF_INET, type=SocketKind.SOCK_STREAM, proto=0, laddr=('127.0.0.1', 5000), raddr=(...
    │    └ <function BaseServer.process_request at 0x000002456CBF6C10>
    └ <werkzeug.serving.BaseWSGIServer object at 0x0000024570BE00A0>

  File "D:\Anaconda\envs\api.project.com\lib\socketserver.py", line 347, in process_request
    self.finish_request(request, client_address)
    │    │              │        └ ('127.0.0.1', 26930)
    │    │              └ <socket.socket fd=560, family=AddressFamily.AF_INET, type=SocketKind.SOCK_STREAM, proto=0, laddr=('127.0.0.1', 5000), raddr=(...
    │    └ <function BaseServer.finish_request at 0x000002456CBF6D30>
    └ <werkzeug.serving.BaseWSGIServer object at 0x0000024570BE00A0>

  File "D:\Anaconda\envs\api.project.com\lib\socketserver.py", line 360, in finish_request
    self.RequestHandlerClass(request, client_address, self)
    │    │                   │        │               └ <werkzeug.serving.BaseWSGIServer object at 0x0000024570BE00A0>
    │    │                   │        └ ('127.0.0.1', 26930)
    │    │                   └ <socket.socket fd=560, family=AddressFamily.AF_INET, type=SocketKind.SOCK_STREAM, proto=0, laddr=('127.0.0.1', 5000), raddr=(...
    │    └ <class 'werkzeug.serving.WSGIRequestHandler'>
    └ <werkzeug.serving.BaseWSGIServer object at 0x0000024570BE00A0>

  File "D:\Anaconda\envs\api.project.com\lib\socketserver.py", line 720, in __init__
    self.handle()
    │    └ <function WSGIRequestHandler.handle at 0x000002456E99ECA0>
    └ <werkzeug.serving.WSGIRequestHandler object at 0x0000024570BBD160>

  File "D:\Anaconda\envs\api.project.com\lib\site-packages\werkzeug\serving.py", line 390, in handle
    super().handle()

  File "D:\Anaconda\envs\api.project.com\lib\http\server.py", line 426, in handle
    self.handle_one_request()
    │    └ <function BaseHTTPRequestHandler.handle_one_request at 0x000002456E78B1F0>
    └ <werkzeug.serving.WSGIRequestHandler object at 0x0000024570BBD160>

  File "D:\Anaconda\envs\api.project.com\lib\http\server.py", line 414, in handle_one_request
    method()
    └ <bound method WSGIRequestHandler.run_wsgi of <werkzeug.serving.WSGIRequestHandler object at 0x0000024570BBD160>>

  File "D:\Anaconda\envs\api.project.com\lib\site-packages\werkzeug\serving.py", line 362, in run_wsgi
    execute(self.server.app)
    │       │    │      └ <werkzeug.debug.DebuggedApplication object at 0x0000024570BEC220>
    │       │    └ <werkzeug.serving.BaseWSGIServer object at 0x0000024570BE00A0>
    │       └ <werkzeug.serving.WSGIRequestHandler object at 0x0000024570BBD160>
    └ <function WSGIRequestHandler.run_wsgi.<locals>.execute at 0x0000024570BBF940>

  File "D:\Anaconda\envs\api.project.com\lib\site-packages\werkzeug\serving.py", line 325, in execute
    for data in application_iter:
                └ <generator object DebuggedApplication.debug_application at 0x0000024570B94E40>

  File "D:\Anaconda\envs\api.project.com\lib\site-packages\werkzeug\debug\__init__.py", line 330, in debug_application
    app_iter = self.app(environ, start_response)
               │    │   │        └ <function WSGIRequestHandler.run_wsgi.<locals>.start_response at 0x0000024570BBF1F0>
               │    │   └ {'wsgi.version': (1, 0), 'wsgi.url_scheme': 'http', 'wsgi.input': <_io.BufferedReader name=560>, 'wsgi.errors': <_io.TextIOWr...
               │    └ <Flask 'app'>
               └ <werkzeug.debug.DebuggedApplication object at 0x0000024570BEC220>

  File "D:\Anaconda\envs\api.project.com\lib\site-packages\flask\app.py", line 2213, in __call__
    return self.wsgi_app(environ, start_response)
           │    │        │        └ <function WSGIRequestHandler.run_wsgi.<locals>.start_response at 0x0000024570BBF1F0>
           │    │        └ {'wsgi.version': (1, 0), 'wsgi.url_scheme': 'http', 'wsgi.input': <_io.BufferedReader name=560>, 'wsgi.errors': <_io.TextIOWr...
           │    └ <function Flask.wsgi_app at 0x000002456F262E50>
           └ <Flask 'app'>

  File "D:\Anaconda\envs\api.project.com\lib\site-packages\flask\app.py", line 2190, in wsgi_app
    response = self.full_dispatch_request()
               │    └ <function Flask.full_dispatch_request at 0x000002456F2623A0>
               └ <Flask 'app'>

  File "D:\Anaconda\envs\api.project.com\lib\site-packages\flask\app.py", line 1484, in full_dispatch_request
    rv = self.dispatch_request()
         │    └ <function Flask.dispatch_request at 0x000002456F262310>
         └ <Flask 'app'>

  File "D:\Anaconda\envs\api.project.com\lib\site-packages\flask\app.py", line 1469, in dispatch_request
    return self.ensure_sync(self.view_functions[rule.endpoint])(**view_args)
           │    │           │    │              │    │            └ {}
           │    │           │    │              │    └ 'userInfo.UserInfo'
           │    │           │    │              └ <Rule '/api_1_0/userInfo' (DELETE, OPTIONS, HEAD, PUT, POST, GET) -> userInfo.UserInfo>
           │    │           │    └ {'static': <function Flask.__init__.<locals>.<lambda> at 0x000002457084EF70>, 'apiversion.Apiversion': <function View.as_view...
           │    │           └ <Flask 'app'>
           │    └ <function Flask.ensure_sync at 0x000002456F2625E0>
           └ <Flask 'app'>

  File "D:\Anaconda\envs\api.project.com\lib\site-packages\flask_restful\__init__.py", line 489, in wrapper
    resp = resource(*args, **kwargs)
           │         │       └ {}
           │         └ ()
           └ <function View.as_view.<locals>.view at 0x0000024570B744C0>

  File "D:\Anaconda\envs\api.project.com\lib\site-packages\flask\views.py", line 109, in view
    return current_app.ensure_sync(self.dispatch_request)(**kwargs)
           │                       │    │                   └ {}
           │                       │    └ <function Resource.dispatch_request at 0x0000024570A7DA60>
           │                       └ <api_1_0.userInfoResource.userInfoResource.UserInfoResource object at 0x0000024570BBD6D0>
           └ <Flask 'app'>

  File "D:\Anaconda\envs\api.project.com\lib\site-packages\flask_restful\__init__.py", line 604, in dispatch_request
    resp = meth(*args, **kwargs)
           │     │       └ {}
           │     └ ()
           └ <bound method UserInfoResource.post of <class 'api_1_0.userInfoResource.userInfoResource.UserInfoResource'>>

  File "D:\Python_RESTfulAPI_Codegen\dist\dist_1703676800155\api.project.com\api_1_0\userInfoResource\userInfoResource.py", line 127, in post
    res = UserInfoController.create_or_update_user_from_wechat(phone_number)
          │                  │                                 └ '18260595626'
          │                  └ <classmethod object at 0x0000024570B71820>
          └ <class 'controller.userInfoController.UserInfoController'>

> File "D:\Python_RESTfulAPI_Codegen\dist\dist_1703676800155\api.project.com\controller\userInfoController.py", line 72, in create_or_update_user_from_wechat
    db.session.commit()
    │  │       └ <function scoped_session.commit at 0x00000245707C50D0>
    │  └ <sqlalchemy.orm.scoping.scoped_session object at 0x000002456F287160>
    └ <SQLAlchemy mysql+pymysql://root:***@8.130.89.73:3306/skill_sharing?charset=utf8>

  File "D:\Anaconda\envs\api.project.com\lib\site-packages\sqlalchemy\orm\scoping.py", line 598, in commit
    return self._proxied.commit()
           │    └ <property object at 0x00000245707BF6D0>
           └ <sqlalchemy.orm.scoping.scoped_session object at 0x000002456F287160>

  File "D:\Anaconda\envs\api.project.com\lib\site-packages\sqlalchemy\orm\session.py", line 1969, in commit
    trans.commit(_to_root=True)
    │     └ <function SessionTransaction.commit at 0x0000024570713AF0>
    └ <sqlalchemy.orm.session.SessionTransaction object at 0x0000024570ACB480>

  File "<string>", line 2, in commit

  File "D:\Anaconda\envs\api.project.com\lib\site-packages\sqlalchemy\orm\state_changes.py", line 139, in _go
    ret_value = fn(self, *arg, **kw)
                │  │      │      └ {'_to_root': True}
                │  │      └ ()
                │  └ <sqlalchemy.orm.session.SessionTransaction object at 0x0000024570ACB480>
                └ <function SessionTransaction.commit at 0x0000024570713A60>

  File "D:\Anaconda\envs\api.project.com\lib\site-packages\sqlalchemy\orm\session.py", line 1256, in commit
    self._prepare_impl()
    │    └ <function SessionTransaction._prepare_impl at 0x00000245707139D0>
    └ <sqlalchemy.orm.session.SessionTransaction object at 0x0000024570ACB480>

  File "<string>", line 2, in _prepare_impl

  File "D:\Anaconda\envs\api.project.com\lib\site-packages\sqlalchemy\orm\state_changes.py", line 139, in _go
    ret_value = fn(self, *arg, **kw)
                │  │      │      └ {}
                │  │      └ ()
                │  └ <sqlalchemy.orm.session.SessionTransaction object at 0x0000024570ACB480>
                └ <function SessionTransaction._prepare_impl at 0x00000245707138B0>

  File "D:\Anaconda\envs\api.project.com\lib\site-packages\sqlalchemy\orm\session.py", line 1231, in _prepare_impl
    self.session.flush()
    │    │       └ <function Session.flush at 0x000002457071E670>
    │    └ <sqlalchemy.orm.session.Session object at 0x0000024570BBD760>
    └ <sqlalchemy.orm.session.SessionTransaction object at 0x0000024570ACB480>

  File "D:\Anaconda\envs\api.project.com\lib\site-packages\sqlalchemy\orm\session.py", line 4312, in flush
    self._flush(objects)
    │    │      └ None
    │    └ <function Session._flush at 0x000002457071E820>
    └ <sqlalchemy.orm.session.Session object at 0x0000024570BBD760>

  File "D:\Anaconda\envs\api.project.com\lib\site-packages\sqlalchemy\orm\session.py", line 4448, in _flush
    transaction.rollback(_capture_exception=True)
    │           └ <function SessionTransaction.rollback at 0x0000024570713D30>
    └ <sqlalchemy.orm.session.SessionTransaction object at 0x0000024570C85940>

  File "D:\Anaconda\envs\api.project.com\lib\site-packages\sqlalchemy\util\langhelpers.py", line 146, in __exit__
    raise exc_value.with_traceback(exc_tb)
          │         │              └ <traceback object at 0x0000024570C7DA00>
          │         └ <method 'with_traceback' of 'BaseException' objects>
          └ IntegrityError('(pymysql.err.IntegrityError) (1048, "Column \'user_name\' cannot be null")')

  File "D:\Anaconda\envs\api.project.com\lib\site-packages\sqlalchemy\orm\session.py", line 4408, in _flush
    flush_context.execute()
    │             └ <function UOWTransaction.execute at 0x00000245707099D0>
    └ <sqlalchemy.orm.unitofwork.UOWTransaction object at 0x0000024570C595E0>

  File "D:\Anaconda\envs\api.project.com\lib\site-packages\sqlalchemy\orm\unitofwork.py", line 466, in execute
    rec.execute(self)
    │   │       └ <sqlalchemy.orm.unitofwork.UOWTransaction object at 0x0000024570C595E0>
    │   └ <function SaveUpdateAll.execute at 0x000002457070A310>
    └ SaveUpdateAll(Mapper[UserInfo(user_info)])

  File "D:\Anaconda\envs\api.project.com\lib\site-packages\sqlalchemy\orm\unitofwork.py", line 642, in execute
    util.preloaded.orm_persistence.save_obj(
    │    │         │               └ <function save_obj at 0x00000245706DF9D0>
    │    │         └ <module 'sqlalchemy.orm.persistence' from 'D:\\Anaconda\\envs\\api.project.com\\lib\\site-packages\\sqlalchemy\\orm\\persiste...
    │    └ <module 'sqlalchemy.util.preloaded' from 'D:\\Anaconda\\envs\\api.project.com\\lib\\site-packages\\sqlalchemy\\util\\preloade...
    └ <module 'sqlalchemy.util' from 'D:\\Anaconda\\envs\\api.project.com\\lib\\site-packages\\sqlalchemy\\util\\__init__.py'>

  File "D:\Anaconda\envs\api.project.com\lib\site-packages\sqlalchemy\orm\persistence.py", line 93, in save_obj
    _emit_insert_statements(
    └ <function _emit_insert_statements at 0x00000245706EA0D0>

  File "D:\Anaconda\envs\api.project.com\lib\site-packages\sqlalchemy\orm\persistence.py", line 1043, in _emit_insert_statements
    result = connection.execute(
             │          └ <function Connection.execute at 0x00000245702381F0>
             └ <sqlalchemy.engine.base.Connection object at 0x0000024570BD3B20>

  File "D:\Anaconda\envs\api.project.com\lib\site-packages\sqlalchemy\engine\base.py", line 1416, in execute
    return meth(
           └ <bound method ClauseElement._execute_on_connection of <sqlalchemy.sql.dml.Insert object at 0x0000024570C7B430>>

  File "D:\Anaconda\envs\api.project.com\lib\site-packages\sqlalchemy\sql\elements.py", line 516, in _execute_on_connection
    return connection._execute_clauseelement(
           │          └ <function Connection._execute_clauseelement at 0x00000245702384C0>
           └ <sqlalchemy.engine.base.Connection object at 0x0000024570BD3B20>

  File "D:\Anaconda\envs\api.project.com\lib\site-packages\sqlalchemy\engine\base.py", line 1639, in _execute_clauseelement
    ret = self._execute_context(
          │    └ <function Connection._execute_context at 0x0000024570238670>
          └ <sqlalchemy.engine.base.Connection object at 0x0000024570BD3B20>

  File "D:\Anaconda\envs\api.project.com\lib\site-packages\sqlalchemy\engine\base.py", line 1848, in _execute_context
    return self._exec_single_context(
           │    └ <function Connection._exec_single_context at 0x0000024570238700>
           └ <sqlalchemy.engine.base.Connection object at 0x0000024570BD3B20>

  File "D:\Anaconda\envs\api.project.com\lib\site-packages\sqlalchemy\engine\base.py", line 1988, in _exec_single_context
    self._handle_dbapi_exception(
    │    └ <function Connection._handle_dbapi_exception at 0x0000024570238940>
    └ <sqlalchemy.engine.base.Connection object at 0x0000024570BD3B20>

  File "D:\Anaconda\envs\api.project.com\lib\site-packages\sqlalchemy\engine\base.py", line 2343, in _handle_dbapi_exception
    raise sqlalchemy_exception.with_traceback(exc_info[2]) from e
          │                    │              │                 └ IntegrityError(1048, "Column 'user_name' cannot be null")
          │                    │              └ (<class 'pymysql.err.IntegrityError'>, IntegrityError(1048, "Column 'user_name' cannot be null"), <traceback object at 0x0000...
          │                    └ <method 'with_traceback' of 'BaseException' objects>
          └ IntegrityError('(pymysql.err.IntegrityError) (1048, "Column \'user_name\' cannot be null")')

  File "D:\Anaconda\envs\api.project.com\lib\site-packages\sqlalchemy\engine\base.py", line 1969, in _exec_single_context
    self.dialect.do_execute(
    │    │       └ <function DefaultDialect.do_execute at 0x00000245704448B0>
    │    └ <sqlalchemy.dialects.mysql.pymysql.MySQLDialect_pymysql object at 0x0000024570872040>
    └ <sqlalchemy.engine.base.Connection object at 0x0000024570BD3B20>

  File "D:\Anaconda\envs\api.project.com\lib\site-packages\sqlalchemy\engine\default.py", line 922, in do_execute
    cursor.execute(statement, parameters)
    │      │       │          └ {'user_id': '2023122910115891', 'user_name': None, 'profile_picture': None, 'signature': None, 'gender': None, 'phone': '1826...
    │      │       └ 'INSERT INTO user_info (user_id, user_name, profile_picture, signature, gender, phone, date_of_birth, address) VALUES (%(user...
    │      └ <function Cursor.execute at 0x0000024570A52700>
    └ <pymysql.cursors.Cursor object at 0x0000024570C7BB50>

  File "D:\Anaconda\envs\api.project.com\lib\site-packages\pymysql\cursors.py", line 158, in execute
    result = self._query(query)
             │    │      └ "INSERT INTO user_info (user_id, user_name, profile_picture, signature, gender, phone, date_of_birth, address) VALUES ('20231...
             │    └ <function Cursor._query at 0x0000024570A52B80>
             └ <pymysql.cursors.Cursor object at 0x0000024570C7BB50>

  File "D:\Anaconda\envs\api.project.com\lib\site-packages\pymysql\cursors.py", line 325, in _query
    conn.query(q)
    │    │     └ "INSERT INTO user_info (user_id, user_name, profile_picture, signature, gender, phone, date_of_birth, address) VALUES ('20231...
    │    └ <function Connection.query at 0x0000024570A5EC10>
    └ <pymysql.connections.Connection object at 0x0000024570BBDDF0>

  File "D:\Anaconda\envs\api.project.com\lib\site-packages\pymysql\connections.py", line 549, in query
    self._affected_rows = self._read_query_result(unbuffered=unbuffered)
    │    │                │    │                             └ False
    │    │                │    └ <function Connection._read_query_result at 0x0000024570A5F280>
    │    │                └ <pymysql.connections.Connection object at 0x0000024570BBDDF0>
    │    └ 0
    └ <pymysql.connections.Connection object at 0x0000024570BBDDF0>

  File "D:\Anaconda\envs\api.project.com\lib\site-packages\pymysql\connections.py", line 779, in _read_query_result
    result.read()
    │      └ <function MySQLResult.read at 0x0000024570A5FA60>
    └ <pymysql.connections.MySQLResult object at 0x0000024570C593D0>

  File "D:\Anaconda\envs\api.project.com\lib\site-packages\pymysql\connections.py", line 1157, in read
    first_packet = self.connection._read_packet()
                   │    └ None
                   └ <pymysql.connections.MySQLResult object at 0x0000024570C593D0>

  File "D:\Anaconda\envs\api.project.com\lib\site-packages\pymysql\connections.py", line 729, in _read_packet
    packet.raise_for_error()
    │      └ <function MysqlPacket.raise_for_error at 0x0000024570A5C820>
    └ <pymysql.protocol.MysqlPacket object at 0x0000024570C59FD0>

  File "D:\Anaconda\envs\api.project.com\lib\site-packages\pymysql\protocol.py", line 221, in raise_for_error
    err.raise_mysql_exception(self._data)
    │   │                     │    └ <member '_data' of 'MysqlPacket' objects>
    │   │                     └ <pymysql.protocol.MysqlPacket object at 0x0000024570C59FD0>
    │   └ <function raise_mysql_exception at 0x00000245708BACA0>
    └ <module 'pymysql.err' from 'D:\\Anaconda\\envs\\api.project.com\\lib\\site-packages\\pymysql\\err.py'>

  File "D:\Anaconda\envs\api.project.com\lib\site-packages\pymysql\err.py", line 143, in raise_mysql_exception
    raise errorclass(errno, errval)
          │          │      └ "Column 'user_name' cannot be null"
          │          └ 1048
          └ <class 'pymysql.err.IntegrityError'>

sqlalchemy.exc.IntegrityError: (pymysql.err.IntegrityError) (1048, "Column 'user_name' cannot be null")
[SQL: INSERT INTO user_info (user_id, user_name, profile_picture, signature, gender, phone, date_of_birth, address) VALUES (%(user_id)s, %(user_name)s, %(profile_picture)s, %(signature)s, %(gender)s, %(phone)s, %(date_of_birth)s, %(address)s)]
[parameters: {'user_id': '2023122910115891', 'user_name': None, 'profile_picture': None, 'signature': None, 'gender': None, 'phone': '18260595626', 'date_of_birth': None, 'address': None}]
(Background on this error at: https://sqlalche.me/e/20/gkpj)
2023-12-29 10:18:46.513 | ERROR    | utils.loggings:exception:40 - (pymysql.err.IntegrityError) (1048, "Column 'user_name' cannot be null")
[SQL: INSERT INTO user_info (user_id, user_name, profile_picture, signature, gender, phone, date_of_birth, address) VALUES (%(user_id)s, %(user_name)s, %(profile_picture)s, %(signature)s, %(gender)s, %(phone)s, %(date_of_birth)s, %(address)s)]
[parameters: {'user_id': '2023122910181896', 'user_name': None, 'profile_picture': None, 'signature': None, 'gender': None, 'phone': '18260595626', 'date_of_birth': None, 'address': None}]
(Background on this error at: https://sqlalche.me/e/20/gkpj)
Traceback (most recent call last):

  File "D:\Anaconda\envs\api.project.com\lib\site-packages\sqlalchemy\engine\base.py", line 1969, in _exec_single_context
    self.dialect.do_execute(
    │    │       └ <function DefaultDialect.do_execute at 0x000002CE8E9F48B0>
    │    └ <sqlalchemy.dialects.mysql.pymysql.MySQLDialect_pymysql object at 0x000002CE8EE22040>
    └ <sqlalchemy.engine.base.Connection object at 0x000002CE8F182850>

  File "D:\Anaconda\envs\api.project.com\lib\site-packages\sqlalchemy\engine\default.py", line 922, in do_execute
    cursor.execute(statement, parameters)
    │      │       │          └ {'user_id': '2023122910181896', 'user_name': None, 'profile_picture': None, 'signature': None, 'gender': None, 'phone': '1826...
    │      │       └ 'INSERT INTO user_info (user_id, user_name, profile_picture, signature, gender, phone, date_of_birth, address) VALUES (%(user...
    │      └ <function Cursor.execute at 0x000002CE8F002700>
    └ <pymysql.cursors.Cursor object at 0x000002CE8F229B50>

  File "D:\Anaconda\envs\api.project.com\lib\site-packages\pymysql\cursors.py", line 158, in execute
    result = self._query(query)
             │    │      └ "INSERT INTO user_info (user_id, user_name, profile_picture, signature, gender, phone, date_of_birth, address) VALUES ('20231...
             │    └ <function Cursor._query at 0x000002CE8F002B80>
             └ <pymysql.cursors.Cursor object at 0x000002CE8F229B50>

  File "D:\Anaconda\envs\api.project.com\lib\site-packages\pymysql\cursors.py", line 325, in _query
    conn.query(q)
    │    │     └ "INSERT INTO user_info (user_id, user_name, profile_picture, signature, gender, phone, date_of_birth, address) VALUES ('20231...
    │    └ <function Connection.query at 0x000002CE8F00EC10>
    └ <pymysql.connections.Connection object at 0x000002CE8F16DDF0>

  File "D:\Anaconda\envs\api.project.com\lib\site-packages\pymysql\connections.py", line 549, in query
    self._affected_rows = self._read_query_result(unbuffered=unbuffered)
    │    │                │    │                             └ False
    │    │                │    └ <function Connection._read_query_result at 0x000002CE8F00F280>
    │    │                └ <pymysql.connections.Connection object at 0x000002CE8F16DDF0>
    │    └ 0
    └ <pymysql.connections.Connection object at 0x000002CE8F16DDF0>

  File "D:\Anaconda\envs\api.project.com\lib\site-packages\pymysql\connections.py", line 779, in _read_query_result
    result.read()
    │      └ <function MySQLResult.read at 0x000002CE8F00FA60>
    └ <pymysql.connections.MySQLResult object at 0x000002CE8F1F63D0>

  File "D:\Anaconda\envs\api.project.com\lib\site-packages\pymysql\connections.py", line 1157, in read
    first_packet = self.connection._read_packet()
                   │    └ None
                   └ <pymysql.connections.MySQLResult object at 0x000002CE8F1F63D0>

  File "D:\Anaconda\envs\api.project.com\lib\site-packages\pymysql\connections.py", line 729, in _read_packet
    packet.raise_for_error()
    │      └ <function MysqlPacket.raise_for_error at 0x000002CE8F00C820>
    └ <pymysql.protocol.MysqlPacket object at 0x000002CE8F1F6FD0>

  File "D:\Anaconda\envs\api.project.com\lib\site-packages\pymysql\protocol.py", line 221, in raise_for_error
    err.raise_mysql_exception(self._data)
    │   │                     │    └ <member '_data' of 'MysqlPacket' objects>
    │   │                     └ <pymysql.protocol.MysqlPacket object at 0x000002CE8F1F6FD0>
    │   └ <function raise_mysql_exception at 0x000002CE8EE6ACA0>
    └ <module 'pymysql.err' from 'D:\\Anaconda\\envs\\api.project.com\\lib\\site-packages\\pymysql\\err.py'>

  File "D:\Anaconda\envs\api.project.com\lib\site-packages\pymysql\err.py", line 143, in raise_mysql_exception
    raise errorclass(errno, errval)
          │          │      └ "Column 'user_name' cannot be null"
          │          └ 1048
          └ <class 'pymysql.err.IntegrityError'>

pymysql.err.IntegrityError: (1048, "Column 'user_name' cannot be null")


The above exception was the direct cause of the following exception:


Traceback (most recent call last):

  File "D:\Anaconda\envs\api.project.com\lib\threading.py", line 890, in _bootstrap
    self._bootstrap_inner()
    │    └ <function Thread._bootstrap_inner at 0x000002CE8B1A4430>
    └ <Thread(Thread-1, started daemon 1400)>

  File "D:\Anaconda\envs\api.project.com\lib\threading.py", line 932, in _bootstrap_inner
    self.run()
    │    └ <function Thread.run at 0x000002CE8B1A4160>
    └ <Thread(Thread-1, started daemon 1400)>

  File "D:\Anaconda\envs\api.project.com\lib\threading.py", line 870, in run
    self._target(*self._args, **self._kwargs)
    │    │        │    │        │    └ {}
    │    │        │    │        └ <Thread(Thread-1, started daemon 1400)>
    │    │        │    └ ()
    │    │        └ <Thread(Thread-1, started daemon 1400)>
    │    └ <bound method BaseWSGIServer.serve_forever of <werkzeug.serving.BaseWSGIServer object at 0x000002CE8F1900A0>>
    └ <Thread(Thread-1, started daemon 1400)>

  File "D:\Anaconda\envs\api.project.com\lib\site-packages\werkzeug\serving.py", line 806, in serve_forever
    super().serve_forever(poll_interval=poll_interval)
                                        └ 0.5

  File "D:\Anaconda\envs\api.project.com\lib\socketserver.py", line 237, in serve_forever
    self._handle_request_noblock()
    │    └ <function BaseServer._handle_request_noblock at 0x000002CE8B1A6A60>
    └ <werkzeug.serving.BaseWSGIServer object at 0x000002CE8F1900A0>

  File "D:\Anaconda\envs\api.project.com\lib\socketserver.py", line 316, in _handle_request_noblock
    self.process_request(request, client_address)
    │    │               │        └ ('127.0.0.1', 37761)
    │    │               └ <socket.socket fd=876, family=AddressFamily.AF_INET, type=SocketKind.SOCK_STREAM, proto=0, laddr=('127.0.0.1', 5000), raddr=(...
    │    └ <function BaseServer.process_request at 0x000002CE8B1A6C10>
    └ <werkzeug.serving.BaseWSGIServer object at 0x000002CE8F1900A0>

  File "D:\Anaconda\envs\api.project.com\lib\socketserver.py", line 347, in process_request
    self.finish_request(request, client_address)
    │    │              │        └ ('127.0.0.1', 37761)
    │    │              └ <socket.socket fd=876, family=AddressFamily.AF_INET, type=SocketKind.SOCK_STREAM, proto=0, laddr=('127.0.0.1', 5000), raddr=(...
    │    └ <function BaseServer.finish_request at 0x000002CE8B1A6D30>
    └ <werkzeug.serving.BaseWSGIServer object at 0x000002CE8F1900A0>

  File "D:\Anaconda\envs\api.project.com\lib\socketserver.py", line 360, in finish_request
    self.RequestHandlerClass(request, client_address, self)
    │    │                   │        │               └ <werkzeug.serving.BaseWSGIServer object at 0x000002CE8F1900A0>
    │    │                   │        └ ('127.0.0.1', 37761)
    │    │                   └ <socket.socket fd=876, family=AddressFamily.AF_INET, type=SocketKind.SOCK_STREAM, proto=0, laddr=('127.0.0.1', 5000), raddr=(...
    │    └ <class 'werkzeug.serving.WSGIRequestHandler'>
    └ <werkzeug.serving.BaseWSGIServer object at 0x000002CE8F1900A0>

  File "D:\Anaconda\envs\api.project.com\lib\socketserver.py", line 720, in __init__
    self.handle()
    │    └ <function WSGIRequestHandler.handle at 0x000002CE8CF4ECA0>
    └ <werkzeug.serving.WSGIRequestHandler object at 0x000002CE8F16D160>

  File "D:\Anaconda\envs\api.project.com\lib\site-packages\werkzeug\serving.py", line 390, in handle
    super().handle()

  File "D:\Anaconda\envs\api.project.com\lib\http\server.py", line 426, in handle
    self.handle_one_request()
    │    └ <function BaseHTTPRequestHandler.handle_one_request at 0x000002CE8CD3B1F0>
    └ <werkzeug.serving.WSGIRequestHandler object at 0x000002CE8F16D160>

  File "D:\Anaconda\envs\api.project.com\lib\http\server.py", line 414, in handle_one_request
    method()
    └ <bound method WSGIRequestHandler.run_wsgi of <werkzeug.serving.WSGIRequestHandler object at 0x000002CE8F16D160>>

  File "D:\Anaconda\envs\api.project.com\lib\site-packages\werkzeug\serving.py", line 362, in run_wsgi
    execute(self.server.app)
    │       │    │      └ <werkzeug.debug.DebuggedApplication object at 0x000002CE8F19B250>
    │       │    └ <werkzeug.serving.BaseWSGIServer object at 0x000002CE8F1900A0>
    │       └ <werkzeug.serving.WSGIRequestHandler object at 0x000002CE8F16D160>
    └ <function WSGIRequestHandler.run_wsgi.<locals>.execute at 0x000002CE8F16FCA0>

  File "D:\Anaconda\envs\api.project.com\lib\site-packages\werkzeug\serving.py", line 325, in execute
    for data in application_iter:
                └ <generator object DebuggedApplication.debug_application at 0x000002CE8F144DD0>

  File "D:\Anaconda\envs\api.project.com\lib\site-packages\werkzeug\debug\__init__.py", line 330, in debug_application
    app_iter = self.app(environ, start_response)
               │    │   │        └ <function WSGIRequestHandler.run_wsgi.<locals>.start_response at 0x000002CE8F16FF70>
               │    │   └ {'wsgi.version': (1, 0), 'wsgi.url_scheme': 'http', 'wsgi.input': <_io.BufferedReader name=876>, 'wsgi.errors': <_io.TextIOWr...
               │    └ <Flask 'app'>
               └ <werkzeug.debug.DebuggedApplication object at 0x000002CE8F19B250>

  File "D:\Anaconda\envs\api.project.com\lib\site-packages\flask\app.py", line 2213, in __call__
    return self.wsgi_app(environ, start_response)
           │    │        │        └ <function WSGIRequestHandler.run_wsgi.<locals>.start_response at 0x000002CE8F16FF70>
           │    │        └ {'wsgi.version': (1, 0), 'wsgi.url_scheme': 'http', 'wsgi.input': <_io.BufferedReader name=876>, 'wsgi.errors': <_io.TextIOWr...
           │    └ <function Flask.wsgi_app at 0x000002CE8D812E50>
           └ <Flask 'app'>

  File "D:\Anaconda\envs\api.project.com\lib\site-packages\flask\app.py", line 2190, in wsgi_app
    response = self.full_dispatch_request()
               │    └ <function Flask.full_dispatch_request at 0x000002CE8D8123A0>
               └ <Flask 'app'>

  File "D:\Anaconda\envs\api.project.com\lib\site-packages\flask\app.py", line 1484, in full_dispatch_request
    rv = self.dispatch_request()
         │    └ <function Flask.dispatch_request at 0x000002CE8D812310>
         └ <Flask 'app'>

  File "D:\Anaconda\envs\api.project.com\lib\site-packages\flask\app.py", line 1469, in dispatch_request
    return self.ensure_sync(self.view_functions[rule.endpoint])(**view_args)
           │    │           │    │              │    │            └ {}
           │    │           │    │              │    └ 'userInfo.UserInfo'
           │    │           │    │              └ <Rule '/api_1_0/userInfo' (PUT, GET, HEAD, DELETE, POST, OPTIONS) -> userInfo.UserInfo>
           │    │           │    └ {'static': <function Flask.__init__.<locals>.<lambda> at 0x000002CE8EDFEF70>, 'apiversion.Apiversion': <function View.as_view...
           │    │           └ <Flask 'app'>
           │    └ <function Flask.ensure_sync at 0x000002CE8D8125E0>
           └ <Flask 'app'>

  File "D:\Anaconda\envs\api.project.com\lib\site-packages\flask_restful\__init__.py", line 489, in wrapper
    resp = resource(*args, **kwargs)
           │         │       └ {}
           │         └ ()
           └ <function View.as_view.<locals>.view at 0x000002CE8F1244C0>

  File "D:\Anaconda\envs\api.project.com\lib\site-packages\flask\views.py", line 109, in view
    return current_app.ensure_sync(self.dispatch_request)(**kwargs)
           │                       │    │                   └ {}
           │                       │    └ <function Resource.dispatch_request at 0x000002CE8F02DA60>
           │                       └ <api_1_0.userInfoResource.userInfoResource.UserInfoResource object at 0x000002CE8F16D6D0>
           └ <Flask 'app'>

  File "D:\Anaconda\envs\api.project.com\lib\site-packages\flask_restful\__init__.py", line 604, in dispatch_request
    resp = meth(*args, **kwargs)
           │     │       └ {}
           │     └ ()
           └ <bound method UserInfoResource.post of <class 'api_1_0.userInfoResource.userInfoResource.UserInfoResource'>>

  File "D:\Python_RESTfulAPI_Codegen\dist\dist_1703676800155\api.project.com\api_1_0\userInfoResource\userInfoResource.py", line 127, in post
    res = UserInfoController.create_or_update_user_from_wechat(phone_number)
          │                  │                                 └ '18260595626'
          │                  └ <classmethod object at 0x000002CE8F121820>
          └ <class 'controller.userInfoController.UserInfoController'>

> File "D:\Python_RESTfulAPI_Codegen\dist\dist_1703676800155\api.project.com\controller\userInfoController.py", line 75, in create_or_update_user_from_wechat
    db.session.commit()
    │  │       └ <function scoped_session.commit at 0x000002CE8ED750D0>
    │  └ <sqlalchemy.orm.scoping.scoped_session object at 0x000002CE8D837160>
    └ <SQLAlchemy mysql+pymysql://root:***@8.130.89.73:3306/skill_sharing?charset=utf8>

  File "D:\Anaconda\envs\api.project.com\lib\site-packages\sqlalchemy\orm\scoping.py", line 598, in commit
    return self._proxied.commit()
           │    └ <property object at 0x000002CE8ED6E810>
           └ <sqlalchemy.orm.scoping.scoped_session object at 0x000002CE8D837160>

  File "D:\Anaconda\envs\api.project.com\lib\site-packages\sqlalchemy\orm\session.py", line 1969, in commit
    trans.commit(_to_root=True)
    │     └ <function SessionTransaction.commit at 0x000002CE8ECC3AF0>
    └ <sqlalchemy.orm.session.SessionTransaction object at 0x000002CE8F1B0E00>

  File "<string>", line 2, in commit

  File "D:\Anaconda\envs\api.project.com\lib\site-packages\sqlalchemy\orm\state_changes.py", line 139, in _go
    ret_value = fn(self, *arg, **kw)
                │  │      │      └ {'_to_root': True}
                │  │      └ ()
                │  └ <sqlalchemy.orm.session.SessionTransaction object at 0x000002CE8F1B0E00>
                └ <function SessionTransaction.commit at 0x000002CE8ECC3A60>

  File "D:\Anaconda\envs\api.project.com\lib\site-packages\sqlalchemy\orm\session.py", line 1256, in commit
    self._prepare_impl()
    │    └ <function SessionTransaction._prepare_impl at 0x000002CE8ECC39D0>
    └ <sqlalchemy.orm.session.SessionTransaction object at 0x000002CE8F1B0E00>

  File "<string>", line 2, in _prepare_impl

  File "D:\Anaconda\envs\api.project.com\lib\site-packages\sqlalchemy\orm\state_changes.py", line 139, in _go
    ret_value = fn(self, *arg, **kw)
                │  │      │      └ {}
                │  │      └ ()
                │  └ <sqlalchemy.orm.session.SessionTransaction object at 0x000002CE8F1B0E00>
                └ <function SessionTransaction._prepare_impl at 0x000002CE8ECC38B0>

  File "D:\Anaconda\envs\api.project.com\lib\site-packages\sqlalchemy\orm\session.py", line 1231, in _prepare_impl
    self.session.flush()
    │    │       └ <function Session.flush at 0x000002CE8ECCE670>
    │    └ <sqlalchemy.orm.session.Session object at 0x000002CE8F16D910>
    └ <sqlalchemy.orm.session.SessionTransaction object at 0x000002CE8F1B0E00>

  File "D:\Anaconda\envs\api.project.com\lib\site-packages\sqlalchemy\orm\session.py", line 4312, in flush
    self._flush(objects)
    │    │      └ None
    │    └ <function Session._flush at 0x000002CE8ECCE820>
    └ <sqlalchemy.orm.session.Session object at 0x000002CE8F16D910>

  File "D:\Anaconda\envs\api.project.com\lib\site-packages\sqlalchemy\orm\session.py", line 4448, in _flush
    transaction.rollback(_capture_exception=True)
    │           └ <function SessionTransaction.rollback at 0x000002CE8ECC3D30>
    └ <sqlalchemy.orm.session.SessionTransaction object at 0x000002CE8F236A80>

  File "D:\Anaconda\envs\api.project.com\lib\site-packages\sqlalchemy\util\langhelpers.py", line 146, in __exit__
    raise exc_value.with_traceback(exc_tb)
          │         │              └ <traceback object at 0x000002CE8F22CA40>
          │         └ <method 'with_traceback' of 'BaseException' objects>
          └ IntegrityError('(pymysql.err.IntegrityError) (1048, "Column \'user_name\' cannot be null")')

  File "D:\Anaconda\envs\api.project.com\lib\site-packages\sqlalchemy\orm\session.py", line 4408, in _flush
    flush_context.execute()
    │             └ <function UOWTransaction.execute at 0x000002CE8ECB99D0>
    └ <sqlalchemy.orm.unitofwork.UOWTransaction object at 0x000002CE8F1F65E0>

  File "D:\Anaconda\envs\api.project.com\lib\site-packages\sqlalchemy\orm\unitofwork.py", line 466, in execute
    rec.execute(self)
    │   │       └ <sqlalchemy.orm.unitofwork.UOWTransaction object at 0x000002CE8F1F65E0>
    │   └ <function SaveUpdateAll.execute at 0x000002CE8ECBA310>
    └ SaveUpdateAll(Mapper[UserInfo(user_info)])

  File "D:\Anaconda\envs\api.project.com\lib\site-packages\sqlalchemy\orm\unitofwork.py", line 642, in execute
    util.preloaded.orm_persistence.save_obj(
    │    │         │               └ <function save_obj at 0x000002CE8EC8F9D0>
    │    │         └ <module 'sqlalchemy.orm.persistence' from 'D:\\Anaconda\\envs\\api.project.com\\lib\\site-packages\\sqlalchemy\\orm\\persiste...
    │    └ <module 'sqlalchemy.util.preloaded' from 'D:\\Anaconda\\envs\\api.project.com\\lib\\site-packages\\sqlalchemy\\util\\preloade...
    └ <module 'sqlalchemy.util' from 'D:\\Anaconda\\envs\\api.project.com\\lib\\site-packages\\sqlalchemy\\util\\__init__.py'>

  File "D:\Anaconda\envs\api.project.com\lib\site-packages\sqlalchemy\orm\persistence.py", line 93, in save_obj
    _emit_insert_statements(
    └ <function _emit_insert_statements at 0x000002CE8EC9A0D0>

  File "D:\Anaconda\envs\api.project.com\lib\site-packages\sqlalchemy\orm\persistence.py", line 1043, in _emit_insert_statements
    result = connection.execute(
             │          └ <function Connection.execute at 0x000002CE8E7E81F0>
             └ <sqlalchemy.engine.base.Connection object at 0x000002CE8F182850>

  File "D:\Anaconda\envs\api.project.com\lib\site-packages\sqlalchemy\engine\base.py", line 1416, in execute
    return meth(
           └ <bound method ClauseElement._execute_on_connection of <sqlalchemy.sql.dml.Insert object at 0x000002CE8F229730>>

  File "D:\Anaconda\envs\api.project.com\lib\site-packages\sqlalchemy\sql\elements.py", line 516, in _execute_on_connection
    return connection._execute_clauseelement(
           │          └ <function Connection._execute_clauseelement at 0x000002CE8E7E84C0>
           └ <sqlalchemy.engine.base.Connection object at 0x000002CE8F182850>

  File "D:\Anaconda\envs\api.project.com\lib\site-packages\sqlalchemy\engine\base.py", line 1639, in _execute_clauseelement
    ret = self._execute_context(
          │    └ <function Connection._execute_context at 0x000002CE8E7E8670>
          └ <sqlalchemy.engine.base.Connection object at 0x000002CE8F182850>

  File "D:\Anaconda\envs\api.project.com\lib\site-packages\sqlalchemy\engine\base.py", line 1848, in _execute_context
    return self._exec_single_context(
           │    └ <function Connection._exec_single_context at 0x000002CE8E7E8700>
           └ <sqlalchemy.engine.base.Connection object at 0x000002CE8F182850>

  File "D:\Anaconda\envs\api.project.com\lib\site-packages\sqlalchemy\engine\base.py", line 1988, in _exec_single_context
    self._handle_dbapi_exception(
    │    └ <function Connection._handle_dbapi_exception at 0x000002CE8E7E8940>
    └ <sqlalchemy.engine.base.Connection object at 0x000002CE8F182850>

  File "D:\Anaconda\envs\api.project.com\lib\site-packages\sqlalchemy\engine\base.py", line 2343, in _handle_dbapi_exception
    raise sqlalchemy_exception.with_traceback(exc_info[2]) from e
          │                    │              │                 └ IntegrityError(1048, "Column 'user_name' cannot be null")
          │                    │              └ (<class 'pymysql.err.IntegrityError'>, IntegrityError(1048, "Column 'user_name' cannot be null"), <traceback object at 0x0000...
          │                    └ <method 'with_traceback' of 'BaseException' objects>
          └ IntegrityError('(pymysql.err.IntegrityError) (1048, "Column \'user_name\' cannot be null")')

  File "D:\Anaconda\envs\api.project.com\lib\site-packages\sqlalchemy\engine\base.py", line 1969, in _exec_single_context
    self.dialect.do_execute(
    │    │       └ <function DefaultDialect.do_execute at 0x000002CE8E9F48B0>
    │    └ <sqlalchemy.dialects.mysql.pymysql.MySQLDialect_pymysql object at 0x000002CE8EE22040>
    └ <sqlalchemy.engine.base.Connection object at 0x000002CE8F182850>

  File "D:\Anaconda\envs\api.project.com\lib\site-packages\sqlalchemy\engine\default.py", line 922, in do_execute
    cursor.execute(statement, parameters)
    │      │       │          └ {'user_id': '2023122910181896', 'user_name': None, 'profile_picture': None, 'signature': None, 'gender': None, 'phone': '1826...
    │      │       └ 'INSERT INTO user_info (user_id, user_name, profile_picture, signature, gender, phone, date_of_birth, address) VALUES (%(user...
    │      └ <function Cursor.execute at 0x000002CE8F002700>
    └ <pymysql.cursors.Cursor object at 0x000002CE8F229B50>

  File "D:\Anaconda\envs\api.project.com\lib\site-packages\pymysql\cursors.py", line 158, in execute
    result = self._query(query)
             │    │      └ "INSERT INTO user_info (user_id, user_name, profile_picture, signature, gender, phone, date_of_birth, address) VALUES ('20231...
             │    └ <function Cursor._query at 0x000002CE8F002B80>
             └ <pymysql.cursors.Cursor object at 0x000002CE8F229B50>

  File "D:\Anaconda\envs\api.project.com\lib\site-packages\pymysql\cursors.py", line 325, in _query
    conn.query(q)
    │    │     └ "INSERT INTO user_info (user_id, user_name, profile_picture, signature, gender, phone, date_of_birth, address) VALUES ('20231...
    │    └ <function Connection.query at 0x000002CE8F00EC10>
    └ <pymysql.connections.Connection object at 0x000002CE8F16DDF0>

  File "D:\Anaconda\envs\api.project.com\lib\site-packages\pymysql\connections.py", line 549, in query
    self._affected_rows = self._read_query_result(unbuffered=unbuffered)
    │    │                │    │                             └ False
    │    │                │    └ <function Connection._read_query_result at 0x000002CE8F00F280>
    │    │                └ <pymysql.connections.Connection object at 0x000002CE8F16DDF0>
    │    └ 0
    └ <pymysql.connections.Connection object at 0x000002CE8F16DDF0>

  File "D:\Anaconda\envs\api.project.com\lib\site-packages\pymysql\connections.py", line 779, in _read_query_result
    result.read()
    │      └ <function MySQLResult.read at 0x000002CE8F00FA60>
    └ <pymysql.connections.MySQLResult object at 0x000002CE8F1F63D0>

  File "D:\Anaconda\envs\api.project.com\lib\site-packages\pymysql\connections.py", line 1157, in read
    first_packet = self.connection._read_packet()
                   │    └ None
                   └ <pymysql.connections.MySQLResult object at 0x000002CE8F1F63D0>

  File "D:\Anaconda\envs\api.project.com\lib\site-packages\pymysql\connections.py", line 729, in _read_packet
    packet.raise_for_error()
    │      └ <function MysqlPacket.raise_for_error at 0x000002CE8F00C820>
    └ <pymysql.protocol.MysqlPacket object at 0x000002CE8F1F6FD0>

  File "D:\Anaconda\envs\api.project.com\lib\site-packages\pymysql\protocol.py", line 221, in raise_for_error
    err.raise_mysql_exception(self._data)
    │   │                     │    └ <member '_data' of 'MysqlPacket' objects>
    │   │                     └ <pymysql.protocol.MysqlPacket object at 0x000002CE8F1F6FD0>
    │   └ <function raise_mysql_exception at 0x000002CE8EE6ACA0>
    └ <module 'pymysql.err' from 'D:\\Anaconda\\envs\\api.project.com\\lib\\site-packages\\pymysql\\err.py'>

  File "D:\Anaconda\envs\api.project.com\lib\site-packages\pymysql\err.py", line 143, in raise_mysql_exception
    raise errorclass(errno, errval)
          │          │      └ "Column 'user_name' cannot be null"
          │          └ 1048
          └ <class 'pymysql.err.IntegrityError'>

sqlalchemy.exc.IntegrityError: (pymysql.err.IntegrityError) (1048, "Column 'user_name' cannot be null")
[SQL: INSERT INTO user_info (user_id, user_name, profile_picture, signature, gender, phone, date_of_birth, address) VALUES (%(user_id)s, %(user_name)s, %(profile_picture)s, %(signature)s, %(gender)s, %(phone)s, %(date_of_birth)s, %(address)s)]
[parameters: {'user_id': '2023122910181896', 'user_name': None, 'profile_picture': None, 'signature': None, 'gender': None, 'phone': '18260595626', 'date_of_birth': None, 'address': None}]
(Background on this error at: https://sqlalche.me/e/20/gkpj)
