2023-12-29 10:20:10.575 | ERROR    | utils.loggings:exception:40 - (pymysql.err.IntegrityError) (1048, "Column 'user_name' cannot be null")
[SQL: INSERT INTO user_info (user_id, user_name, profile_picture, signature, gender, phone, date_of_birth, address) VALUES (%(user_id)s, %(user_name)s, %(profile_picture)s, %(signature)s, %(gender)s, %(phone)s, %(date_of_birth)s, %(address)s)]
[parameters: {'user_id': '2023122910209845', 'user_name': None, 'profile_picture': None, 'signature': None, 'gender': None, 'phone': '18260595626', 'date_of_birth': None, 'address': None}]
(Background on this error at: https://sqlalche.me/e/20/gkpj)
Traceback (most recent call last):

  File "D:\Anaconda\envs\api.project.com\lib\site-packages\sqlalchemy\engine\base.py", line 1969, in _exec_single_context
    self.dialect.do_execute(
    │    │       └ <function DefaultDialect.do_execute at 0x000001AB811748B0>
    │    └ <sqlalchemy.dialects.mysql.pymysql.MySQLDialect_pymysql object at 0x000001AB815A2040>
    └ <sqlalchemy.engine.base.Connection object at 0x000001AB81902B20>

  File "D:\Anaconda\envs\api.project.com\lib\site-packages\sqlalchemy\engine\default.py", line 922, in do_execute
    cursor.execute(statement, parameters)
    │      │       │          └ {'user_id': '2023122910209845', 'user_name': None, 'profile_picture': None, 'signature': None, 'gender': None, 'phone': '1826...
    │      │       └ 'INSERT INTO user_info (user_id, user_name, profile_picture, signature, gender, phone, date_of_birth, address) VALUES (%(user...
    │      └ <function Cursor.execute at 0x000001AB81783700>
    └ <pymysql.cursors.Cursor object at 0x000001AB819ABB50>

  File "D:\Anaconda\envs\api.project.com\lib\site-packages\pymysql\cursors.py", line 158, in execute
    result = self._query(query)
             │    │      └ "INSERT INTO user_info (user_id, user_name, profile_picture, signature, gender, phone, date_of_birth, address) VALUES ('20231...
             │    └ <function Cursor._query at 0x000001AB81783B80>
             └ <pymysql.cursors.Cursor object at 0x000001AB819ABB50>

  File "D:\Anaconda\envs\api.project.com\lib\site-packages\pymysql\cursors.py", line 325, in _query
    conn.query(q)
    │    │     └ "INSERT INTO user_info (user_id, user_name, profile_picture, signature, gender, phone, date_of_birth, address) VALUES ('20231...
    │    └ <function Connection.query at 0x000001AB8178EC10>
    └ <pymysql.connections.Connection object at 0x000001AB818EDDF0>

  File "D:\Anaconda\envs\api.project.com\lib\site-packages\pymysql\connections.py", line 549, in query
    self._affected_rows = self._read_query_result(unbuffered=unbuffered)
    │    │                │    │                             └ False
    │    │                │    └ <function Connection._read_query_result at 0x000001AB8178F280>
    │    │                └ <pymysql.connections.Connection object at 0x000001AB818EDDF0>
    │    └ 0
    └ <pymysql.connections.Connection object at 0x000001AB818EDDF0>

  File "D:\Anaconda\envs\api.project.com\lib\site-packages\pymysql\connections.py", line 779, in _read_query_result
    result.read()
    │      └ <function MySQLResult.read at 0x000001AB8178FA60>
    └ <pymysql.connections.MySQLResult object at 0x000001AB819653D0>

  File "D:\Anaconda\envs\api.project.com\lib\site-packages\pymysql\connections.py", line 1157, in read
    first_packet = self.connection._read_packet()
                   │    └ None
                   └ <pymysql.connections.MySQLResult object at 0x000001AB819653D0>

  File "D:\Anaconda\envs\api.project.com\lib\site-packages\pymysql\connections.py", line 729, in _read_packet
    packet.raise_for_error()
    │      └ <function MysqlPacket.raise_for_error at 0x000001AB8178C820>
    └ <pymysql.protocol.MysqlPacket object at 0x000001AB81965FD0>

  File "D:\Anaconda\envs\api.project.com\lib\site-packages\pymysql\protocol.py", line 221, in raise_for_error
    err.raise_mysql_exception(self._data)
    │   │                     │    └ <member '_data' of 'MysqlPacket' objects>
    │   │                     └ <pymysql.protocol.MysqlPacket object at 0x000001AB81965FD0>
    │   └ <function raise_mysql_exception at 0x000001AB815EACA0>
    └ <module 'pymysql.err' from 'D:\\Anaconda\\envs\\api.project.com\\lib\\site-packages\\pymysql\\err.py'>

  File "D:\Anaconda\envs\api.project.com\lib\site-packages\pymysql\err.py", line 143, in raise_mysql_exception
    raise errorclass(errno, errval)
          │          │      └ "Column 'user_name' cannot be null"
          │          └ 1048
          └ <class 'pymysql.err.IntegrityError'>

pymysql.err.IntegrityError: (1048, "Column 'user_name' cannot be null")


The above exception was the direct cause of the following exception:


Traceback (most recent call last):

  File "D:\Anaconda\envs\api.project.com\lib\threading.py", line 890, in _bootstrap
    self._bootstrap_inner()
    │    └ <function Thread._bootstrap_inner at 0x000001ABFD945430>
    └ <Thread(Thread-1, started daemon 15668)>

  File "D:\Anaconda\envs\api.project.com\lib\threading.py", line 932, in _bootstrap_inner
    self.run()
    │    └ <function Thread.run at 0x000001ABFD945160>
    └ <Thread(Thread-1, started daemon 15668)>

  File "D:\Anaconda\envs\api.project.com\lib\threading.py", line 870, in run
    self._target(*self._args, **self._kwargs)
    │    │        │    │        │    └ {}
    │    │        │    │        └ <Thread(Thread-1, started daemon 15668)>
    │    │        │    └ ()
    │    │        └ <Thread(Thread-1, started daemon 15668)>
    │    └ <bound method BaseWSGIServer.serve_forever of <werkzeug.serving.BaseWSGIServer object at 0x000001AB819100A0>>
    └ <Thread(Thread-1, started daemon 15668)>

  File "D:\Anaconda\envs\api.project.com\lib\site-packages\werkzeug\serving.py", line 806, in serve_forever
    super().serve_forever(poll_interval=poll_interval)
                                        └ 0.5

  File "D:\Anaconda\envs\api.project.com\lib\socketserver.py", line 237, in serve_forever
    self._handle_request_noblock()
    │    └ <function BaseServer._handle_request_noblock at 0x000001ABFD946A60>
    └ <werkzeug.serving.BaseWSGIServer object at 0x000001AB819100A0>

  File "D:\Anaconda\envs\api.project.com\lib\socketserver.py", line 316, in _handle_request_noblock
    self.process_request(request, client_address)
    │    │               │        └ ('127.0.0.1', 41564)
    │    │               └ <socket.socket fd=400, family=AddressFamily.AF_INET, type=SocketKind.SOCK_STREAM, proto=0, laddr=('127.0.0.1', 5000), raddr=(...
    │    └ <function BaseServer.process_request at 0x000001ABFD946C10>
    └ <werkzeug.serving.BaseWSGIServer object at 0x000001AB819100A0>

  File "D:\Anaconda\envs\api.project.com\lib\socketserver.py", line 347, in process_request
    self.finish_request(request, client_address)
    │    │              │        └ ('127.0.0.1', 41564)
    │    │              └ <socket.socket fd=400, family=AddressFamily.AF_INET, type=SocketKind.SOCK_STREAM, proto=0, laddr=('127.0.0.1', 5000), raddr=(...
    │    └ <function BaseServer.finish_request at 0x000001ABFD946D30>
    └ <werkzeug.serving.BaseWSGIServer object at 0x000001AB819100A0>

  File "D:\Anaconda\envs\api.project.com\lib\socketserver.py", line 360, in finish_request
    self.RequestHandlerClass(request, client_address, self)
    │    │                   │        │               └ <werkzeug.serving.BaseWSGIServer object at 0x000001AB819100A0>
    │    │                   │        └ ('127.0.0.1', 41564)
    │    │                   └ <socket.socket fd=400, family=AddressFamily.AF_INET, type=SocketKind.SOCK_STREAM, proto=0, laddr=('127.0.0.1', 5000), raddr=(...
    │    └ <class 'werkzeug.serving.WSGIRequestHandler'>
    └ <werkzeug.serving.BaseWSGIServer object at 0x000001AB819100A0>

  File "D:\Anaconda\envs\api.project.com\lib\socketserver.py", line 720, in __init__
    self.handle()
    │    └ <function WSGIRequestHandler.handle at 0x000001ABFF6CECA0>
    └ <werkzeug.serving.WSGIRequestHandler object at 0x000001AB818ED160>

  File "D:\Anaconda\envs\api.project.com\lib\site-packages\werkzeug\serving.py", line 390, in handle
    super().handle()

  File "D:\Anaconda\envs\api.project.com\lib\http\server.py", line 426, in handle
    self.handle_one_request()
    │    └ <function BaseHTTPRequestHandler.handle_one_request at 0x000001ABFF4BB1F0>
    └ <werkzeug.serving.WSGIRequestHandler object at 0x000001AB818ED160>

  File "D:\Anaconda\envs\api.project.com\lib\http\server.py", line 414, in handle_one_request
    method()
    └ <bound method WSGIRequestHandler.run_wsgi of <werkzeug.serving.WSGIRequestHandler object at 0x000001AB818ED160>>

  File "D:\Anaconda\envs\api.project.com\lib\site-packages\werkzeug\serving.py", line 362, in run_wsgi
    execute(self.server.app)
    │       │    │      └ <werkzeug.debug.DebuggedApplication object at 0x000001AB8191C220>
    │       │    └ <werkzeug.serving.BaseWSGIServer object at 0x000001AB819100A0>
    │       └ <werkzeug.serving.WSGIRequestHandler object at 0x000001AB818ED160>
    └ <function WSGIRequestHandler.run_wsgi.<locals>.execute at 0x000001AB818EF1F0>

  File "D:\Anaconda\envs\api.project.com\lib\site-packages\werkzeug\serving.py", line 325, in execute
    for data in application_iter:
                └ <generator object DebuggedApplication.debug_application at 0x000001AB818C4E40>

  File "D:\Anaconda\envs\api.project.com\lib\site-packages\werkzeug\debug\__init__.py", line 330, in debug_application
    app_iter = self.app(environ, start_response)
               │    │   │        └ <function WSGIRequestHandler.run_wsgi.<locals>.start_response at 0x000001AB818EF430>
               │    │   └ {'wsgi.version': (1, 0), 'wsgi.url_scheme': 'http', 'wsgi.input': <_io.BufferedReader name=400>, 'wsgi.errors': <_io.TextIOWr...
               │    └ <Flask 'app'>
               └ <werkzeug.debug.DebuggedApplication object at 0x000001AB8191C220>

  File "D:\Anaconda\envs\api.project.com\lib\site-packages\flask\app.py", line 2213, in __call__
    return self.wsgi_app(environ, start_response)
           │    │        │        └ <function WSGIRequestHandler.run_wsgi.<locals>.start_response at 0x000001AB818EF430>
           │    │        └ {'wsgi.version': (1, 0), 'wsgi.url_scheme': 'http', 'wsgi.input': <_io.BufferedReader name=400>, 'wsgi.errors': <_io.TextIOWr...
           │    └ <function Flask.wsgi_app at 0x000001ABFFF92E50>
           └ <Flask 'app'>

  File "D:\Anaconda\envs\api.project.com\lib\site-packages\flask\app.py", line 2190, in wsgi_app
    response = self.full_dispatch_request()
               │    └ <function Flask.full_dispatch_request at 0x000001ABFFF923A0>
               └ <Flask 'app'>

  File "D:\Anaconda\envs\api.project.com\lib\site-packages\flask\app.py", line 1484, in full_dispatch_request
    rv = self.dispatch_request()
         │    └ <function Flask.dispatch_request at 0x000001ABFFF92310>
         └ <Flask 'app'>

  File "D:\Anaconda\envs\api.project.com\lib\site-packages\flask\app.py", line 1469, in dispatch_request
    return self.ensure_sync(self.view_functions[rule.endpoint])(**view_args)
           │    │           │    │              │    │            └ {}
           │    │           │    │              │    └ 'userInfo.UserInfo'
           │    │           │    │              └ <Rule '/api_1_0/userInfo' (OPTIONS, HEAD, DELETE, GET, POST, PUT) -> userInfo.UserInfo>
           │    │           │    └ {'static': <function Flask.__init__.<locals>.<lambda> at 0x000001AB8157EF70>, 'apiversion.Apiversion': <function View.as_view...
           │    │           └ <Flask 'app'>
           │    └ <function Flask.ensure_sync at 0x000001ABFFF925E0>
           └ <Flask 'app'>

  File "D:\Anaconda\envs\api.project.com\lib\site-packages\flask_restful\__init__.py", line 489, in wrapper
    resp = resource(*args, **kwargs)
           │         │       └ {}
           │         └ ()
           └ <function View.as_view.<locals>.view at 0x000001AB818A44C0>

  File "D:\Anaconda\envs\api.project.com\lib\site-packages\flask\views.py", line 109, in view
    return current_app.ensure_sync(self.dispatch_request)(**kwargs)
           │                       │    │                   └ {}
           │                       │    └ <function Resource.dispatch_request at 0x000001AB817ADA60>
           │                       └ <api_1_0.userInfoResource.userInfoResource.UserInfoResource object at 0x000001AB818ED6D0>
           └ <Flask 'app'>

  File "D:\Anaconda\envs\api.project.com\lib\site-packages\flask_restful\__init__.py", line 604, in dispatch_request
    resp = meth(*args, **kwargs)
           │     │       └ {}
           │     └ ()
           └ <bound method UserInfoResource.post of <class 'api_1_0.userInfoResource.userInfoResource.UserInfoResource'>>

  File "D:\Python_RESTfulAPI_Codegen\dist\dist_1703676800155\api.project.com\api_1_0\userInfoResource\userInfoResource.py", line 127, in post
    res = UserInfoController.create_or_update_user_from_wechat(phone_number)
          │                  │                                 └ '18260595626'
          │                  └ <classmethod object at 0x000001AB818A1820>
          └ <class 'controller.userInfoController.UserInfoController'>

> File "D:\Python_RESTfulAPI_Codegen\dist\dist_1703676800155\api.project.com\controller\userInfoController.py", line 72, in create_or_update_user_from_wechat
    db.session.commit()
    │  │       └ <function scoped_session.commit at 0x000001AB814F50D0>
    │  └ <sqlalchemy.orm.scoping.scoped_session object at 0x000001ABFFFB7160>
    └ <SQLAlchemy mysql+pymysql://root:***@8.130.89.73:3306/skill_sharing?charset=utf8>

  File "D:\Anaconda\envs\api.project.com\lib\site-packages\sqlalchemy\orm\scoping.py", line 598, in commit
    return self._proxied.commit()
           │    └ <property object at 0x000001AB814F05E0>
           └ <sqlalchemy.orm.scoping.scoped_session object at 0x000001ABFFFB7160>

  File "D:\Anaconda\envs\api.project.com\lib\site-packages\sqlalchemy\orm\session.py", line 1969, in commit
    trans.commit(_to_root=True)
    │     └ <function SessionTransaction.commit at 0x000001AB81443AF0>
    └ <sqlalchemy.orm.session.SessionTransaction object at 0x000001AB819958C0>

  File "<string>", line 2, in commit

  File "D:\Anaconda\envs\api.project.com\lib\site-packages\sqlalchemy\orm\state_changes.py", line 139, in _go
    ret_value = fn(self, *arg, **kw)
                │  │      │      └ {'_to_root': True}
                │  │      └ ()
                │  └ <sqlalchemy.orm.session.SessionTransaction object at 0x000001AB819958C0>
                └ <function SessionTransaction.commit at 0x000001AB81443A60>

  File "D:\Anaconda\envs\api.project.com\lib\site-packages\sqlalchemy\orm\session.py", line 1256, in commit
    self._prepare_impl()
    │    └ <function SessionTransaction._prepare_impl at 0x000001AB814439D0>
    └ <sqlalchemy.orm.session.SessionTransaction object at 0x000001AB819958C0>

  File "<string>", line 2, in _prepare_impl

  File "D:\Anaconda\envs\api.project.com\lib\site-packages\sqlalchemy\orm\state_changes.py", line 139, in _go
    ret_value = fn(self, *arg, **kw)
                │  │      │      └ {}
                │  │      └ ()
                │  └ <sqlalchemy.orm.session.SessionTransaction object at 0x000001AB819958C0>
                └ <function SessionTransaction._prepare_impl at 0x000001AB814438B0>

  File "D:\Anaconda\envs\api.project.com\lib\site-packages\sqlalchemy\orm\session.py", line 1231, in _prepare_impl
    self.session.flush()
    │    │       └ <function Session.flush at 0x000001AB8144E670>
    │    └ <sqlalchemy.orm.session.Session object at 0x000001AB818ED7C0>
    └ <sqlalchemy.orm.session.SessionTransaction object at 0x000001AB819958C0>

  File "D:\Anaconda\envs\api.project.com\lib\site-packages\sqlalchemy\orm\session.py", line 4312, in flush
    self._flush(objects)
    │    │      └ None
    │    └ <function Session._flush at 0x000001AB8144E820>
    └ <sqlalchemy.orm.session.Session object at 0x000001AB818ED7C0>

  File "D:\Anaconda\envs\api.project.com\lib\site-packages\sqlalchemy\orm\session.py", line 4448, in _flush
    transaction.rollback(_capture_exception=True)
    │           └ <function SessionTransaction.rollback at 0x000001AB81443D30>
    └ <sqlalchemy.orm.session.SessionTransaction object at 0x000001AB819B4BC0>

  File "D:\Anaconda\envs\api.project.com\lib\site-packages\sqlalchemy\util\langhelpers.py", line 146, in __exit__
    raise exc_value.with_traceback(exc_tb)
          │         │              └ <traceback object at 0x000001AB819ACB00>
          │         └ <method 'with_traceback' of 'BaseException' objects>
          └ IntegrityError('(pymysql.err.IntegrityError) (1048, "Column \'user_name\' cannot be null")')

  File "D:\Anaconda\envs\api.project.com\lib\site-packages\sqlalchemy\orm\session.py", line 4408, in _flush
    flush_context.execute()
    │             └ <function UOWTransaction.execute at 0x000001AB814399D0>
    └ <sqlalchemy.orm.unitofwork.UOWTransaction object at 0x000001AB819655E0>

  File "D:\Anaconda\envs\api.project.com\lib\site-packages\sqlalchemy\orm\unitofwork.py", line 466, in execute
    rec.execute(self)
    │   │       └ <sqlalchemy.orm.unitofwork.UOWTransaction object at 0x000001AB819655E0>
    │   └ <function SaveUpdateAll.execute at 0x000001AB8143A310>
    └ SaveUpdateAll(Mapper[UserInfo(user_info)])

  File "D:\Anaconda\envs\api.project.com\lib\site-packages\sqlalchemy\orm\unitofwork.py", line 642, in execute
    util.preloaded.orm_persistence.save_obj(
    │    │         │               └ <function save_obj at 0x000001AB8140F9D0>
    │    │         └ <module 'sqlalchemy.orm.persistence' from 'D:\\Anaconda\\envs\\api.project.com\\lib\\site-packages\\sqlalchemy\\orm\\persiste...
    │    └ <module 'sqlalchemy.util.preloaded' from 'D:\\Anaconda\\envs\\api.project.com\\lib\\site-packages\\sqlalchemy\\util\\preloade...
    └ <module 'sqlalchemy.util' from 'D:\\Anaconda\\envs\\api.project.com\\lib\\site-packages\\sqlalchemy\\util\\__init__.py'>

  File "D:\Anaconda\envs\api.project.com\lib\site-packages\sqlalchemy\orm\persistence.py", line 93, in save_obj
    _emit_insert_statements(
    └ <function _emit_insert_statements at 0x000001AB8141A0D0>

  File "D:\Anaconda\envs\api.project.com\lib\site-packages\sqlalchemy\orm\persistence.py", line 1043, in _emit_insert_statements
    result = connection.execute(
             │          └ <function Connection.execute at 0x000001AB80F681F0>
             └ <sqlalchemy.engine.base.Connection object at 0x000001AB81902B20>

  File "D:\Anaconda\envs\api.project.com\lib\site-packages\sqlalchemy\engine\base.py", line 1416, in execute
    return meth(
           └ <bound method ClauseElement._execute_on_connection of <sqlalchemy.sql.dml.Insert object at 0x000001AB819AB730>>

  File "D:\Anaconda\envs\api.project.com\lib\site-packages\sqlalchemy\sql\elements.py", line 516, in _execute_on_connection
    return connection._execute_clauseelement(
           │          └ <function Connection._execute_clauseelement at 0x000001AB80F684C0>
           └ <sqlalchemy.engine.base.Connection object at 0x000001AB81902B20>

  File "D:\Anaconda\envs\api.project.com\lib\site-packages\sqlalchemy\engine\base.py", line 1639, in _execute_clauseelement
    ret = self._execute_context(
          │    └ <function Connection._execute_context at 0x000001AB80F68670>
          └ <sqlalchemy.engine.base.Connection object at 0x000001AB81902B20>

  File "D:\Anaconda\envs\api.project.com\lib\site-packages\sqlalchemy\engine\base.py", line 1848, in _execute_context
    return self._exec_single_context(
           │    └ <function Connection._exec_single_context at 0x000001AB80F68700>
           └ <sqlalchemy.engine.base.Connection object at 0x000001AB81902B20>

  File "D:\Anaconda\envs\api.project.com\lib\site-packages\sqlalchemy\engine\base.py", line 1988, in _exec_single_context
    self._handle_dbapi_exception(
    │    └ <function Connection._handle_dbapi_exception at 0x000001AB80F68940>
    └ <sqlalchemy.engine.base.Connection object at 0x000001AB81902B20>

  File "D:\Anaconda\envs\api.project.com\lib\site-packages\sqlalchemy\engine\base.py", line 2343, in _handle_dbapi_exception
    raise sqlalchemy_exception.with_traceback(exc_info[2]) from e
          │                    │              │                 └ IntegrityError(1048, "Column 'user_name' cannot be null")
          │                    │              └ (<class 'pymysql.err.IntegrityError'>, IntegrityError(1048, "Column 'user_name' cannot be null"), <traceback object at 0x0000...
          │                    └ <method 'with_traceback' of 'BaseException' objects>
          └ IntegrityError('(pymysql.err.IntegrityError) (1048, "Column \'user_name\' cannot be null")')

  File "D:\Anaconda\envs\api.project.com\lib\site-packages\sqlalchemy\engine\base.py", line 1969, in _exec_single_context
    self.dialect.do_execute(
    │    │       └ <function DefaultDialect.do_execute at 0x000001AB811748B0>
    │    └ <sqlalchemy.dialects.mysql.pymysql.MySQLDialect_pymysql object at 0x000001AB815A2040>
    └ <sqlalchemy.engine.base.Connection object at 0x000001AB81902B20>

  File "D:\Anaconda\envs\api.project.com\lib\site-packages\sqlalchemy\engine\default.py", line 922, in do_execute
    cursor.execute(statement, parameters)
    │      │       │          └ {'user_id': '2023122910209845', 'user_name': None, 'profile_picture': None, 'signature': None, 'gender': None, 'phone': '1826...
    │      │       └ 'INSERT INTO user_info (user_id, user_name, profile_picture, signature, gender, phone, date_of_birth, address) VALUES (%(user...
    │      └ <function Cursor.execute at 0x000001AB81783700>
    └ <pymysql.cursors.Cursor object at 0x000001AB819ABB50>

  File "D:\Anaconda\envs\api.project.com\lib\site-packages\pymysql\cursors.py", line 158, in execute
    result = self._query(query)
             │    │      └ "INSERT INTO user_info (user_id, user_name, profile_picture, signature, gender, phone, date_of_birth, address) VALUES ('20231...
             │    └ <function Cursor._query at 0x000001AB81783B80>
             └ <pymysql.cursors.Cursor object at 0x000001AB819ABB50>

  File "D:\Anaconda\envs\api.project.com\lib\site-packages\pymysql\cursors.py", line 325, in _query
    conn.query(q)
    │    │     └ "INSERT INTO user_info (user_id, user_name, profile_picture, signature, gender, phone, date_of_birth, address) VALUES ('20231...
    │    └ <function Connection.query at 0x000001AB8178EC10>
    └ <pymysql.connections.Connection object at 0x000001AB818EDDF0>

  File "D:\Anaconda\envs\api.project.com\lib\site-packages\pymysql\connections.py", line 549, in query
    self._affected_rows = self._read_query_result(unbuffered=unbuffered)
    │    │                │    │                             └ False
    │    │                │    └ <function Connection._read_query_result at 0x000001AB8178F280>
    │    │                └ <pymysql.connections.Connection object at 0x000001AB818EDDF0>
    │    └ 0
    └ <pymysql.connections.Connection object at 0x000001AB818EDDF0>

  File "D:\Anaconda\envs\api.project.com\lib\site-packages\pymysql\connections.py", line 779, in _read_query_result
    result.read()
    │      └ <function MySQLResult.read at 0x000001AB8178FA60>
    └ <pymysql.connections.MySQLResult object at 0x000001AB819653D0>

  File "D:\Anaconda\envs\api.project.com\lib\site-packages\pymysql\connections.py", line 1157, in read
    first_packet = self.connection._read_packet()
                   │    └ None
                   └ <pymysql.connections.MySQLResult object at 0x000001AB819653D0>

  File "D:\Anaconda\envs\api.project.com\lib\site-packages\pymysql\connections.py", line 729, in _read_packet
    packet.raise_for_error()
    │      └ <function MysqlPacket.raise_for_error at 0x000001AB8178C820>
    └ <pymysql.protocol.MysqlPacket object at 0x000001AB81965FD0>

  File "D:\Anaconda\envs\api.project.com\lib\site-packages\pymysql\protocol.py", line 221, in raise_for_error
    err.raise_mysql_exception(self._data)
    │   │                     │    └ <member '_data' of 'MysqlPacket' objects>
    │   │                     └ <pymysql.protocol.MysqlPacket object at 0x000001AB81965FD0>
    │   └ <function raise_mysql_exception at 0x000001AB815EACA0>
    └ <module 'pymysql.err' from 'D:\\Anaconda\\envs\\api.project.com\\lib\\site-packages\\pymysql\\err.py'>

  File "D:\Anaconda\envs\api.project.com\lib\site-packages\pymysql\err.py", line 143, in raise_mysql_exception
    raise errorclass(errno, errval)
          │          │      └ "Column 'user_name' cannot be null"
          │          └ 1048
          └ <class 'pymysql.err.IntegrityError'>

sqlalchemy.exc.IntegrityError: (pymysql.err.IntegrityError) (1048, "Column 'user_name' cannot be null")
[SQL: INSERT INTO user_info (user_id, user_name, profile_picture, signature, gender, phone, date_of_birth, address) VALUES (%(user_id)s, %(user_name)s, %(profile_picture)s, %(signature)s, %(gender)s, %(phone)s, %(date_of_birth)s, %(address)s)]
[parameters: {'user_id': '2023122910209845', 'user_name': None, 'profile_picture': None, 'signature': None, 'gender': None, 'phone': '18260595626', 'date_of_birth': None, 'address': None}]
(Background on this error at: https://sqlalche.me/e/20/gkpj)
2023-12-29 10:20:25.600 | ERROR    | utils.loggings:exception:40 - (pymysql.err.IntegrityError) (1048, "Column 'user_name' cannot be null")
[SQL: INSERT INTO user_info (user_id, user_name, profile_picture, signature, gender, phone, date_of_birth, address) VALUES (%(user_id)s, %(user_name)s, %(profile_picture)s, %(signature)s, %(gender)s, %(phone)s, %(date_of_birth)s, %(address)s)]
[parameters: {'user_id': '2023122910208219', 'user_name': None, 'profile_picture': None, 'signature': None, 'gender': None, 'phone': '18260595626', 'date_of_birth': None, 'address': None}]
(Background on this error at: https://sqlalche.me/e/20/gkpj)
Traceback (most recent call last):

  File "D:\Anaconda\envs\api.project.com\lib\site-packages\sqlalchemy\engine\base.py", line 1969, in _exec_single_context
    self.dialect.do_execute(
    │    │       └ <function DefaultDialect.do_execute at 0x0000017CD6EF48B0>
    │    └ <sqlalchemy.dialects.mysql.pymysql.MySQLDialect_pymysql object at 0x0000017CD7322040>
    └ <sqlalchemy.engine.base.Connection object at 0x0000017CD7682850>

  File "D:\Anaconda\envs\api.project.com\lib\site-packages\sqlalchemy\engine\default.py", line 922, in do_execute
    cursor.execute(statement, parameters)
    │      │       │          └ {'user_id': '2023122910208219', 'user_name': None, 'profile_picture': None, 'signature': None, 'gender': None, 'phone': '1826...
    │      │       └ 'INSERT INTO user_info (user_id, user_name, profile_picture, signature, gender, phone, date_of_birth, address) VALUES (%(user...
    │      └ <function Cursor.execute at 0x0000017CD7503700>
    └ <pymysql.cursors.Cursor object at 0x0000017CD772BB50>

  File "D:\Anaconda\envs\api.project.com\lib\site-packages\pymysql\cursors.py", line 158, in execute
    result = self._query(query)
             │    │      └ "INSERT INTO user_info (user_id, user_name, profile_picture, signature, gender, phone, date_of_birth, address) VALUES ('20231...
             │    └ <function Cursor._query at 0x0000017CD7503B80>
             └ <pymysql.cursors.Cursor object at 0x0000017CD772BB50>

  File "D:\Anaconda\envs\api.project.com\lib\site-packages\pymysql\cursors.py", line 325, in _query
    conn.query(q)
    │    │     └ "INSERT INTO user_info (user_id, user_name, profile_picture, signature, gender, phone, date_of_birth, address) VALUES ('20231...
    │    └ <function Connection.query at 0x0000017CD750FC10>
    └ <pymysql.connections.Connection object at 0x0000017CD766DDF0>

  File "D:\Anaconda\envs\api.project.com\lib\site-packages\pymysql\connections.py", line 549, in query
    self._affected_rows = self._read_query_result(unbuffered=unbuffered)
    │    │                │    │                             └ False
    │    │                │    └ <function Connection._read_query_result at 0x0000017CD7510280>
    │    │                └ <pymysql.connections.Connection object at 0x0000017CD766DDF0>
    │    └ 0
    └ <pymysql.connections.Connection object at 0x0000017CD766DDF0>

  File "D:\Anaconda\envs\api.project.com\lib\site-packages\pymysql\connections.py", line 779, in _read_query_result
    result.read()
    │      └ <function MySQLResult.read at 0x0000017CD7510A60>
    └ <pymysql.connections.MySQLResult object at 0x0000017CD76E33D0>

  File "D:\Anaconda\envs\api.project.com\lib\site-packages\pymysql\connections.py", line 1157, in read
    first_packet = self.connection._read_packet()
                   │    └ None
                   └ <pymysql.connections.MySQLResult object at 0x0000017CD76E33D0>

  File "D:\Anaconda\envs\api.project.com\lib\site-packages\pymysql\connections.py", line 729, in _read_packet
    packet.raise_for_error()
    │      └ <function MysqlPacket.raise_for_error at 0x0000017CD750C820>
    └ <pymysql.protocol.MysqlPacket object at 0x0000017CD76E3FD0>

  File "D:\Anaconda\envs\api.project.com\lib\site-packages\pymysql\protocol.py", line 221, in raise_for_error
    err.raise_mysql_exception(self._data)
    │   │                     │    └ <member '_data' of 'MysqlPacket' objects>
    │   │                     └ <pymysql.protocol.MysqlPacket object at 0x0000017CD76E3FD0>
    │   └ <function raise_mysql_exception at 0x0000017CD736ACA0>
    └ <module 'pymysql.err' from 'D:\\Anaconda\\envs\\api.project.com\\lib\\site-packages\\pymysql\\err.py'>

  File "D:\Anaconda\envs\api.project.com\lib\site-packages\pymysql\err.py", line 143, in raise_mysql_exception
    raise errorclass(errno, errval)
          │          │      └ "Column 'user_name' cannot be null"
          │          └ 1048
          └ <class 'pymysql.err.IntegrityError'>

pymysql.err.IntegrityError: (1048, "Column 'user_name' cannot be null")


The above exception was the direct cause of the following exception:


Traceback (most recent call last):

  File "D:\Anaconda\envs\api.project.com\lib\threading.py", line 890, in _bootstrap
    self._bootstrap_inner()
    │    └ <function Thread._bootstrap_inner at 0x0000017CD36B5430>
    └ <Thread(Thread-1, started daemon 23996)>

  File "D:\Anaconda\envs\api.project.com\lib\threading.py", line 932, in _bootstrap_inner
    self.run()
    │    └ <function Thread.run at 0x0000017CD36B5160>
    └ <Thread(Thread-1, started daemon 23996)>

  File "D:\Anaconda\envs\api.project.com\lib\threading.py", line 870, in run
    self._target(*self._args, **self._kwargs)
    │    │        │    │        │    └ {}
    │    │        │    │        └ <Thread(Thread-1, started daemon 23996)>
    │    │        │    └ ()
    │    │        └ <Thread(Thread-1, started daemon 23996)>
    │    └ <bound method BaseWSGIServer.serve_forever of <werkzeug.serving.BaseWSGIServer object at 0x0000017CD76900A0>>
    └ <Thread(Thread-1, started daemon 23996)>

  File "D:\Anaconda\envs\api.project.com\lib\site-packages\werkzeug\serving.py", line 806, in serve_forever
    super().serve_forever(poll_interval=poll_interval)
                                        └ 0.5

  File "D:\Anaconda\envs\api.project.com\lib\socketserver.py", line 237, in serve_forever
    self._handle_request_noblock()
    │    └ <function BaseServer._handle_request_noblock at 0x0000017CD36B6A60>
    └ <werkzeug.serving.BaseWSGIServer object at 0x0000017CD76900A0>

  File "D:\Anaconda\envs\api.project.com\lib\socketserver.py", line 316, in _handle_request_noblock
    self.process_request(request, client_address)
    │    │               │        └ ('127.0.0.1', 55369)
    │    │               └ <socket.socket fd=408, family=AddressFamily.AF_INET, type=SocketKind.SOCK_STREAM, proto=0, laddr=('127.0.0.1', 5000), raddr=(...
    │    └ <function BaseServer.process_request at 0x0000017CD36B6C10>
    └ <werkzeug.serving.BaseWSGIServer object at 0x0000017CD76900A0>

  File "D:\Anaconda\envs\api.project.com\lib\socketserver.py", line 347, in process_request
    self.finish_request(request, client_address)
    │    │              │        └ ('127.0.0.1', 55369)
    │    │              └ <socket.socket fd=408, family=AddressFamily.AF_INET, type=SocketKind.SOCK_STREAM, proto=0, laddr=('127.0.0.1', 5000), raddr=(...
    │    └ <function BaseServer.finish_request at 0x0000017CD36B6D30>
    └ <werkzeug.serving.BaseWSGIServer object at 0x0000017CD76900A0>

  File "D:\Anaconda\envs\api.project.com\lib\socketserver.py", line 360, in finish_request
    self.RequestHandlerClass(request, client_address, self)
    │    │                   │        │               └ <werkzeug.serving.BaseWSGIServer object at 0x0000017CD76900A0>
    │    │                   │        └ ('127.0.0.1', 55369)
    │    │                   └ <socket.socket fd=408, family=AddressFamily.AF_INET, type=SocketKind.SOCK_STREAM, proto=0, laddr=('127.0.0.1', 5000), raddr=(...
    │    └ <class 'werkzeug.serving.WSGIRequestHandler'>
    └ <werkzeug.serving.BaseWSGIServer object at 0x0000017CD76900A0>

  File "D:\Anaconda\envs\api.project.com\lib\socketserver.py", line 720, in __init__
    self.handle()
    │    └ <function WSGIRequestHandler.handle at 0x0000017CD544ECA0>
    └ <werkzeug.serving.WSGIRequestHandler object at 0x0000017CD766D160>

  File "D:\Anaconda\envs\api.project.com\lib\site-packages\werkzeug\serving.py", line 390, in handle
    super().handle()

  File "D:\Anaconda\envs\api.project.com\lib\http\server.py", line 426, in handle
    self.handle_one_request()
    │    └ <function BaseHTTPRequestHandler.handle_one_request at 0x0000017CD523B1F0>
    └ <werkzeug.serving.WSGIRequestHandler object at 0x0000017CD766D160>

  File "D:\Anaconda\envs\api.project.com\lib\http\server.py", line 414, in handle_one_request
    method()
    └ <bound method WSGIRequestHandler.run_wsgi of <werkzeug.serving.WSGIRequestHandler object at 0x0000017CD766D160>>

  File "D:\Anaconda\envs\api.project.com\lib\site-packages\werkzeug\serving.py", line 362, in run_wsgi
    execute(self.server.app)
    │       │    │      └ <werkzeug.debug.DebuggedApplication object at 0x0000017CD769C220>
    │       │    └ <werkzeug.serving.BaseWSGIServer object at 0x0000017CD76900A0>
    │       └ <werkzeug.serving.WSGIRequestHandler object at 0x0000017CD766D160>
    └ <function WSGIRequestHandler.run_wsgi.<locals>.execute at 0x0000017CD766F430>

  File "D:\Anaconda\envs\api.project.com\lib\site-packages\werkzeug\serving.py", line 325, in execute
    for data in application_iter:
                └ <generator object DebuggedApplication.debug_application at 0x0000017CD7644E40>

  File "D:\Anaconda\envs\api.project.com\lib\site-packages\werkzeug\debug\__init__.py", line 330, in debug_application
    app_iter = self.app(environ, start_response)
               │    │   │        └ <function WSGIRequestHandler.run_wsgi.<locals>.start_response at 0x0000017CD766FF70>
               │    │   └ {'wsgi.version': (1, 0), 'wsgi.url_scheme': 'http', 'wsgi.input': <_io.BufferedReader name=408>, 'wsgi.errors': <_io.TextIOWr...
               │    └ <Flask 'app'>
               └ <werkzeug.debug.DebuggedApplication object at 0x0000017CD769C220>

  File "D:\Anaconda\envs\api.project.com\lib\site-packages\flask\app.py", line 2213, in __call__
    return self.wsgi_app(environ, start_response)
           │    │        │        └ <function WSGIRequestHandler.run_wsgi.<locals>.start_response at 0x0000017CD766FF70>
           │    │        └ {'wsgi.version': (1, 0), 'wsgi.url_scheme': 'http', 'wsgi.input': <_io.BufferedReader name=408>, 'wsgi.errors': <_io.TextIOWr...
           │    └ <function Flask.wsgi_app at 0x0000017CD5D12E50>
           └ <Flask 'app'>

  File "D:\Anaconda\envs\api.project.com\lib\site-packages\flask\app.py", line 2190, in wsgi_app
    response = self.full_dispatch_request()
               │    └ <function Flask.full_dispatch_request at 0x0000017CD5D123A0>
               └ <Flask 'app'>

  File "D:\Anaconda\envs\api.project.com\lib\site-packages\flask\app.py", line 1484, in full_dispatch_request
    rv = self.dispatch_request()
         │    └ <function Flask.dispatch_request at 0x0000017CD5D12310>
         └ <Flask 'app'>

  File "D:\Anaconda\envs\api.project.com\lib\site-packages\flask\app.py", line 1469, in dispatch_request
    return self.ensure_sync(self.view_functions[rule.endpoint])(**view_args)
           │    │           │    │              │    │            └ {}
           │    │           │    │              │    └ 'userInfo.UserInfo'
           │    │           │    │              └ <Rule '/api_1_0/userInfo' (OPTIONS, GET, POST, DELETE, PUT, HEAD) -> userInfo.UserInfo>
           │    │           │    └ {'static': <function Flask.__init__.<locals>.<lambda> at 0x0000017CD72FEF70>, 'apiversion.Apiversion': <function View.as_view...
           │    │           └ <Flask 'app'>
           │    └ <function Flask.ensure_sync at 0x0000017CD5D125E0>
           └ <Flask 'app'>

  File "D:\Anaconda\envs\api.project.com\lib\site-packages\flask_restful\__init__.py", line 489, in wrapper
    resp = resource(*args, **kwargs)
           │         │       └ {}
           │         └ ()
           └ <function View.as_view.<locals>.view at 0x0000017CD76244C0>

  File "D:\Anaconda\envs\api.project.com\lib\site-packages\flask\views.py", line 109, in view
    return current_app.ensure_sync(self.dispatch_request)(**kwargs)
           │                       │    │                   └ {}
           │                       │    └ <function Resource.dispatch_request at 0x0000017CD752DA60>
           │                       └ <api_1_0.userInfoResource.userInfoResource.UserInfoResource object at 0x0000017CD766D6D0>
           └ <Flask 'app'>

  File "D:\Anaconda\envs\api.project.com\lib\site-packages\flask_restful\__init__.py", line 604, in dispatch_request
    resp = meth(*args, **kwargs)
           │     │       └ {}
           │     └ ()
           └ <bound method UserInfoResource.post of <class 'api_1_0.userInfoResource.userInfoResource.UserInfoResource'>>

  File "D:\Python_RESTfulAPI_Codegen\dist\dist_1703676800155\api.project.com\api_1_0\userInfoResource\userInfoResource.py", line 127, in post
    res = UserInfoController.create_or_update_user_from_wechat(phone_number)
          │                  │                                 └ '18260595626'
          │                  └ <classmethod object at 0x0000017CD7621820>
          └ <class 'controller.userInfoController.UserInfoController'>

> File "D:\Python_RESTfulAPI_Codegen\dist\dist_1703676800155\api.project.com\controller\userInfoController.py", line 72, in create_or_update_user_from_wechat
    db.session.commit()
    │  │       └ <function scoped_session.commit at 0x0000017CD72750D0>
    │  └ <sqlalchemy.orm.scoping.scoped_session object at 0x0000017CD5D37160>
    └ <SQLAlchemy mysql+pymysql://root:***@8.130.89.73:3306/skill_sharing?charset=utf8>

  File "D:\Anaconda\envs\api.project.com\lib\site-packages\sqlalchemy\orm\scoping.py", line 598, in commit
    return self._proxied.commit()
           │    └ <property object at 0x0000017CD726E810>
           └ <sqlalchemy.orm.scoping.scoped_session object at 0x0000017CD5D37160>

  File "D:\Anaconda\envs\api.project.com\lib\site-packages\sqlalchemy\orm\session.py", line 1969, in commit
    trans.commit(_to_root=True)
    │     └ <function SessionTransaction.commit at 0x0000017CD71C3AF0>
    └ <sqlalchemy.orm.session.SessionTransaction object at 0x0000017CD7676040>

  File "<string>", line 2, in commit

  File "D:\Anaconda\envs\api.project.com\lib\site-packages\sqlalchemy\orm\state_changes.py", line 139, in _go
    ret_value = fn(self, *arg, **kw)
                │  │      │      └ {'_to_root': True}
                │  │      └ ()
                │  └ <sqlalchemy.orm.session.SessionTransaction object at 0x0000017CD7676040>
                └ <function SessionTransaction.commit at 0x0000017CD71C3A60>

  File "D:\Anaconda\envs\api.project.com\lib\site-packages\sqlalchemy\orm\session.py", line 1256, in commit
    self._prepare_impl()
    │    └ <function SessionTransaction._prepare_impl at 0x0000017CD71C39D0>
    └ <sqlalchemy.orm.session.SessionTransaction object at 0x0000017CD7676040>

  File "<string>", line 2, in _prepare_impl

  File "D:\Anaconda\envs\api.project.com\lib\site-packages\sqlalchemy\orm\state_changes.py", line 139, in _go
    ret_value = fn(self, *arg, **kw)
                │  │      │      └ {}
                │  │      └ ()
                │  └ <sqlalchemy.orm.session.SessionTransaction object at 0x0000017CD7676040>
                └ <function SessionTransaction._prepare_impl at 0x0000017CD71C38B0>

  File "D:\Anaconda\envs\api.project.com\lib\site-packages\sqlalchemy\orm\session.py", line 1231, in _prepare_impl
    self.session.flush()
    │    │       └ <function Session.flush at 0x0000017CD71CE670>
    │    └ <sqlalchemy.orm.session.Session object at 0x0000017CD766D910>
    └ <sqlalchemy.orm.session.SessionTransaction object at 0x0000017CD7676040>

  File "D:\Anaconda\envs\api.project.com\lib\site-packages\sqlalchemy\orm\session.py", line 4312, in flush
    self._flush(objects)
    │    │      └ None
    │    └ <function Session._flush at 0x0000017CD71CE820>
    └ <sqlalchemy.orm.session.Session object at 0x0000017CD766D910>

  File "D:\Anaconda\envs\api.project.com\lib\site-packages\sqlalchemy\orm\session.py", line 4448, in _flush
    transaction.rollback(_capture_exception=True)
    │           └ <function SessionTransaction.rollback at 0x0000017CD71C3D30>
    └ <sqlalchemy.orm.session.SessionTransaction object at 0x0000017CD7735C40>

  File "D:\Anaconda\envs\api.project.com\lib\site-packages\sqlalchemy\util\langhelpers.py", line 146, in __exit__
    raise exc_value.with_traceback(exc_tb)
          │         │              └ <traceback object at 0x0000017CD772DB00>
          │         └ <method 'with_traceback' of 'BaseException' objects>
          └ IntegrityError('(pymysql.err.IntegrityError) (1048, "Column \'user_name\' cannot be null")')

  File "D:\Anaconda\envs\api.project.com\lib\site-packages\sqlalchemy\orm\session.py", line 4408, in _flush
    flush_context.execute()
    │             └ <function UOWTransaction.execute at 0x0000017CD71B99D0>
    └ <sqlalchemy.orm.unitofwork.UOWTransaction object at 0x0000017CD76E35E0>

  File "D:\Anaconda\envs\api.project.com\lib\site-packages\sqlalchemy\orm\unitofwork.py", line 466, in execute
    rec.execute(self)
    │   │       └ <sqlalchemy.orm.unitofwork.UOWTransaction object at 0x0000017CD76E35E0>
    │   └ <function SaveUpdateAll.execute at 0x0000017CD71BA310>
    └ SaveUpdateAll(Mapper[UserInfo(user_info)])

  File "D:\Anaconda\envs\api.project.com\lib\site-packages\sqlalchemy\orm\unitofwork.py", line 642, in execute
    util.preloaded.orm_persistence.save_obj(
    │    │         │               └ <function save_obj at 0x0000017CD718F9D0>
    │    │         └ <module 'sqlalchemy.orm.persistence' from 'D:\\Anaconda\\envs\\api.project.com\\lib\\site-packages\\sqlalchemy\\orm\\persiste...
    │    └ <module 'sqlalchemy.util.preloaded' from 'D:\\Anaconda\\envs\\api.project.com\\lib\\site-packages\\sqlalchemy\\util\\preloade...
    └ <module 'sqlalchemy.util' from 'D:\\Anaconda\\envs\\api.project.com\\lib\\site-packages\\sqlalchemy\\util\\__init__.py'>

  File "D:\Anaconda\envs\api.project.com\lib\site-packages\sqlalchemy\orm\persistence.py", line 93, in save_obj
    _emit_insert_statements(
    └ <function _emit_insert_statements at 0x0000017CD719A0D0>

  File "D:\Anaconda\envs\api.project.com\lib\site-packages\sqlalchemy\orm\persistence.py", line 1043, in _emit_insert_statements
    result = connection.execute(
             │          └ <function Connection.execute at 0x0000017CD6CE81F0>
             └ <sqlalchemy.engine.base.Connection object at 0x0000017CD7682850>

  File "D:\Anaconda\envs\api.project.com\lib\site-packages\sqlalchemy\engine\base.py", line 1416, in execute
    return meth(
           └ <bound method ClauseElement._execute_on_connection of <sqlalchemy.sql.dml.Insert object at 0x0000017CD772B730>>

  File "D:\Anaconda\envs\api.project.com\lib\site-packages\sqlalchemy\sql\elements.py", line 516, in _execute_on_connection
    return connection._execute_clauseelement(
           │          └ <function Connection._execute_clauseelement at 0x0000017CD6CE84C0>
           └ <sqlalchemy.engine.base.Connection object at 0x0000017CD7682850>

  File "D:\Anaconda\envs\api.project.com\lib\site-packages\sqlalchemy\engine\base.py", line 1639, in _execute_clauseelement
    ret = self._execute_context(
          │    └ <function Connection._execute_context at 0x0000017CD6CE8670>
          └ <sqlalchemy.engine.base.Connection object at 0x0000017CD7682850>

  File "D:\Anaconda\envs\api.project.com\lib\site-packages\sqlalchemy\engine\base.py", line 1848, in _execute_context
    return self._exec_single_context(
           │    └ <function Connection._exec_single_context at 0x0000017CD6CE8700>
           └ <sqlalchemy.engine.base.Connection object at 0x0000017CD7682850>

  File "D:\Anaconda\envs\api.project.com\lib\site-packages\sqlalchemy\engine\base.py", line 1988, in _exec_single_context
    self._handle_dbapi_exception(
    │    └ <function Connection._handle_dbapi_exception at 0x0000017CD6CE8940>
    └ <sqlalchemy.engine.base.Connection object at 0x0000017CD7682850>

  File "D:\Anaconda\envs\api.project.com\lib\site-packages\sqlalchemy\engine\base.py", line 2343, in _handle_dbapi_exception
    raise sqlalchemy_exception.with_traceback(exc_info[2]) from e
          │                    │              │                 └ IntegrityError(1048, "Column 'user_name' cannot be null")
          │                    │              └ (<class 'pymysql.err.IntegrityError'>, IntegrityError(1048, "Column 'user_name' cannot be null"), <traceback object at 0x0000...
          │                    └ <method 'with_traceback' of 'BaseException' objects>
          └ IntegrityError('(pymysql.err.IntegrityError) (1048, "Column \'user_name\' cannot be null")')

  File "D:\Anaconda\envs\api.project.com\lib\site-packages\sqlalchemy\engine\base.py", line 1969, in _exec_single_context
    self.dialect.do_execute(
    │    │       └ <function DefaultDialect.do_execute at 0x0000017CD6EF48B0>
    │    └ <sqlalchemy.dialects.mysql.pymysql.MySQLDialect_pymysql object at 0x0000017CD7322040>
    └ <sqlalchemy.engine.base.Connection object at 0x0000017CD7682850>

  File "D:\Anaconda\envs\api.project.com\lib\site-packages\sqlalchemy\engine\default.py", line 922, in do_execute
    cursor.execute(statement, parameters)
    │      │       │          └ {'user_id': '2023122910208219', 'user_name': None, 'profile_picture': None, 'signature': None, 'gender': None, 'phone': '1826...
    │      │       └ 'INSERT INTO user_info (user_id, user_name, profile_picture, signature, gender, phone, date_of_birth, address) VALUES (%(user...
    │      └ <function Cursor.execute at 0x0000017CD7503700>
    └ <pymysql.cursors.Cursor object at 0x0000017CD772BB50>

  File "D:\Anaconda\envs\api.project.com\lib\site-packages\pymysql\cursors.py", line 158, in execute
    result = self._query(query)
             │    │      └ "INSERT INTO user_info (user_id, user_name, profile_picture, signature, gender, phone, date_of_birth, address) VALUES ('20231...
             │    └ <function Cursor._query at 0x0000017CD7503B80>
             └ <pymysql.cursors.Cursor object at 0x0000017CD772BB50>

  File "D:\Anaconda\envs\api.project.com\lib\site-packages\pymysql\cursors.py", line 325, in _query
    conn.query(q)
    │    │     └ "INSERT INTO user_info (user_id, user_name, profile_picture, signature, gender, phone, date_of_birth, address) VALUES ('20231...
    │    └ <function Connection.query at 0x0000017CD750FC10>
    └ <pymysql.connections.Connection object at 0x0000017CD766DDF0>

  File "D:\Anaconda\envs\api.project.com\lib\site-packages\pymysql\connections.py", line 549, in query
    self._affected_rows = self._read_query_result(unbuffered=unbuffered)
    │    │                │    │                             └ False
    │    │                │    └ <function Connection._read_query_result at 0x0000017CD7510280>
    │    │                └ <pymysql.connections.Connection object at 0x0000017CD766DDF0>
    │    └ 0
    └ <pymysql.connections.Connection object at 0x0000017CD766DDF0>

  File "D:\Anaconda\envs\api.project.com\lib\site-packages\pymysql\connections.py", line 779, in _read_query_result
    result.read()
    │      └ <function MySQLResult.read at 0x0000017CD7510A60>
    └ <pymysql.connections.MySQLResult object at 0x0000017CD76E33D0>

  File "D:\Anaconda\envs\api.project.com\lib\site-packages\pymysql\connections.py", line 1157, in read
    first_packet = self.connection._read_packet()
                   │    └ None
                   └ <pymysql.connections.MySQLResult object at 0x0000017CD76E33D0>

  File "D:\Anaconda\envs\api.project.com\lib\site-packages\pymysql\connections.py", line 729, in _read_packet
    packet.raise_for_error()
    │      └ <function MysqlPacket.raise_for_error at 0x0000017CD750C820>
    └ <pymysql.protocol.MysqlPacket object at 0x0000017CD76E3FD0>

  File "D:\Anaconda\envs\api.project.com\lib\site-packages\pymysql\protocol.py", line 221, in raise_for_error
    err.raise_mysql_exception(self._data)
    │   │                     │    └ <member '_data' of 'MysqlPacket' objects>
    │   │                     └ <pymysql.protocol.MysqlPacket object at 0x0000017CD76E3FD0>
    │   └ <function raise_mysql_exception at 0x0000017CD736ACA0>
    └ <module 'pymysql.err' from 'D:\\Anaconda\\envs\\api.project.com\\lib\\site-packages\\pymysql\\err.py'>

  File "D:\Anaconda\envs\api.project.com\lib\site-packages\pymysql\err.py", line 143, in raise_mysql_exception
    raise errorclass(errno, errval)
          │          │      └ "Column 'user_name' cannot be null"
          │          └ 1048
          └ <class 'pymysql.err.IntegrityError'>

sqlalchemy.exc.IntegrityError: (pymysql.err.IntegrityError) (1048, "Column 'user_name' cannot be null")
[SQL: INSERT INTO user_info (user_id, user_name, profile_picture, signature, gender, phone, date_of_birth, address) VALUES (%(user_id)s, %(user_name)s, %(profile_picture)s, %(signature)s, %(gender)s, %(phone)s, %(date_of_birth)s, %(address)s)]
[parameters: {'user_id': '2023122910208219', 'user_name': None, 'profile_picture': None, 'signature': None, 'gender': None, 'phone': '18260595626', 'date_of_birth': None, 'address': None}]
(Background on this error at: https://sqlalche.me/e/20/gkpj)
2023-12-29 10:35:55.649 | ERROR    | utils.loggings:exception:40 - (pymysql.err.IntegrityError) (1048, "Column 'user_name' cannot be null")
[SQL: INSERT INTO user_info (user_id, user_name, profile_picture, signature, gender, phone, date_of_birth, address) VALUES (%(user_id)s, %(user_name)s, %(profile_picture)s, %(signature)s, %(gender)s, %(phone)s, %(date_of_birth)s, %(address)s)]
[parameters: {'user_id': '2023122910351947', 'user_name': None, 'profile_picture': None, 'signature': None, 'gender': None, 'phone': '18260595626', 'date_of_birth': None, 'address': None}]
(Background on this error at: https://sqlalche.me/e/20/gkpj)
Traceback (most recent call last):

  File "D:\Anaconda\envs\api.project.com\lib\site-packages\sqlalchemy\engine\base.py", line 1969, in _exec_single_context
    self.dialect.do_execute(
    │    │       └ <function DefaultDialect.do_execute at 0x000001212D12C8B0>
    │    └ <sqlalchemy.dialects.mysql.pymysql.MySQLDialect_pymysql object at 0x000001212D552040>
    └ <sqlalchemy.engine.base.Connection object at 0x000001212D8DCD00>

  File "D:\Anaconda\envs\api.project.com\lib\site-packages\sqlalchemy\engine\default.py", line 922, in do_execute
    cursor.execute(statement, parameters)
    │      │       │          └ {'user_id': '2023122910351947', 'user_name': None, 'profile_picture': None, 'signature': None, 'gender': None, 'phone': '1826...
    │      │       └ 'INSERT INTO user_info (user_id, user_name, profile_picture, signature, gender, phone, date_of_birth, address) VALUES (%(user...
    │      └ <function Cursor.execute at 0x000001212D732700>
    └ <pymysql.cursors.Cursor object at 0x000001212D959B50>

  File "D:\Anaconda\envs\api.project.com\lib\site-packages\pymysql\cursors.py", line 158, in execute
    result = self._query(query)
             │    │      └ "INSERT INTO user_info (user_id, user_name, profile_picture, signature, gender, phone, date_of_birth, address) VALUES ('20231...
             │    └ <function Cursor._query at 0x000001212D732B80>
             └ <pymysql.cursors.Cursor object at 0x000001212D959B50>

  File "D:\Anaconda\envs\api.project.com\lib\site-packages\pymysql\cursors.py", line 325, in _query
    conn.query(q)
    │    │     └ "INSERT INTO user_info (user_id, user_name, profile_picture, signature, gender, phone, date_of_birth, address) VALUES ('20231...
    │    └ <function Connection.query at 0x000001212D73EC10>
    └ <pymysql.connections.Connection object at 0x000001212D8DCDF0>

  File "D:\Anaconda\envs\api.project.com\lib\site-packages\pymysql\connections.py", line 549, in query
    self._affected_rows = self._read_query_result(unbuffered=unbuffered)
    │    │                │    │                             └ False
    │    │                │    └ <function Connection._read_query_result at 0x000001212D73F280>
    │    │                └ <pymysql.connections.Connection object at 0x000001212D8DCDF0>
    │    └ 0
    └ <pymysql.connections.Connection object at 0x000001212D8DCDF0>

  File "D:\Anaconda\envs\api.project.com\lib\site-packages\pymysql\connections.py", line 779, in _read_query_result
    result.read()
    │      └ <function MySQLResult.read at 0x000001212D73FA60>
    └ <pymysql.connections.MySQLResult object at 0x000001212D9303D0>

  File "D:\Anaconda\envs\api.project.com\lib\site-packages\pymysql\connections.py", line 1157, in read
    first_packet = self.connection._read_packet()
                   │    └ None
                   └ <pymysql.connections.MySQLResult object at 0x000001212D9303D0>

  File "D:\Anaconda\envs\api.project.com\lib\site-packages\pymysql\connections.py", line 729, in _read_packet
    packet.raise_for_error()
    │      └ <function MysqlPacket.raise_for_error at 0x000001212D73C820>
    └ <pymysql.protocol.MysqlPacket object at 0x000001212D930FD0>

  File "D:\Anaconda\envs\api.project.com\lib\site-packages\pymysql\protocol.py", line 221, in raise_for_error
    err.raise_mysql_exception(self._data)
    │   │                     │    └ <member '_data' of 'MysqlPacket' objects>
    │   │                     └ <pymysql.protocol.MysqlPacket object at 0x000001212D930FD0>
    │   └ <function raise_mysql_exception at 0x000001212D59ACA0>
    └ <module 'pymysql.err' from 'D:\\Anaconda\\envs\\api.project.com\\lib\\site-packages\\pymysql\\err.py'>

  File "D:\Anaconda\envs\api.project.com\lib\site-packages\pymysql\err.py", line 143, in raise_mysql_exception
    raise errorclass(errno, errval)
          │          │      └ "Column 'user_name' cannot be null"
          │          └ 1048
          └ <class 'pymysql.err.IntegrityError'>

pymysql.err.IntegrityError: (1048, "Column 'user_name' cannot be null")


The above exception was the direct cause of the following exception:


Traceback (most recent call last):

  File "D:\Anaconda\envs\api.project.com\lib\threading.py", line 890, in _bootstrap
    self._bootstrap_inner()
    │    └ <function Thread._bootstrap_inner at 0x00000121298F4430>
    └ <Thread(Thread-1, started daemon 8152)>

  File "D:\Anaconda\envs\api.project.com\lib\threading.py", line 932, in _bootstrap_inner
    self.run()
    │    └ <function Thread.run at 0x00000121298F4160>
    └ <Thread(Thread-1, started daemon 8152)>

  File "D:\Anaconda\envs\api.project.com\lib\threading.py", line 870, in run
    self._target(*self._args, **self._kwargs)
    │    │        │    │        │    └ {}
    │    │        │    │        └ <Thread(Thread-1, started daemon 8152)>
    │    │        │    └ ()
    │    │        └ <Thread(Thread-1, started daemon 8152)>
    │    └ <bound method BaseWSGIServer.serve_forever of <werkzeug.serving.BaseWSGIServer object at 0x000001212D88D4F0>>
    └ <Thread(Thread-1, started daemon 8152)>

  File "D:\Anaconda\envs\api.project.com\lib\site-packages\werkzeug\serving.py", line 806, in serve_forever
    super().serve_forever(poll_interval=poll_interval)
                                        └ 0.5

  File "D:\Anaconda\envs\api.project.com\lib\socketserver.py", line 237, in serve_forever
    self._handle_request_noblock()
    │    └ <function BaseServer._handle_request_noblock at 0x00000121298F6A60>
    └ <werkzeug.serving.BaseWSGIServer object at 0x000001212D88D4F0>

  File "D:\Anaconda\envs\api.project.com\lib\socketserver.py", line 316, in _handle_request_noblock
    self.process_request(request, client_address)
    │    │               │        └ ('127.0.0.1', 10432)
    │    │               └ <socket.socket fd=684, family=AddressFamily.AF_INET, type=SocketKind.SOCK_STREAM, proto=0, laddr=('127.0.0.1', 5000), raddr=(...
    │    └ <function BaseServer.process_request at 0x00000121298F6C10>
    └ <werkzeug.serving.BaseWSGIServer object at 0x000001212D88D4F0>

  File "D:\Anaconda\envs\api.project.com\lib\socketserver.py", line 347, in process_request
    self.finish_request(request, client_address)
    │    │              │        └ ('127.0.0.1', 10432)
    │    │              └ <socket.socket fd=684, family=AddressFamily.AF_INET, type=SocketKind.SOCK_STREAM, proto=0, laddr=('127.0.0.1', 5000), raddr=(...
    │    └ <function BaseServer.finish_request at 0x00000121298F6D30>
    └ <werkzeug.serving.BaseWSGIServer object at 0x000001212D88D4F0>

  File "D:\Anaconda\envs\api.project.com\lib\socketserver.py", line 360, in finish_request
    self.RequestHandlerClass(request, client_address, self)
    │    │                   │        │               └ <werkzeug.serving.BaseWSGIServer object at 0x000001212D88D4F0>
    │    │                   │        └ ('127.0.0.1', 10432)
    │    │                   └ <socket.socket fd=684, family=AddressFamily.AF_INET, type=SocketKind.SOCK_STREAM, proto=0, laddr=('127.0.0.1', 5000), raddr=(...
    │    └ <class 'werkzeug.serving.WSGIRequestHandler'>
    └ <werkzeug.serving.BaseWSGIServer object at 0x000001212D88D4F0>

  File "D:\Anaconda\envs\api.project.com\lib\socketserver.py", line 720, in __init__
    self.handle()
    │    └ <function WSGIRequestHandler.handle at 0x000001212B67ECA0>
    └ <werkzeug.serving.WSGIRequestHandler object at 0x000001212D8DC040>

  File "D:\Anaconda\envs\api.project.com\lib\site-packages\werkzeug\serving.py", line 390, in handle
    super().handle()

  File "D:\Anaconda\envs\api.project.com\lib\http\server.py", line 426, in handle
    self.handle_one_request()
    │    └ <function BaseHTTPRequestHandler.handle_one_request at 0x000001212B46B1F0>
    └ <werkzeug.serving.WSGIRequestHandler object at 0x000001212D8DC040>

  File "D:\Anaconda\envs\api.project.com\lib\http\server.py", line 414, in handle_one_request
    method()
    └ <bound method WSGIRequestHandler.run_wsgi of <werkzeug.serving.WSGIRequestHandler object at 0x000001212D8DC040>>

  File "D:\Anaconda\envs\api.project.com\lib\site-packages\werkzeug\serving.py", line 362, in run_wsgi
    execute(self.server.app)
    │       │    │      └ <werkzeug.debug.DebuggedApplication object at 0x000001212D875220>
    │       │    └ <werkzeug.serving.BaseWSGIServer object at 0x000001212D88D4F0>
    │       └ <werkzeug.serving.WSGIRequestHandler object at 0x000001212D8DC040>
    └ <function WSGIRequestHandler.run_wsgi.<locals>.execute at 0x000001212D8DEF70>

  File "D:\Anaconda\envs\api.project.com\lib\site-packages\werkzeug\serving.py", line 325, in execute
    for data in application_iter:
                └ <generator object DebuggedApplication.debug_application at 0x000001212D8B3DD0>

  File "D:\Anaconda\envs\api.project.com\lib\site-packages\werkzeug\debug\__init__.py", line 330, in debug_application
    app_iter = self.app(environ, start_response)
               │    │   │        └ <function WSGIRequestHandler.run_wsgi.<locals>.start_response at 0x000001212D8DEAF0>
               │    │   └ {'wsgi.version': (1, 0), 'wsgi.url_scheme': 'http', 'wsgi.input': <_io.BufferedReader name=684>, 'wsgi.errors': <_io.TextIOWr...
               │    └ <Flask 'app'>
               └ <werkzeug.debug.DebuggedApplication object at 0x000001212D875220>

  File "D:\Anaconda\envs\api.project.com\lib\site-packages\flask\app.py", line 2213, in __call__
    return self.wsgi_app(environ, start_response)
           │    │        │        └ <function WSGIRequestHandler.run_wsgi.<locals>.start_response at 0x000001212D8DEAF0>
           │    │        └ {'wsgi.version': (1, 0), 'wsgi.url_scheme': 'http', 'wsgi.input': <_io.BufferedReader name=684>, 'wsgi.errors': <_io.TextIOWr...
           │    └ <function Flask.wsgi_app at 0x000001212BF42E50>
           └ <Flask 'app'>

  File "D:\Anaconda\envs\api.project.com\lib\site-packages\flask\app.py", line 2190, in wsgi_app
    response = self.full_dispatch_request()
               │    └ <function Flask.full_dispatch_request at 0x000001212BF423A0>
               └ <Flask 'app'>

  File "D:\Anaconda\envs\api.project.com\lib\site-packages\flask\app.py", line 1484, in full_dispatch_request
    rv = self.dispatch_request()
         │    └ <function Flask.dispatch_request at 0x000001212BF42310>
         └ <Flask 'app'>

  File "D:\Anaconda\envs\api.project.com\lib\site-packages\flask\app.py", line 1469, in dispatch_request
    return self.ensure_sync(self.view_functions[rule.endpoint])(**view_args)
           │    │           │    │              │    │            └ {}
           │    │           │    │              │    └ 'userInfo.UserInfo'
           │    │           │    │              └ <Rule '/api_1_0/userInfo' (GET, HEAD, OPTIONS, POST, DELETE, PUT) -> userInfo.UserInfo>
           │    │           │    └ {'static': <function Flask.__init__.<locals>.<lambda> at 0x000001212D52DF70>, 'apiversion.Apiversion': <function View.as_view...
           │    │           └ <Flask 'app'>
           │    └ <function Flask.ensure_sync at 0x000001212BF425E0>
           └ <Flask 'app'>

  File "D:\Anaconda\envs\api.project.com\lib\site-packages\flask_restful\__init__.py", line 489, in wrapper
    resp = resource(*args, **kwargs)
           │         │       └ {}
           │         └ ()
           └ <function View.as_view.<locals>.view at 0x000001212D8544C0>

  File "D:\Anaconda\envs\api.project.com\lib\site-packages\flask\views.py", line 109, in view
    return current_app.ensure_sync(self.dispatch_request)(**kwargs)
           │                       │    │                   └ {}
           │                       │    └ <function Resource.dispatch_request at 0x000001212D75DA60>
           │                       └ <api_1_0.userInfoResource.userInfoResource.UserInfoResource object at 0x000001212D8DC640>
           └ <Flask 'app'>

  File "D:\Anaconda\envs\api.project.com\lib\site-packages\flask_restful\__init__.py", line 604, in dispatch_request
    resp = meth(*args, **kwargs)
           │     │       └ {}
           │     └ ()
           └ <bound method UserInfoResource.post of <class 'api_1_0.userInfoResource.userInfoResource.UserInfoResource'>>

  File "D:\Python_RESTfulAPI_Codegen\dist\dist_1703676800155\api.project.com\api_1_0\userInfoResource\userInfoResource.py", line 127, in post
    res = UserInfoController.create_or_update_user_from_wechat(phone_number)
          │                  │                                 └ '18260595626'
          │                  └ <classmethod object at 0x000001212D8519D0>
          └ <class 'controller.userInfoController.UserInfoController'>

> File "D:\Python_RESTfulAPI_Codegen\dist\dist_1703676800155\api.project.com\controller\userInfoController.py", line 72, in create_or_update_user_from_wechat
    db.session.commit()
    │  │       └ <function scoped_session.commit at 0x000001212D4A40D0>
    │  └ <sqlalchemy.orm.scoping.scoped_session object at 0x000001212BF67160>
    └ <SQLAlchemy mysql+pymysql://root:***@8.130.89.73:3306/skill_sharing?charset=utf8>

  File "D:\Anaconda\envs\api.project.com\lib\site-packages\sqlalchemy\orm\scoping.py", line 598, in commit
    return self._proxied.commit()
           │    └ <property object at 0x000001212D49E680>
           └ <sqlalchemy.orm.scoping.scoped_session object at 0x000001212BF67160>

  File "D:\Anaconda\envs\api.project.com\lib\site-packages\sqlalchemy\orm\session.py", line 1969, in commit
    trans.commit(_to_root=True)
    │     └ <function SessionTransaction.commit at 0x000001212D3F3AF0>
    └ <sqlalchemy.orm.session.SessionTransaction object at 0x000001212D92C480>

  File "<string>", line 2, in commit

  File "D:\Anaconda\envs\api.project.com\lib\site-packages\sqlalchemy\orm\state_changes.py", line 139, in _go
    ret_value = fn(self, *arg, **kw)
                │  │      │      └ {'_to_root': True}
                │  │      └ ()
                │  └ <sqlalchemy.orm.session.SessionTransaction object at 0x000001212D92C480>
                └ <function SessionTransaction.commit at 0x000001212D3F3A60>

  File "D:\Anaconda\envs\api.project.com\lib\site-packages\sqlalchemy\orm\session.py", line 1256, in commit
    self._prepare_impl()
    │    └ <function SessionTransaction._prepare_impl at 0x000001212D3F39D0>
    └ <sqlalchemy.orm.session.SessionTransaction object at 0x000001212D92C480>

  File "<string>", line 2, in _prepare_impl

  File "D:\Anaconda\envs\api.project.com\lib\site-packages\sqlalchemy\orm\state_changes.py", line 139, in _go
    ret_value = fn(self, *arg, **kw)
                │  │      │      └ {}
                │  │      └ ()
                │  └ <sqlalchemy.orm.session.SessionTransaction object at 0x000001212D92C480>
                └ <function SessionTransaction._prepare_impl at 0x000001212D3F38B0>

  File "D:\Anaconda\envs\api.project.com\lib\site-packages\sqlalchemy\orm\session.py", line 1231, in _prepare_impl
    self.session.flush()
    │    │       └ <function Session.flush at 0x000001212D3FE670>
    │    └ <sqlalchemy.orm.session.Session object at 0x000001212D8DC880>
    └ <sqlalchemy.orm.session.SessionTransaction object at 0x000001212D92C480>

  File "D:\Anaconda\envs\api.project.com\lib\site-packages\sqlalchemy\orm\session.py", line 4312, in flush
    self._flush(objects)
    │    │      └ None
    │    └ <function Session._flush at 0x000001212D3FE820>
    └ <sqlalchemy.orm.session.Session object at 0x000001212D8DC880>

  File "D:\Anaconda\envs\api.project.com\lib\site-packages\sqlalchemy\orm\session.py", line 4448, in _flush
    transaction.rollback(_capture_exception=True)
    │           └ <function SessionTransaction.rollback at 0x000001212D3F3D30>
    └ <sqlalchemy.orm.session.SessionTransaction object at 0x000001212D961B00>

  File "D:\Anaconda\envs\api.project.com\lib\site-packages\sqlalchemy\util\langhelpers.py", line 146, in __exit__
    raise exc_value.with_traceback(exc_tb)
          │         │              └ <traceback object at 0x000001212D95CA80>
          │         └ <method 'with_traceback' of 'BaseException' objects>
          └ IntegrityError('(pymysql.err.IntegrityError) (1048, "Column \'user_name\' cannot be null")')

  File "D:\Anaconda\envs\api.project.com\lib\site-packages\sqlalchemy\orm\session.py", line 4408, in _flush
    flush_context.execute()
    │             └ <function UOWTransaction.execute at 0x000001212D3E99D0>
    └ <sqlalchemy.orm.unitofwork.UOWTransaction object at 0x000001212D9305E0>

  File "D:\Anaconda\envs\api.project.com\lib\site-packages\sqlalchemy\orm\unitofwork.py", line 466, in execute
    rec.execute(self)
    │   │       └ <sqlalchemy.orm.unitofwork.UOWTransaction object at 0x000001212D9305E0>
    │   └ <function SaveUpdateAll.execute at 0x000001212D3EA310>
    └ SaveUpdateAll(Mapper[UserInfo(user_info)])

  File "D:\Anaconda\envs\api.project.com\lib\site-packages\sqlalchemy\orm\unitofwork.py", line 642, in execute
    util.preloaded.orm_persistence.save_obj(
    │    │         │               └ <function save_obj at 0x000001212D3BF9D0>
    │    │         └ <module 'sqlalchemy.orm.persistence' from 'D:\\Anaconda\\envs\\api.project.com\\lib\\site-packages\\sqlalchemy\\orm\\persiste...
    │    └ <module 'sqlalchemy.util.preloaded' from 'D:\\Anaconda\\envs\\api.project.com\\lib\\site-packages\\sqlalchemy\\util\\preloade...
    └ <module 'sqlalchemy.util' from 'D:\\Anaconda\\envs\\api.project.com\\lib\\site-packages\\sqlalchemy\\util\\__init__.py'>

  File "D:\Anaconda\envs\api.project.com\lib\site-packages\sqlalchemy\orm\persistence.py", line 93, in save_obj
    _emit_insert_statements(
    └ <function _emit_insert_statements at 0x000001212D3CA0D0>

  File "D:\Anaconda\envs\api.project.com\lib\site-packages\sqlalchemy\orm\persistence.py", line 1043, in _emit_insert_statements
    result = connection.execute(
             │          └ <function Connection.execute at 0x000001212CF181F0>
             └ <sqlalchemy.engine.base.Connection object at 0x000001212D8DCD00>

  File "D:\Anaconda\envs\api.project.com\lib\site-packages\sqlalchemy\engine\base.py", line 1416, in execute
    return meth(
           └ <bound method ClauseElement._execute_on_connection of <sqlalchemy.sql.dml.Insert object at 0x000001212D959730>>

  File "D:\Anaconda\envs\api.project.com\lib\site-packages\sqlalchemy\sql\elements.py", line 516, in _execute_on_connection
    return connection._execute_clauseelement(
           │          └ <function Connection._execute_clauseelement at 0x000001212CF184C0>
           └ <sqlalchemy.engine.base.Connection object at 0x000001212D8DCD00>

  File "D:\Anaconda\envs\api.project.com\lib\site-packages\sqlalchemy\engine\base.py", line 1639, in _execute_clauseelement
    ret = self._execute_context(
          │    └ <function Connection._execute_context at 0x000001212CF18670>
          └ <sqlalchemy.engine.base.Connection object at 0x000001212D8DCD00>

  File "D:\Anaconda\envs\api.project.com\lib\site-packages\sqlalchemy\engine\base.py", line 1848, in _execute_context
    return self._exec_single_context(
           │    └ <function Connection._exec_single_context at 0x000001212CF18700>
           └ <sqlalchemy.engine.base.Connection object at 0x000001212D8DCD00>

  File "D:\Anaconda\envs\api.project.com\lib\site-packages\sqlalchemy\engine\base.py", line 1988, in _exec_single_context
    self._handle_dbapi_exception(
    │    └ <function Connection._handle_dbapi_exception at 0x000001212CF18940>
    └ <sqlalchemy.engine.base.Connection object at 0x000001212D8DCD00>

  File "D:\Anaconda\envs\api.project.com\lib\site-packages\sqlalchemy\engine\base.py", line 2343, in _handle_dbapi_exception
    raise sqlalchemy_exception.with_traceback(exc_info[2]) from e
          │                    │              │                 └ IntegrityError(1048, "Column 'user_name' cannot be null")
          │                    │              └ (<class 'pymysql.err.IntegrityError'>, IntegrityError(1048, "Column 'user_name' cannot be null"), <traceback object at 0x0000...
          │                    └ <method 'with_traceback' of 'BaseException' objects>
          └ IntegrityError('(pymysql.err.IntegrityError) (1048, "Column \'user_name\' cannot be null")')

  File "D:\Anaconda\envs\api.project.com\lib\site-packages\sqlalchemy\engine\base.py", line 1969, in _exec_single_context
    self.dialect.do_execute(
    │    │       └ <function DefaultDialect.do_execute at 0x000001212D12C8B0>
    │    └ <sqlalchemy.dialects.mysql.pymysql.MySQLDialect_pymysql object at 0x000001212D552040>
    └ <sqlalchemy.engine.base.Connection object at 0x000001212D8DCD00>

  File "D:\Anaconda\envs\api.project.com\lib\site-packages\sqlalchemy\engine\default.py", line 922, in do_execute
    cursor.execute(statement, parameters)
    │      │       │          └ {'user_id': '2023122910351947', 'user_name': None, 'profile_picture': None, 'signature': None, 'gender': None, 'phone': '1826...
    │      │       └ 'INSERT INTO user_info (user_id, user_name, profile_picture, signature, gender, phone, date_of_birth, address) VALUES (%(user...
    │      └ <function Cursor.execute at 0x000001212D732700>
    └ <pymysql.cursors.Cursor object at 0x000001212D959B50>

  File "D:\Anaconda\envs\api.project.com\lib\site-packages\pymysql\cursors.py", line 158, in execute
    result = self._query(query)
             │    │      └ "INSERT INTO user_info (user_id, user_name, profile_picture, signature, gender, phone, date_of_birth, address) VALUES ('20231...
             │    └ <function Cursor._query at 0x000001212D732B80>
             └ <pymysql.cursors.Cursor object at 0x000001212D959B50>

  File "D:\Anaconda\envs\api.project.com\lib\site-packages\pymysql\cursors.py", line 325, in _query
    conn.query(q)
    │    │     └ "INSERT INTO user_info (user_id, user_name, profile_picture, signature, gender, phone, date_of_birth, address) VALUES ('20231...
    │    └ <function Connection.query at 0x000001212D73EC10>
    └ <pymysql.connections.Connection object at 0x000001212D8DCDF0>

  File "D:\Anaconda\envs\api.project.com\lib\site-packages\pymysql\connections.py", line 549, in query
    self._affected_rows = self._read_query_result(unbuffered=unbuffered)
    │    │                │    │                             └ False
    │    │                │    └ <function Connection._read_query_result at 0x000001212D73F280>
    │    │                └ <pymysql.connections.Connection object at 0x000001212D8DCDF0>
    │    └ 0
    └ <pymysql.connections.Connection object at 0x000001212D8DCDF0>

  File "D:\Anaconda\envs\api.project.com\lib\site-packages\pymysql\connections.py", line 779, in _read_query_result
    result.read()
    │      └ <function MySQLResult.read at 0x000001212D73FA60>
    └ <pymysql.connections.MySQLResult object at 0x000001212D9303D0>

  File "D:\Anaconda\envs\api.project.com\lib\site-packages\pymysql\connections.py", line 1157, in read
    first_packet = self.connection._read_packet()
                   │    └ None
                   └ <pymysql.connections.MySQLResult object at 0x000001212D9303D0>

  File "D:\Anaconda\envs\api.project.com\lib\site-packages\pymysql\connections.py", line 729, in _read_packet
    packet.raise_for_error()
    │      └ <function MysqlPacket.raise_for_error at 0x000001212D73C820>
    └ <pymysql.protocol.MysqlPacket object at 0x000001212D930FD0>

  File "D:\Anaconda\envs\api.project.com\lib\site-packages\pymysql\protocol.py", line 221, in raise_for_error
    err.raise_mysql_exception(self._data)
    │   │                     │    └ <member '_data' of 'MysqlPacket' objects>
    │   │                     └ <pymysql.protocol.MysqlPacket object at 0x000001212D930FD0>
    │   └ <function raise_mysql_exception at 0x000001212D59ACA0>
    └ <module 'pymysql.err' from 'D:\\Anaconda\\envs\\api.project.com\\lib\\site-packages\\pymysql\\err.py'>

  File "D:\Anaconda\envs\api.project.com\lib\site-packages\pymysql\err.py", line 143, in raise_mysql_exception
    raise errorclass(errno, errval)
          │          │      └ "Column 'user_name' cannot be null"
          │          └ 1048
          └ <class 'pymysql.err.IntegrityError'>

sqlalchemy.exc.IntegrityError: (pymysql.err.IntegrityError) (1048, "Column 'user_name' cannot be null")
[SQL: INSERT INTO user_info (user_id, user_name, profile_picture, signature, gender, phone, date_of_birth, address) VALUES (%(user_id)s, %(user_name)s, %(profile_picture)s, %(signature)s, %(gender)s, %(phone)s, %(date_of_birth)s, %(address)s)]
[parameters: {'user_id': '2023122910351947', 'user_name': None, 'profile_picture': None, 'signature': None, 'gender': None, 'phone': '18260595626', 'date_of_birth': None, 'address': None}]
(Background on this error at: https://sqlalche.me/e/20/gkpj)
